Workbook

Sheet Read Me
A1: Halda River OCP — Fish Contamination & Human Health Risk: Calculation Workbook
A3: This workbook reproduces, with live formulas, every calculation reported in
A4: 'Halda_OCP_Fish_Risk_Results.docx' (Sections 4.1–4.6).
A6: Sheet guide:
A7: 1. Raw Data — the 27-sample × 14-compound concentration matrix (µg/kg ww), plus per-sample ΣOCP.
A8: 2. Descriptive Stats — Table 4.3 (mean, SD, range, detection frequency per compound) + overall ΣOCP.
A9: 3. Group Mean Concentrations — mean concentration of each compound, by zone, by species and overall.
A10: 4. Table 4.4 (SumOCP by group) — Table 4.4 (ΣOCP mean ± SD by zone/species), linked to the KW test below.
A11: 5. Kruskal-Wallis Test — full rank-based H-test workings for the zone and species comparisons.
A12: 6. Exposure & Toxicity Inputs — Table 4.1 (BW, IR, EF, ED, AT) and Table 4.2 (RfD, CSF per compound).
A13: 7. Risk Assessment — full THQ and CR matrix (compound × grouping × consumer), with HI = ΣTHQ.
A14: 8. Summary (Table 4.5) — Table 4.5, HI and CR by zone/species/overall, adult and child.
... A26: in Sections 4.3–4.5 of the report, including both Kruskal–Wallis tests, is formula-driven here.

Sheet Raw Data
A1: Table — OCP concentrations in Halda River fish muscle (µg/kg wet weight)
A3: Sample ID | B3: Zone | C3: Species | D3: o,p'-DDT | E3: p,p'-DDT | F3: o,p'-DDD | G3: p,p'-DDD | H3: o,p'-DDE | I3: p,p'-DDE | J3: α-HCH | K3: β-HCH | L3: γ-HCH (Lindane) | M3: δ-HCH | N3: Aldrin | O3: Dieldrin | P3: Heptachlor | Q3: Heptachlor epoxide | R3: ΣOCP (µg/kg ww) | S3: ΣDDT | T3: ΣHCH | U3: ΣDRN | V3: ΣHPT
A4: RUR1 | B4: Up-stream | C4: Rui | D4: 0.5 | E4: 0.5 | F4: 0.5 | G4: 1.12 | H4: 1.241 | I4: 2.284 | J4: 1.029 | K4: 5.381 | L4: 0.5 | M4: 2.538 | N4: 0.5 | O4: 0.5 | P4: 0.5 | Q4: 0.5 | R4: =SUM(D4:Q4) -> 17.593 | S4: =D4+E4+F4+G4+H4+I4 -> 6.145 | T4: =J4+K4+L4+M4 -> 9.448 | U4: =N4+O4 -> 1 | V4: =P4+Q4 -> 1
A5: RUR2 | B5: Up-stream | C5: Rui | D5: 0.5 | E5: 0.5 | F5: 0.5 | G5: 2.176 | H5: 2.034 | I5: 3.733 | J5: 1.299 | K5: 5.163 | L5: 0.5 | M5: 1.513 | N5: 0.5 | O5: 0.5 | P5: 0.5 | Q5: 0.5 | R5: =SUM(D5:Q5) -> 19.918 | S5: =D5+E5+F5+G5+H5+I5 -> 9.443 | T5: =J5+K5+L5+M5 -> 8.475 | U5: =N5+O5 -> 1 | V5: =P5+Q5 -> 1
A6: RUR3 | B6: Up-stream | C6: Rui | D6: 0.5 | E6: 0.5 | F6: 0.5 | G6: 2.378 | H6: 1.231 | I6: 2.547 | J6: 1.152 | K6: 5.936 | L6: 0.5 | M6: 2.426 | N6: 0.5 | O6: 0.5 | P6: 0.5 | Q6: 0.5 | R6: =SUM(D6:Q6) -> 19.67 | S6: =D6+E6+F6+G6+H6+I6 -> 7.656 | T6: =J6+K6+L6+M6 -> 10.014 | U6: =N6+O6 -> 1 | V6: =P6+Q6 -> 1
A7: CUR1 | B7: Up-stream | C7: Catla | D7: 0.5 | E7: 0.5 | F7: 0.5 | G7: 0.5 | H7: 0.5 | I7: 0.5 | J7: 2.2 | K7: 0.5 | L7: 0.5 | M7: 0.5 | N7: 0.5 | O7: 0.5 | P7: 0.5 | Q7: 0.5 | R7: =SUM(D7:Q7) -> 8.7 | S7: =D7+E7+F7+G7+H7+I7 -> 3 | T7: =J7+K7+L7+M7 -> 3.7 | U7: =N7+O7 -> 1 | V7: =P7+Q7 -> 1
A8: CUR2 | B8: Up-stream | C8: Catla | D8: 0.5 | E8: 0.5 | F8: 0.5 | G8: 0.5 | H8: 0.5 | I8: 0.5 | J8: 0.5 | K8: 0.5 | L8: 0.5 | M8: 0.5 | N8: 0.5 | O8: 0.5 | P8: 0.5 | Q8: 0.5 | R8: =SUM(D8:Q8) -> 7 | S8: =D8+E8+F8+G8+H8+I8 -> 3 | T8: =J8+K8+L8+M8 -> 2 | U8: =N8+O8 -> 1 | V8: =P8+Q8 -> 1
A9: CUR3 | B9: Up-stream | C9: Catla | D9: 0.5 | E9: 0.5 | F9: 0.5 | G9: 0.5 | H9: 0.5 | I9: 0.5 | J9: 1.521 | K9: 0.5 | L9: 0.5 | M9: 0.5 | N9: 0.5 | O9: 0.5 | P9: 0.5 | Q9: 0.5 | R9: =SUM(D9:Q9) -> 8.021 | S9: =D9+E9+F9+G9+H9+I9 -> 3 | T9: =J9+K9+L9+M9 -> 3.021 | U9: =N9+O9 -> 1 | V9: =P9+Q9 -> 1
A10: MUR1 | B10: Up-stream | C10: Mrigal | D10: 2.103 | E10: 2.335 | F10: 0.5 | G10: 2.474 | H10: 5.14 | I10: 5.264 | J10: 3.814 | K10: 5.356 | L10: 0.5 | M10: 3.48 | N10: 0.5 | O10: 0.5 | P10: 0.5 | Q10: 3.824 | R10: =SUM(D10:Q10) -> 36.29 | S10: =D10+E10+F10+G10+H10+I10 -> 17.816 | T10: =J10+K10+L10+M10 -> 13.15 | U10: =N10+O10 -> 1 | V10: =P10+Q10 -> 4.324
A11: MUR2 | B11: Up-stream | C11: Mrigal | D11: 0.5 | E11: 3.204 | F11: 0.5 | G11: 3.288 | H11: 0.5 | I11: 6.735 | J11: 2.375 | K11: 5.834 | L11: 0.5 | M11: 4.166 | N11: 0.5 | O11: 0.5 | P11: 0.5 | Q11: 2.336 | R11: =SUM(D11:Q11) -> 31.438 | S11: =D11+E11+F11+G11+H11+I11 -> 14.727 | T11: =J11+K11+L11+M11 -> 12.875 | U11: =N11+O11 -> 1 | V11: =P11+Q11 -> 2.836
A12: MUR3 | B12: Up-stream | C12: Mrigal | D12: 2.023 | E12: 2.763 | F12: 0.5 | G12: 2.157 | H12: 5.405 | I12: 5.532 | J12: 5.274 | K12: 5.457 | L12: 0.5 | M12: 4.8 | N12: 0.5 | O12: 0.5 | P12: 0.5 | Q12: 3.238 | R12: =SUM(D12:Q12) -> 39.149 | S12: =D12+E12+F12+G12+H12+I12 -> 18.38 | T12: =J12+K12+L12+M12 -> 16.031 | U12: =N12+O12 -> 1 | V12: =P12+Q12 -> 3.738
A13: RMR1 | B13: Mid-stream | C13: Rui | D13: 2.046 | E13: 3.636 | F13: 0.5 | G13: 1.983 | H13: 5.35 | I13: 3.536 | J13: 0.5 | K13: 6.023 | L13: 0.5 | M13: 3.411 | N13: 0.5 | O13: 6.589 | P13: 2.041 | Q13: 1.941 | R13: =SUM(D13:Q13) -> 38.556 | S13: =D13+E13+F13+G13+H13+I13 -> 17.051 | T13: =J13+K13+L13+M13 -> 10.434 | U13: =N13+O13 -> 7.089 | V13: =P13+Q13 -> 3.982
A14: RMR2 | B14: Mid-stream | C14: Rui | D14: 2.329 | E14: 3.389 | F14: 0.5 | G14: 3.834 | H14: 5.738 | I14: 2.024 | J14: 3.013 | K14: 5.354 | L14: 0.5 | M14: 3.222 | N14: 0.5 | O14: 5.55 | P14: 1.046 | Q14: 3.046 | R14: =SUM(D14:Q14) -> 40.045 | S14: =D14+E14+F14+G14+H14+I14 -> 17.814 | T14: =J14+K14+L14+M14 -> 12.089 | U14: =N14+O14 -> 6.05 | V14: =P14+Q14 -> 4.092
A15: RMR3 | B15: Mid-stream | C15: Rui | D15: 2.268 | E15: 1.354 | F15: 0.5 | G15: 2.378 | H15: 5.394 | I15: 3.937 | J15: 1.198 | K15: 5.243 | L15: 0.5 | M15: 3.304 | N15: 0.5 | O15: 5.63 | P15: 1.594 | Q15: 3.695 | R15: =SUM(D15:Q15) -> 37.495 | S15: =D15+E15+F15+G15+H15+I15 -> 15.831 | T15: =J15+K15+L15+M15 -> 10.245 | U15: =N15+O15 -> 6.13 | V15: =P15+Q15 -> 5.289
... A30: MDR3 | B30: Down-stream | C30: Mrigal | D30: 5.936 | E30: 7.085 | F30: 3.256 | G30: 4.936 | H30: 7.389 | I30: 7.257 | J30: 6.339 | K30: 6.312 | L30: 2.937 | M30: 6.111 | N30: 5.72 | O30: 6.72 | P30: 3.294 | Q30: 4.414 | R30: =SUM(D30:Q30) -> 77.706 | S30: =D30+E30+F30+G30+H30+I30 -> 35.859 | T30: =J30+K30+L30+M30 -> 21.699 | U30: =N30+O30 -> 12.44 | V30: =P30+Q30 -> 7.708
A32: Source: user-provided Fish.xlsx. A value of 0 denotes a concentration below the analytical detection limit (retained as zero; no substitution applied).

Sheet Descriptive Stats
A1: Table 4.3 — Descriptive statistics for individual OCPs in fish muscle (µg/kg ww, n = 27)
A3: Compound | B3: Mean (µg/kg ww) | C3: SD | D3: Min (µg/kg ww) | E3: Max (µg/kg ww) | F3: Detection frequency (%) | G3: n
A4: o,p'-DDT | B4: =AVERAGE('Raw Data'!D4:D30) -> 1.9531481 | C4: =STDEV('Raw Data'!D4:D30) -> 1.5344713 | D4: =MIN('Raw Data'!D4:D30) -> 0.5 | E4: =MAX('Raw Data'!D4:D30) -> 5.936 | F4: =COUNTIF('Raw Data'!D4:D30,">0")/COUNT('Raw Data'!D4:D30)*100 -> 100 | G4: =COUNT('Raw Data'!D4:D30) -> 27
A5: p,p'-DDT | B5: =AVERAGE('Raw Data'!E4:E30) -> 2.7546296 | C5: =STDEV('Raw Data'!E4:E30) -> 1.8699775 | D5: =MIN('Raw Data'!E4:E30) -> 0.5 | E5: =MAX('Raw Data'!E4:E30) -> 7.085 | F5: =COUNTIF('Raw Data'!E4:E30,">0")/COUNT('Raw Data'!E4:E30)*100 -> 100 | G5: =COUNT('Raw Data'!E4:E30) -> 27
A6: o,p'-DDD | B6: =AVERAGE('Raw Data'!F4:F30) -> 1.221037 | C6: =STDEV('Raw Data'!F4:F30) -> 1.5445166 | D6: =MIN('Raw Data'!F4:F30) -> 0.5 | E6: =MAX('Raw Data'!F4:F30) -> 6.916 | F6: =COUNTIF('Raw Data'!F4:F30,">0")/COUNT('Raw Data'!F4:F30)*100 -> 100 | G6: =COUNT('Raw Data'!F4:F30) -> 27
A7: p,p'-DDD | B7: =AVERAGE('Raw Data'!G4:G30) -> 2.3694444 | C7: =STDEV('Raw Data'!G4:G30) -> 1.3311547 | D7: =MIN('Raw Data'!G4:G30) -> 0.5 | E7: =MAX('Raw Data'!G4:G30) -> 6.236 | F7: =COUNTIF('Raw Data'!G4:G30,">0")/COUNT('Raw Data'!G4:G30)*100 -> 100 | G7: =COUNT('Raw Data'!G4:G30) -> 27
A8: o,p'-DDE | B8: =AVERAGE('Raw Data'!H4:H30) -> 4.4041111 | C8: =STDEV('Raw Data'!H4:H30) -> 2.4195815 | D8: =MIN('Raw Data'!H4:H30) -> 0.5 | E8: =MAX('Raw Data'!H4:H30) -> 7.443 | F8: =COUNTIF('Raw Data'!H4:H30,">0")/COUNT('Raw Data'!H4:H30)*100 -> 100 | G8: =COUNT('Raw Data'!H4:H30) -> 27
A9: p,p'-DDE | B9: =AVERAGE('Raw Data'!I4:I30) -> 4.4995556 | C9: =STDEV('Raw Data'!I4:I30) -> 2.1804094 | D9: =MIN('Raw Data'!I4:I30) -> 0.5 | E9: =MAX('Raw Data'!I4:I30) -> 8.836 | F9: =COUNTIF('Raw Data'!I4:I30,">0")/COUNT('Raw Data'!I4:I30)*100 -> 100 | G9: =COUNT('Raw Data'!I4:I30) -> 27
A10: α-HCH | B10: =AVERAGE('Raw Data'!J4:J30) -> 2.5724444 | C10: =STDEV('Raw Data'!J4:J30) -> 1.7529061 | D10: =MIN('Raw Data'!J4:J30) -> 0.5 | E10: =MAX('Raw Data'!J4:J30) -> 6.687 | F10: =COUNTIF('Raw Data'!J4:J30,">0")/COUNT('Raw Data'!J4:J30)*100 -> 100 | G10: =COUNT('Raw Data'!J4:J30) -> 27
A11: β-HCH | B11: =AVERAGE('Raw Data'!K4:K30) -> 5.0496296 | C11: =STDEV('Raw Data'!K4:K30) -> 1.8593817 | D11: =MIN('Raw Data'!K4:K30) -> 0.5 | E11: =MAX('Raw Data'!K4:K30) -> 7.092 | F11: =COUNTIF('Raw Data'!K4:K30,">0")/COUNT('Raw Data'!K4:K30)*100 -> 100 | G11: =COUNT('Raw Data'!K4:K30) -> 27
A12: γ-HCH (Lindane) | B12: =AVERAGE('Raw Data'!L4:L30) -> 0.89718519 | C12: =STDEV('Raw Data'!L4:L30) -> 0.79349684 | D12: =MIN('Raw Data'!L4:L30) -> 0.5 | E12: =MAX('Raw Data'!L4:L30) -> 2.986 | F12: =COUNTIF('Raw Data'!L4:L30,">0")/COUNT('Raw Data'!L4:L30)*100 -> 100 | G12: =COUNT('Raw Data'!L4:L30) -> 27
A13: δ-HCH | B13: =AVERAGE('Raw Data'!M4:M30) -> 2.733 | C13: =STDEV('Raw Data'!M4:M30) -> 1.7933237 | D13: =MIN('Raw Data'!M4:M30) -> 0.5 | E13: =MAX('Raw Data'!M4:M30) -> 6.111 | F13: =COUNTIF('Raw Data'!M4:M30,">0")/COUNT('Raw Data'!M4:M30)*100 -> 100 | G13: =COUNT('Raw Data'!M4:M30) -> 27
A14: Aldrin | B14: =AVERAGE('Raw Data'!N4:N30) -> 2.3730741 | C14: =STDEV('Raw Data'!N4:N30) -> 2.3980942 | D14: =MIN('Raw Data'!N4:N30) -> 0.5 | E14: =MAX('Raw Data'!N4:N30) -> 6.067 | F14: =COUNTIF('Raw Data'!N4:N30,">0")/COUNT('Raw Data'!N4:N30)*100 -> 100 | G14: =COUNT('Raw Data'!N4:N30) -> 27
A15: Dieldrin | B15: =AVERAGE('Raw Data'!O4:O30) -> 3.6557778 | C15: =STDEV('Raw Data'!O4:O30) -> 2.918586 | D15: =MIN('Raw Data'!O4:O30) -> 0.5 | E15: =MAX('Raw Data'!O4:O30) -> 7.837 | F15: =COUNTIF('Raw Data'!O4:O30,">0")/COUNT('Raw Data'!O4:O30)*100 -> 100 | G15: =COUNT('Raw Data'!O4:O30) -> 27
A16: Heptachlor | B16: =AVERAGE('Raw Data'!P4:P30) -> 1.5165185 | C16: =STDEV('Raw Data'!P4:P30) -> 1.1598377 | D16: =MIN('Raw Data'!P4:P30) -> 0.5 | E16: =MAX('Raw Data'!P4:P30) -> 3.689 | F16: =COUNTIF('Raw Data'!P4:P30,">0")/COUNT('Raw Data'!P4:P30)*100 -> 100 | G16: =COUNT('Raw Data'!P4:P30) -> 27
A17: Heptachlor epoxide | B17: =AVERAGE('Raw Data'!Q4:Q30) -> 2.7272222 | C17: =STDEV('Raw Data'!Q4:Q30) -> 1.7759989 | D17: =MIN('Raw Data'!Q4:Q30) -> 0.5 | E17: =MAX('Raw Data'!Q4:Q30) -> 5.452 | F17: =COUNTIF('Raw Data'!Q4:Q30,">0")/COUNT('Raw Data'!Q4:Q30)*100 -> 100 | G17: =COUNT('Raw Data'!Q4:Q30) -> 27
A18: ΣOCP (sum of all 14 congeners) | B18: =AVERAGE('Raw Data'!R4:R30) -> 38.726778 | C18: =STDEV('Raw Data'!R4:R30) -> 20.772094 | D18: =MIN('Raw Data'!D4:Q30) -> 0.5 | E18: =MAX('Raw Data'!D4:Q30) -> 8.836 | F18: =COUNTIF('Raw Data'!Q5:Q31,">0")/COUNT('Raw Data'!Q5:Q31)*100 -> 100
A19: ΣDDT | B19: =AVERAGE('Raw Data'!S4:S30) -> 17.201926 | C19: =STDEV('Raw Data'!S4:S30) -> 9.302187 | D19: =MIN('Raw Data'!D4:I30) -> 0.5 | E19: =MAX('Raw Data'!D4:I30) -> 8.836 | F19: =COUNTIF('Raw Data'!Q6:Q32,">0")/COUNT('Raw Data'!Q6:Q32)*100 -> 100
A20: ΣHCH | B20: =AVERAGE('Raw Data'!T4:T30) -> 11.252259 | C20: =STDEV('Raw Data'!T4:T30) -> 5.1314894 | D20: =MIN('Raw Data'!J4:M30) -> 0.5 | E20: =MAX('Raw Data'!J4:M30) -> 7.092 | F20: =COUNTIF('Raw Data'!Q7:Q33,">0")/COUNT('Raw Data'!Q7:Q33)*100 -> 100
A21: ΣDRN | B21: =AVERAGE('Raw Data'!U4:U30) -> 6.0288519 | C21: =STDEV('Raw Data'!U4:U30) -> 4.9713586 | D21: =MIN('Raw Data'!N4:O30) -> 0.5 | E21: =MAX('Raw Data'!N4:O30) -> 7.837 | F21: =COUNTIF('Raw Data'!Q8:Q34,">0")/COUNT('Raw Data'!Q8:Q34)*100 -> 100
A22: ΣHPT | B22: =AVERAGE('Raw Data'!V4:V30) -> 4.2437407 | C22: =STDEV('Raw Data'!V4:V30) -> 2.74234 | D22: =MIN('Raw Data'!P4:Q30) -> 0.5 | E22: =MAX('Raw Data'!P4:Q30) -> 5.452 | F22: =COUNTIF('Raw Data'!Q9:Q35,">0")/COUNT('Raw Data'!Q9:Q35)*100 -> 100

Sheet Group Mean Concentrations
A1: Mean OCP concentration (µg/kg ww) by zone, species and overall — feeds Table 4.4 and the risk calculations
A3: Compound | B3: Up-stream | C3: Mid-stream | D3: Down-stream | E3: Catla | F3: Rui | G3: Mrigal | H3: Overall
A4: o,p'-DDT | B4: =AVERAGEIFS('Raw Data'!D4:D30,'Raw Data'!B4:B30,"Up-stream") -> 0.84733333 | C4: =AVERAGEIFS('Raw Data'!D4:D30,'Raw Data'!B4:B30,"Mid-stream") -> 1.5281111 | D4: =AVERAGEIFS('Raw Data'!D4:D30,'Raw Data'!B4:B30,"Down-stream") -> 3.484 | E4: =AVERAGEIFS('Raw Data'!D4:D30,'Raw Data'!C4:C30,"Catla") -> 1.0756667 | F4: =AVERAGEIFS('Raw Data'!D4:D30,'Raw Data'!C4:C30,"Rui") -> 1.8882222 | G4: =AVERAGEIFS('Raw Data'!D4:D30,'Raw Data'!C4:C30,"Mrigal") -> 2.8955556 | H4: =AVERAGE('Raw Data'!D4:D30) -> 1.9531481
A5: p,p'-DDT | B5: =AVERAGEIFS('Raw Data'!E4:E30,'Raw Data'!B4:B30,"Up-stream") -> 1.2557778 | C5: =AVERAGEIFS('Raw Data'!E4:E30,'Raw Data'!B4:B30,"Mid-stream") -> 2.9981111 | D5: =AVERAGEIFS('Raw Data'!E4:E30,'Raw Data'!B4:B30,"Down-stream") -> 4.01 | E5: =AVERAGEIFS('Raw Data'!E4:E30,'Raw Data'!C4:C30,"Catla") -> 1.5661111 | F5: =AVERAGEIFS('Raw Data'!E4:E30,'Raw Data'!C4:C30,"Rui") -> 2.1482222 | G5: =AVERAGEIFS('Raw Data'!E4:E30,'Raw Data'!C4:C30,"Mrigal") -> 4.5495556 | H5: =AVERAGE('Raw Data'!E4:E30) -> 2.7546296
A6: o,p'-DDD | B6: =AVERAGEIFS('Raw Data'!F4:F30,'Raw Data'!B4:B30,"Up-stream") -> 0.5 | C6: =AVERAGEIFS('Raw Data'!F4:F30,'Raw Data'!B4:B30,"Mid-stream") -> 0.5 | D6: =AVERAGEIFS('Raw Data'!F4:F30,'Raw Data'!B4:B30,"Down-stream") -> 2.6631111 | E6: =AVERAGEIFS('Raw Data'!F4:F30,'Raw Data'!C4:C30,"Catla") -> 0.5 | F6: =AVERAGEIFS('Raw Data'!F4:F30,'Raw Data'!C4:C30,"Rui") -> 1.285 | G6: =AVERAGEIFS('Raw Data'!F4:F30,'Raw Data'!C4:C30,"Mrigal") -> 1.8781111 | H6: =AVERAGE('Raw Data'!F4:F30) -> 1.221037
A7: p,p'-DDD | B7: =AVERAGEIFS('Raw Data'!G4:G30,'Raw Data'!B4:B30,"Up-stream") -> 1.677 | C7: =AVERAGEIFS('Raw Data'!G4:G30,'Raw Data'!B4:B30,"Mid-stream") -> 2.1291111 | D7: =AVERAGEIFS('Raw Data'!G4:G30,'Raw Data'!B4:B30,"Down-stream") -> 3.3022222 | E7: =AVERAGEIFS('Raw Data'!G4:G30,'Raw Data'!C4:C30,"Catla") -> 1.4481111 | F7: =AVERAGEIFS('Raw Data'!G4:G30,'Raw Data'!C4:C30,"Rui") -> 2.3781111 | G7: =AVERAGEIFS('Raw Data'!G4:G30,'Raw Data'!C4:C30,"Mrigal") -> 3.2821111 | H7: =AVERAGE('Raw Data'!G4:G30) -> 2.3694444
A8: o,p'-DDE | B8: =AVERAGEIFS('Raw Data'!H4:H30,'Raw Data'!B4:B30,"Up-stream") -> 1.8945556 | C8: =AVERAGEIFS('Raw Data'!H4:H30,'Raw Data'!B4:B30,"Mid-stream") -> 4.9821111 | D8: =AVERAGEIFS('Raw Data'!H4:H30,'Raw Data'!B4:B30,"Down-stream") -> 6.3356667 | E8: =AVERAGEIFS('Raw Data'!H4:H30,'Raw Data'!C4:C30,"Catla") -> 3.3081111 | F8: =AVERAGEIFS('Raw Data'!H4:H30,'Raw Data'!C4:C30,"Rui") -> 4.3662222 | G8: =AVERAGEIFS('Raw Data'!H4:H30,'Raw Data'!C4:C30,"Mrigal") -> 5.538 | H8: =AVERAGE('Raw Data'!H4:H30) -> 4.4041111
A9: p,p'-DDE | B9: =AVERAGEIFS('Raw Data'!I4:I30,'Raw Data'!B4:B30,"Up-stream") -> 3.0661111 | C9: =AVERAGEIFS('Raw Data'!I4:I30,'Raw Data'!B4:B30,"Mid-stream") -> 4.1381111 | D9: =AVERAGEIFS('Raw Data'!I4:I30,'Raw Data'!B4:B30,"Down-stream") -> 6.2944444 | E9: =AVERAGEIFS('Raw Data'!I4:I30,'Raw Data'!C4:C30,"Catla") -> 3.5103333 | F9: =AVERAGEIFS('Raw Data'!I4:I30,'Raw Data'!C4:C30,"Rui") -> 3.5765556 | G9: =AVERAGEIFS('Raw Data'!I4:I30,'Raw Data'!C4:C30,"Mrigal") -> 6.4117778 | H9: =AVERAGE('Raw Data'!I4:I30) -> 4.4995556
A10: α-HCH | B10: =AVERAGEIFS('Raw Data'!J4:J30,'Raw Data'!B4:B30,"Up-stream") -> 2.1293333 | C10: =AVERAGEIFS('Raw Data'!J4:J30,'Raw Data'!B4:B30,"Mid-stream") -> 1.8408889 | D10: =AVERAGEIFS('Raw Data'!J4:J30,'Raw Data'!B4:B30,"Down-stream") -> 3.7471111 | E10: =AVERAGEIFS('Raw Data'!J4:J30,'Raw Data'!C4:C30,"Catla") -> 1.4833333 | F10: =AVERAGEIFS('Raw Data'!J4:J30,'Raw Data'!C4:C30,"Rui") -> 1.824 | G10: =AVERAGEIFS('Raw Data'!J4:J30,'Raw Data'!C4:C30,"Mrigal") -> 4.41 | H10: =AVERAGE('Raw Data'!J4:J30) -> 2.5724444
A11: β-HCH | B11: =AVERAGEIFS('Raw Data'!K4:K30,'Raw Data'!B4:B30,"Up-stream") -> 3.8474444 | C11: =AVERAGEIFS('Raw Data'!K4:K30,'Raw Data'!B4:B30,"Mid-stream") -> 5.1592222 | D11: =AVERAGEIFS('Raw Data'!K4:K30,'Raw Data'!B4:B30,"Down-stream") -> 6.1422222 | E11: =AVERAGEIFS('Raw Data'!K4:K30,'Raw Data'!C4:C30,"Catla") -> 3.6184444 | F11: =AVERAGEIFS('Raw Data'!K4:K30,'Raw Data'!C4:C30,"Rui") -> 5.6588889 | G11: =AVERAGEIFS('Raw Data'!K4:K30,'Raw Data'!C4:C30,"Mrigal") -> 5.8715556 | H11: =AVERAGE('Raw Data'!K4:K30) -> 5.0496296
A12: γ-HCH (Lindane) | B12: =AVERAGEIFS('Raw Data'!L4:L30,'Raw Data'!B4:B30,"Up-stream") -> 0.5 | C12: =AVERAGEIFS('Raw Data'!L4:L30,'Raw Data'!B4:B30,"Mid-stream") -> 0.5 | D12: =AVERAGEIFS('Raw Data'!L4:L30,'Raw Data'!B4:B30,"Down-stream") -> 1.6915556 | E12: =AVERAGEIFS('Raw Data'!L4:L30,'Raw Data'!C4:C30,"Catla") -> 0.5 | F12: =AVERAGEIFS('Raw Data'!L4:L30,'Raw Data'!C4:C30,"Rui") -> 0.95877778 | G12: =AVERAGEIFS('Raw Data'!L4:L30,'Raw Data'!C4:C30,"Mrigal") -> 1.2327778 | H12: =AVERAGE('Raw Data'!L4:L30) -> 0.89718519
A13: δ-HCH | B13: =AVERAGEIFS('Raw Data'!M4:M30,'Raw Data'!B4:B30,"Up-stream") -> 2.2692222 | C13: =AVERAGEIFS('Raw Data'!M4:M30,'Raw Data'!B4:B30,"Mid-stream") -> 1.6841111 | D13: =AVERAGEIFS('Raw Data'!M4:M30,'Raw Data'!B4:B30,"Down-stream") -> 4.2456667 | E13: =AVERAGEIFS('Raw Data'!M4:M30,'Raw Data'!C4:C30,"Catla") -> 1.2675556 | F13: =AVERAGEIFS('Raw Data'!M4:M30,'Raw Data'!C4:C30,"Rui") -> 3.1438889 | G13: =AVERAGEIFS('Raw Data'!M4:M30,'Raw Data'!C4:C30,"Mrigal") -> 3.7875556 | H13: =AVERAGE('Raw Data'!M4:M30) -> 2.733
A14: Aldrin | B14: =AVERAGEIFS('Raw Data'!N4:N30,'Raw Data'!B4:B30,"Up-stream") -> 0.5 | C14: =AVERAGEIFS('Raw Data'!N4:N30,'Raw Data'!B4:B30,"Mid-stream") -> 1.5228889 | D14: =AVERAGEIFS('Raw Data'!N4:N30,'Raw Data'!B4:B30,"Down-stream") -> 5.0963333 | E14: =AVERAGEIFS('Raw Data'!N4:N30,'Raw Data'!C4:C30,"Catla") -> 1.7044444 | F14: =AVERAGEIFS('Raw Data'!N4:N30,'Raw Data'!C4:C30,"Rui") -> 2.1003333 | G14: =AVERAGEIFS('Raw Data'!N4:N30,'Raw Data'!C4:C30,"Mrigal") -> 3.3144444 | H14: =AVERAGE('Raw Data'!N4:N30) -> 2.3730741
A15: Dieldrin | B15: =AVERAGEIFS('Raw Data'!O4:O30,'Raw Data'!B4:B30,"Up-stream") -> 0.5 | C15: =AVERAGEIFS('Raw Data'!O4:O30,'Raw Data'!B4:B30,"Mid-stream") -> 4.1962222 | D15: =AVERAGEIFS('Raw Data'!O4:O30,'Raw Data'!B4:B30,"Down-stream") -> 6.2711111 | E15: =AVERAGEIFS('Raw Data'!O4:O30,'Raw Data'!C4:C30,"Catla") -> 2.2125556 | F15: =AVERAGEIFS('Raw Data'!O4:O30,'Raw Data'!C4:C30,"Rui") -> 4.1302222 | G15: =AVERAGEIFS('Raw Data'!O4:O30,'Raw Data'!C4:C30,"Mrigal") -> 4.6245556 | H15: =AVERAGE('Raw Data'!O4:O30) -> 3.6557778
A16: Heptachlor | B16: =AVERAGEIFS('Raw Data'!P4:P30,'Raw Data'!B4:B30,"Up-stream") -> 0.5 | C16: =AVERAGEIFS('Raw Data'!P4:P30,'Raw Data'!B4:B30,"Mid-stream") -> 1.4706667 | D16: =AVERAGEIFS('Raw Data'!P4:P30,'Raw Data'!B4:B30,"Down-stream") -> 2.5788889 | E16: =AVERAGEIFS('Raw Data'!P4:P30,'Raw Data'!C4:C30,"Catla") -> 0.94911111 | F16: =AVERAGEIFS('Raw Data'!P4:P30,'Raw Data'!C4:C30,"Rui") -> 1.593 | G16: =AVERAGEIFS('Raw Data'!P4:P30,'Raw Data'!C4:C30,"Mrigal") -> 2.0074444 | H16: =AVERAGE('Raw Data'!P4:P30) -> 1.5165185
A17: Heptachlor epoxide | B17: =AVERAGEIFS('Raw Data'!Q4:Q30,'Raw Data'!B4:B30,"Up-stream") -> 1.3775556 | C17: =AVERAGEIFS('Raw Data'!Q4:Q30,'Raw Data'!B4:B30,"Mid-stream") -> 2.6085556 | D17: =AVERAGEIFS('Raw Data'!Q4:Q30,'Raw Data'!B4:B30,"Down-stream") -> 4.1955556 | E17: =AVERAGEIFS('Raw Data'!Q4:Q30,'Raw Data'!C4:C30,"Catla") -> 1.3983333 | F17: =AVERAGEIFS('Raw Data'!Q4:Q30,'Raw Data'!C4:C30,"Rui") -> 2.682 | G17: =AVERAGEIFS('Raw Data'!Q4:Q30,'Raw Data'!C4:C30,"Mrigal") -> 4.1013333 | H17: =AVERAGE('Raw Data'!Q4:Q30) -> 2.7272222
A19: ΣOCP — Mean (µg/kg ww) | B19: =AVERAGEIFS('Raw Data'!R4:R30,'Raw Data'!B4:B30,"Up-stream") -> 20.864333 | C19: =AVERAGEIFS('Raw Data'!R4:R30,'Raw Data'!B4:B30,"Mid-stream") -> 35.258111 | D19: =AVERAGEIFS('Raw Data'!R4:R30,'Raw Data'!B4:B30,"Down-stream") -> 60.057889 | E19: =AVERAGEIFS('Raw Data'!R4:R30,'Raw Data'!C4:C30,"Catla") -> 24.542111 | F19: =AVERAGEIFS('Raw Data'!R4:R30,'Raw Data'!C4:C30,"Rui") -> 37.733444 | G19: =AVERAGEIFS('Raw Data'!R4:R30,'Raw Data'!C4:C30,"Mrigal") -> 53.904778 | H19: =AVERAGE('Raw Data'!R4:R30) -> 38.726778
A20: ΣOCP — SD | B20: =SQRT(SUMPRODUCT(('Raw Data'!B4:B30="Up-stream")*('Raw Data'!R4:R30-AVERAGEIFS('Raw Data'!R4:R30,'Raw Data'!B4:B30,"Up-stream"))^2)/(COUNTIF('Raw Data'!B4:B30,"Up-stream")-1)) -> 12.258916 | C20: =SQRT(SUMPRODUCT(('Raw Data'!B4:B30="Mid-stream")*('Raw Data'!R4:R30-AVERAGEIFS('Raw Data'!R4:R30,'Raw Data'!B4:B30,"Mid-stream"))^2)/(COUNTIF('Raw Data'!B4:B30,"Mid-stream")-1)) -> 12.676305 | D20: =SQRT(SUMPRODUCT(('Raw Data'!B4:B30="Down-stream")*('Raw Data'!R4:R30-AVERAGEIFS('Raw Data'!R4:R30,'Raw Data'!B4:B30,"Down-stream"))^2)/(COUNTIF('Raw Data'!B4:B30,"Down-stream")-1)) -> 14.386126 | E20: =SQRT(SUMPRODUCT(('Raw Data'!C4:C30="Catla")*('Raw Data'!R4:R30-AVERAGEIFS('Raw Data'!R4:R30,'Raw Data'!C4:C30,"Catla"))^2)/(COUNTIF('Raw Data'!C4:C30,"Catla")-1)) -> 17.222508 | F20: =SQRT(SUMPRODUCT(('Raw Data'!C4:C30="Rui")*('Raw Data'!R4:R30-AVERAGEIFS('Raw Data'!R4:R30,'Raw Data'!C4:C30,"Rui"))^2)/(COUNTIF('Raw Data'!C4:C30,"Rui")-1)) -> 15.813489 | G20: =SQRT(SUMPRODUCT(('Raw Data'!C4:C30="Mrigal")*('Raw Data'!R4:R30-AVERAGEIFS('Raw Data'!R4:R30,'Raw Data'!C4:C30,"Mrigal"))^2)/(COUNTIF('Raw Data'!C4:C30,"Mrigal")-1)) -> 19.209237 | H20: =STDEV('Raw Data'!R4:R30) -> 20.772094

Sheet Exposure & Toxicity Inputs
A1: Table 4.1 — Exposure parameters used in the risk calculation
A3: Parameter | B3: Adult | C3: Child | D3: Source / basis
A4: Body weight, BW (kg) | B4: 70 | C4: 15 | D4: USEPA Exposure Factors Handbook (2011) default
A5: Fish ingestion rate, IR (g/day) | B5: 74 | C5: 37 | D5: Bangladesh national per-capita fish consumption, ≈27 kg/capita/yr (FAO/DoF statistics, 2023); child assumed 50% of adult portion in the absence of an age-disaggregated national survey
A6: Exposure frequency, EF (days/yr) | B6: 365 | C6: 365 | D6: USEPA (1989) default
A7: Exposure duration, ED (yr) | B7: 70 | C7: 6 | D7: USEPA (1989) default lifetime / childhood exposure duration
A8: Averaging time, AT — non-carcinogenic (days) | B8: =B7*365 -> 25550 | C8: =C7*365 -> 2190 | D8: USEPA (1989); AT = ED × 365
A9: Averaging time, AT — carcinogenic (days) | B9: =70*365 -> 25550 | C9: =70*365 -> 25550 | D9: USEPA (1989), lifetime (70 yr) for both adult and child
A12: Table 4.2 — Oral reference doses (RfD) and cancer slope factors (CSF) applied
A14: Compound | B14: RfD (mg/kg-day) | C14: CSF (mg/kg-day)⁻¹ | D14: RfD basis | E14: CSF basis
A15: o,p'-DDT | B15: 0.0005 | C15: 0.34 | D15: USEPA IRIS (DDT) | E15: USEPA IRIS (DDT)
A16: p,p'-DDT | B16: 0.0005 | C16: 0.34 | D16: USEPA IRIS (DDT) | E16: USEPA IRIS (DDT)
A17: o,p'-DDD | B17: 0.0005 | C17: 0.34 | D17: Surrogate: DDT (IRIS) | E17: Surrogate: DDT (IRIS)
A18: p,p'-DDD | B18: 0.0005 | C18: 0.34 | D18: Surrogate: DDT (IRIS) | E18: Surrogate: DDT (IRIS)
A19: o,p'-DDE | B19: 0.0005 | C19: 0.34 | D19: Surrogate: DDT (IRIS) | E19: Surrogate: DDT (IRIS)
A20: p,p'-DDE | B20: 0.0005 | C20: 0.34 | D20: Surrogate: DDT (IRIS) | E20: Surrogate: DDT (IRIS)
A21: α-HCH | B21: 0.0003 | C21: 6.3 | D21: RfD surrogate: γ-HCH (IRIS) | E21: IRIS/Cal-EPA
A22: β-HCH | B22: 0.0003 | C22: 1.8 | D22: RfD surrogate: γ-HCH (IRIS) | E22: Cal-EPA
A23: γ-HCH (Lindane) | B23: 0.0003 | C23: 1.3 | D23: USEPA IRIS | E23: USEPA IRIS
A24: δ-HCH | B24: 0.0003 | C24: not classified | D24: RfD surrogate: γ-HCH (IRIS) | E24: Not classified
A25: Aldrin | B25: 3e-05 | C25: 17 | D25: USEPA IRIS | E25: USEPA IRIS
A26: Dieldrin | B26: 5e-05 | C26: 16 | D26: USEPA IRIS | E26: USEPA IRIS
A27: Heptachlor | B27: 0.0005 | C27: 4.5 | D27: USEPA IRIS | E27: USEPA IRIS
A28: Heptachlor epoxide | B28: 1.3e-05 | C28: 9.1 | D28: USEPA IRIS | E28: USEPA IRIS
A30: Where a compound-specific chronic RfD is not listed on IRIS, the value of the closest structural congener was applied as a conservative surrogate (see basis columns). Cross-check against the current USEPA IRIS database (epa.gov/iris) before final submission.

Sheet Risk Assessment
A1: Target Hazard Quotient (THQ), Hazard Index (HI) and Cancer Risk (CR), by grouping and consumer
A2: EDI = (C × IR × EF × ED) / (BW × AT) | THQ = EDI / RfD | HI = ΣTHQ | CR = EDI(carcinogenic) × CSF
A3: THQ by compound (dimensionless)
A4: Compound | B4: Up-stream | D4: Mid-stream | F4: Down-stream | H4: Catla | J4: Rui | L4: Mrigal | N4: Overall
B5: Adult | C5: Child | D5: Adult | E5: Child | F5: Adult | G5: Child | H5: Adult | I5: Child | J5: Adult | K5: Child | L5: Adult | M5: Child | N5: Adult | O5: Child
A6: o,p'-DDT | B6: =(('Group Mean Concentrations'!B4/1000)*('Exposure & Toxicity Inputs'!B5/1000)*'Exposure & Toxicity Inputs'!B6*'Exposure & Toxicity Inputs'!B7)/('Exposure & Toxicity Inputs'!B4*'Exposure & Toxicity Inputs'!B8)/'Exposure & Toxicity Inputs'!B15 -> 0.0017915048 | C6: =(('Group Mean Concentrations'!B4/1000)*('Exposure & Toxicity Inputs'!C5/1000)*'Exposure & Toxicity Inputs'!C6*'Exposure & Toxicity Inputs'!C7)/('Exposure & Toxicity Inputs'!C4*'Exposure & Toxicity Inputs'!C8)/'Exposure & Toxicity Inputs'!B15 -> 0.0041801778 | D6: =(('Group Mean Concentrations'!C4/1000)*('Exposure & Toxicity Inputs'!B5/1000)*'Exposure & Toxicity Inputs'!B6*'Exposure & Toxicity Inputs'!B7)/('Exposure & Toxicity Inputs'!B4*'Exposure & Toxicity Inputs'!B8)/'Exposure & Toxicity Inputs'!B15 -> 0.0032308635 | E6: =(('Group Mean Concentrations'!C4/1000)*('Exposure & Toxicity Inputs'!C5/1000)*'Exposure & Toxicity Inputs'!C6*'Exposure & Toxicity Inputs'!C7)/('Exposure & Toxicity Inputs'!C4*'Exposure & Toxicity Inputs'!C8)/'Exposure & Toxicity Inputs'!B15 -> 0.0075386815 | F6: =(('Group Mean Concentrations'!D4/1000)*('Exposure & Toxicity Inputs'!B5/1000)*'Exposure & Toxicity Inputs'!B6*'Exposure & Toxicity Inputs'!B7)/('Exposure & Toxicity Inputs'!B4*'Exposure & Toxicity Inputs'!B8)/'Exposure & Toxicity Inputs'!B15 -> 0.0073661714 | G6: =(('Group Mean Concentrations'!D4/1000)*('Exposure & Toxicity Inputs'!C5/1000)*'Exposure & Toxicity Inputs'!C6*'Exposure & Toxicity Inputs'!C7)/('Exposure & Toxicity Inputs'!C4*'Exposure & Toxicity Inputs'!C8)/'Exposure & Toxicity Inputs'!B15 -> 0.017187733 | H6: =(('Group Mean Concentrations'!E4/1000)*('Exposure & Toxicity Inputs'!B5/1000)*'Exposure & Toxicity Inputs'!B6*'Exposure & Toxicity Inputs'!B7)/('Exposure & Toxicity Inputs'!B4*'Exposure & Toxicity Inputs'!B8)/'Exposure & Toxicity Inputs'!B15 -> 0.0022742667 | I6: =(('Group Mean Concentrations'!E4/1000)*('Exposure & Toxicity Inputs'!C5/1000)*'Exposure & Toxicity Inputs'!C6*'Exposure & Toxicity Inputs'!C7)/('Exposure & Toxicity Inputs'!C4*'Exposure & Toxicity Inputs'!C8)/'Exposure & Toxicity Inputs'!B15 -> 0.0053066222 | J6: =(('Group Mean Concentrations'!F4/1000)*('Exposure & Toxicity Inputs'!B5/1000)*'Exposure & Toxicity Inputs'!B6*'Exposure & Toxicity Inputs'!B7)/('Exposure & Toxicity Inputs'!B4*'Exposure & Toxicity Inputs'!B8)/'Exposure & Toxicity Inputs'!B15 -> 0.0039922413 | K6: =(('Group Mean Concentrations'!F4/1000)*('Exposure & Toxicity Inputs'!C5/1000)*'Exposure & Toxicity Inputs'!C6*'Exposure & Toxicity Inputs'!C7)/('Exposure & Toxicity Inputs'!C4*'Exposure & Toxicity Inputs'!C8)/'Exposure & Toxicity Inputs'!B15 -> 0.0093152296 | L6: =(('Group Mean Concentrations'!G4/1000)*('Exposure & Toxicity Inputs'!B5/1000)*'Exposure & Toxicity Inputs'!B6*'Exposure & Toxicity Inputs'!B7)/('Exposure & Toxicity Inputs'!B4*'Exposure & Toxicity Inputs'!B8)/'Exposure & Toxicity Inputs'!B15 -> 0.0061220317 | M6: =(('Group Mean Concentrations'!G4/1000)*('Exposure & Toxicity Inputs'!C5/1000)*'Exposure & Toxicity Inputs'!C6*'Exposure & Toxicity Inputs'!C7)/('Exposure & Toxicity Inputs'!C4*'Exposure & Toxicity Inputs'!C8)/'Exposure & Toxicity Inputs'!B15 -> 0.014284741 | N6: =(('Group Mean Concentrations'!H4/1000)*('Exposure & Toxicity Inputs'!B5/1000)*'Exposure & Toxicity Inputs'!B6*'Exposure & Toxicity Inputs'!B7)/('Exposure & Toxicity Inputs'!B4*'Exposure & Toxicity Inputs'!B8)/'Exposure & Toxicity Inputs'!B15 -> 0.0041295132 | O6: =(('Group Mean Concentrations'!H4/1000)*('Exposure & Toxicity Inputs'!C5/1000)*'Exposure & Toxicity Inputs'!C6*'Exposure & Toxicity Inputs'!C7)/('Exposure & Toxicity Inputs'!C4*'Exposure & Toxicity Inputs'!C8)/'Exposure & Toxicity Inputs'!B15 -> 0.0096355309
A7: p,p'-DDT | B7: =(('Group Mean Concentrations'!B5/1000)*('Exposure & Toxicity Inputs'!B5/1000)*'Exposure & Toxicity Inputs'!B6*'Exposure & Toxicity Inputs'!B7)/('Exposure & Toxicity Inputs'!B4*'Exposure & Toxicity Inputs'!B8)/'Exposure & Toxicity Inputs'!B16 -> 0.002655073 | C7: =(('Group Mean Concentrations'!B5/1000)*('Exposure & Toxicity Inputs'!C5/1000)*'Exposure & Toxicity Inputs'!C6*'Exposure & Toxicity Inputs'!C7)/('Exposure & Toxicity Inputs'!C4*'Exposure & Toxicity Inputs'!C8)/'Exposure & Toxicity Inputs'!B16 -> 0.0061951704 | D7: =(('Group Mean Concentrations'!C5/1000)*('Exposure & Toxicity Inputs'!B5/1000)*'Exposure & Toxicity Inputs'!B6*'Exposure & Toxicity Inputs'!B7)/('Exposure & Toxicity Inputs'!B4*'Exposure & Toxicity Inputs'!B8)/'Exposure & Toxicity Inputs'!B16 -> 0.0063388635 | E7: =(('Group Mean Concentrations'!C5/1000)*('Exposure & Toxicity Inputs'!C5/1000)*'Exposure & Toxicity Inputs'!C6*'Exposure & Toxicity Inputs'!C7)/('Exposure & Toxicity Inputs'!C4*'Exposure & Toxicity Inputs'!C8)/'Exposure & Toxicity Inputs'!B16 -> 0.014790681 | F7: =(('Group Mean Concentrations'!D5/1000)*('Exposure & Toxicity Inputs'!B5/1000)*'Exposure & Toxicity Inputs'!B6*'Exposure & Toxicity Inputs'!B7)/('Exposure & Toxicity Inputs'!B4*'Exposure & Toxicity Inputs'!B8)/'Exposure & Toxicity Inputs'!B16 -> 0.0084782857 | G7: =(('Group Mean Concentrations'!D5/1000)*('Exposure & Toxicity Inputs'!C5/1000)*'Exposure & Toxicity Inputs'!C6*'Exposure & Toxicity Inputs'!C7)/('Exposure & Toxicity Inputs'!C4*'Exposure & Toxicity Inputs'!C8)/'Exposure & Toxicity Inputs'!B16 -> 0.019782667 | H7: =(('Group Mean Concentrations'!E5/1000)*('Exposure & Toxicity Inputs'!B5/1000)*'Exposure & Toxicity Inputs'!B6*'Exposure & Toxicity Inputs'!B7)/('Exposure & Toxicity Inputs'!B4*'Exposure & Toxicity Inputs'!B8)/'Exposure & Toxicity Inputs'!B16 -> 0.0033112063 | I7: =(('Group Mean Concentrations'!E5/1000)*('Exposure & Toxicity Inputs'!C5/1000)*'Exposure & Toxicity Inputs'!C6*'Exposure & Toxicity Inputs'!C7)/('Exposure & Toxicity Inputs'!C4*'Exposure & Toxicity Inputs'!C8)/'Exposure & Toxicity Inputs'!B16 -> 0.0077261481 | J7: =(('Group Mean Concentrations'!F5/1000)*('Exposure & Toxicity Inputs'!B5/1000)*'Exposure & Toxicity Inputs'!B6*'Exposure & Toxicity Inputs'!B7)/('Exposure & Toxicity Inputs'!B4*'Exposure & Toxicity Inputs'!B8)/'Exposure & Toxicity Inputs'!B16 -> 0.0045419556 | K7: =(('Group Mean Concentrations'!F5/1000)*('Exposure & Toxicity Inputs'!C5/1000)*'Exposure & Toxicity Inputs'!C6*'Exposure & Toxicity Inputs'!C7)/('Exposure & Toxicity Inputs'!C4*'Exposure & Toxicity Inputs'!C8)/'Exposure & Toxicity Inputs'!B16 -> 0.010597896 | L7: =(('Group Mean Concentrations'!G5/1000)*('Exposure & Toxicity Inputs'!B5/1000)*'Exposure & Toxicity Inputs'!B6*'Exposure & Toxicity Inputs'!B7)/('Exposure & Toxicity Inputs'!B4*'Exposure & Toxicity Inputs'!B8)/'Exposure & Toxicity Inputs'!B16 -> 0.0096190603 | M7: =(('Group Mean Concentrations'!G5/1000)*('Exposure & Toxicity Inputs'!C5/1000)*'Exposure & Toxicity Inputs'!C6*'Exposure & Toxicity Inputs'!C7)/('Exposure & Toxicity Inputs'!C4*'Exposure & Toxicity Inputs'!C8)/'Exposure & Toxicity Inputs'!B16 -> 0.022444474 | N7: =(('Group Mean Concentrations'!H5/1000)*('Exposure & Toxicity Inputs'!B5/1000)*'Exposure & Toxicity Inputs'!B6*'Exposure & Toxicity Inputs'!B7)/('Exposure & Toxicity Inputs'!B4*'Exposure & Toxicity Inputs'!B8)/'Exposure & Toxicity Inputs'!B16 -> 0.0058240741 | O7: =(('Group Mean Concentrations'!H5/1000)*('Exposure & Toxicity Inputs'!C5/1000)*'Exposure & Toxicity Inputs'!C6*'Exposure & Toxicity Inputs'!C7)/('Exposure & Toxicity Inputs'!C4*'Exposure & Toxicity Inputs'!C8)/'Exposure & Toxicity Inputs'!B16 -> 0.013589506
A8: o,p'-DDD | B8: =(('Group Mean Concentrations'!B6/1000)*('Exposure & Toxicity Inputs'!B5/1000)*'Exposure & Toxicity Inputs'!B6*'Exposure & Toxicity Inputs'!B7)/('Exposure & Toxicity Inputs'!B4*'Exposure & Toxicity Inputs'!B8)/'Exposure & Toxicity Inputs'!B17 -> 0.0010571429 | C8: =(('Group Mean Concentrations'!B6/1000)*('Exposure & Toxicity Inputs'!C5/1000)*'Exposure & Toxicity Inputs'!C6*'Exposure & Toxicity Inputs'!C7)/('Exposure & Toxicity Inputs'!C4*'Exposure & Toxicity Inputs'!C8)/'Exposure & Toxicity Inputs'!B17 -> 0.0024666667 | D8: =(('Group Mean Concentrations'!C6/1000)*('Exposure & Toxicity Inputs'!B5/1000)*'Exposure & Toxicity Inputs'!B6*'Exposure & Toxicity Inputs'!B7)/('Exposure & Toxicity Inputs'!B4*'Exposure & Toxicity Inputs'!B8)/'Exposure & Toxicity Inputs'!B17 -> 0.0010571429 | E8: =(('Group Mean Concentrations'!C6/1000)*('Exposure & Toxicity Inputs'!C5/1000)*'Exposure & Toxicity Inputs'!C6*'Exposure & Toxicity Inputs'!C7)/('Exposure & Toxicity Inputs'!C4*'Exposure & Toxicity Inputs'!C8)/'Exposure & Toxicity Inputs'!B17 -> 0.0024666667 | F8: =(('Group Mean Concentrations'!D6/1000)*('Exposure & Toxicity Inputs'!B5/1000)*'Exposure & Toxicity Inputs'!B6*'Exposure & Toxicity Inputs'!B7)/('Exposure & Toxicity Inputs'!B4*'Exposure & Toxicity Inputs'!B8)/'Exposure & Toxicity Inputs'!B17 -> 0.0056305778 | G8: =(('Group Mean Concentrations'!D6/1000)*('Exposure & Toxicity Inputs'!C5/1000)*'Exposure & Toxicity Inputs'!C6*'Exposure & Toxicity Inputs'!C7)/('Exposure & Toxicity Inputs'!C4*'Exposure & Toxicity Inputs'!C8)/'Exposure & Toxicity Inputs'!B17 -> 0.013138015 | H8: =(('Group Mean Concentrations'!E6/1000)*('Exposure & Toxicity Inputs'!B5/1000)*'Exposure & Toxicity Inputs'!B6*'Exposure & Toxicity Inputs'!B7)/('Exposure & Toxicity Inputs'!B4*'Exposure & Toxicity Inputs'!B8)/'Exposure & Toxicity Inputs'!B17 -> 0.0010571429 | I8: =(('Group Mean Concentrations'!E6/1000)*('Exposure & Toxicity Inputs'!C5/1000)*'Exposure & Toxicity Inputs'!C6*'Exposure & Toxicity Inputs'!C7)/('Exposure & Toxicity Inputs'!C4*'Exposure & Toxicity Inputs'!C8)/'Exposure & Toxicity Inputs'!B17 -> 0.0024666667 | J8: =(('Group Mean Concentrations'!F6/1000)*('Exposure & Toxicity Inputs'!B5/1000)*'Exposure & Toxicity Inputs'!B6*'Exposure & Toxicity Inputs'!B7)/('Exposure & Toxicity Inputs'!B4*'Exposure & Toxicity Inputs'!B8)/'Exposure & Toxicity Inputs'!B17 -> 0.0027168571 | K8: =(('Group Mean Concentrations'!F6/1000)*('Exposure & Toxicity Inputs'!C5/1000)*'Exposure & Toxicity Inputs'!C6*'Exposure & Toxicity Inputs'!C7)/('Exposure & Toxicity Inputs'!C4*'Exposure & Toxicity Inputs'!C8)/'Exposure & Toxicity Inputs'!B17 -> 0.0063393333 | L8: =(('Group Mean Concentrations'!G6/1000)*('Exposure & Toxicity Inputs'!B5/1000)*'Exposure & Toxicity Inputs'!B6*'Exposure & Toxicity Inputs'!B7)/('Exposure & Toxicity Inputs'!B4*'Exposure & Toxicity Inputs'!B8)/'Exposure & Toxicity Inputs'!B17 -> 0.0039708635 | M8: =(('Group Mean Concentrations'!G6/1000)*('Exposure & Toxicity Inputs'!C5/1000)*'Exposure & Toxicity Inputs'!C6*'Exposure & Toxicity Inputs'!C7)/('Exposure & Toxicity Inputs'!C4*'Exposure & Toxicity Inputs'!C8)/'Exposure & Toxicity Inputs'!B17 -> 0.0092653481 | N8: =(('Group Mean Concentrations'!H6/1000)*('Exposure & Toxicity Inputs'!B5/1000)*'Exposure & Toxicity Inputs'!B6*'Exposure & Toxicity Inputs'!B7)/('Exposure & Toxicity Inputs'!B4*'Exposure & Toxicity Inputs'!B8)/'Exposure & Toxicity Inputs'!B17 -> 0.0025816212 | O8: =(('Group Mean Concentrations'!H6/1000)*('Exposure & Toxicity Inputs'!C5/1000)*'Exposure & Toxicity Inputs'!C6*'Exposure & Toxicity Inputs'!C7)/('Exposure & Toxicity Inputs'!C4*'Exposure & Toxicity Inputs'!C8)/'Exposure & Toxicity Inputs'!B17 -> 0.0060237827
A9: p,p'-DDD | B9: =(('Group Mean Concentrations'!B7/1000)*('Exposure & Toxicity Inputs'!B5/1000)*'Exposure & Toxicity Inputs'!B6*'Exposure & Toxicity Inputs'!B7)/('Exposure & Toxicity Inputs'!B4*'Exposure & Toxicity Inputs'!B8)/'Exposure & Toxicity Inputs'!B18 -> 0.0035456571 | C9: =(('Group Mean Concentrations'!B7/1000)*('Exposure & Toxicity Inputs'!C5/1000)*'Exposure & Toxicity Inputs'!C6*'Exposure & Toxicity Inputs'!C7)/('Exposure & Toxicity Inputs'!C4*'Exposure & Toxicity Inputs'!C8)/'Exposure & Toxicity Inputs'!B18 -> 0.0082732 | D9: =(('Group Mean Concentrations'!C7/1000)*('Exposure & Toxicity Inputs'!B5/1000)*'Exposure & Toxicity Inputs'!B6*'Exposure & Toxicity Inputs'!B7)/('Exposure & Toxicity Inputs'!B4*'Exposure & Toxicity Inputs'!B8)/'Exposure & Toxicity Inputs'!B18 -> 0.0045015492 | E9: =(('Group Mean Concentrations'!C7/1000)*('Exposure & Toxicity Inputs'!C5/1000)*'Exposure & Toxicity Inputs'!C6*'Exposure & Toxicity Inputs'!C7)/('Exposure & Toxicity Inputs'!C4*'Exposure & Toxicity Inputs'!C8)/'Exposure & Toxicity Inputs'!B18 -> 0.010503615 | F9: =(('Group Mean Concentrations'!D7/1000)*('Exposure & Toxicity Inputs'!B5/1000)*'Exposure & Toxicity Inputs'!B6*'Exposure & Toxicity Inputs'!B7)/('Exposure & Toxicity Inputs'!B4*'Exposure & Toxicity Inputs'!B8)/'Exposure & Toxicity Inputs'!B18 -> 0.0069818413 | G9: =(('Group Mean Concentrations'!D7/1000)*('Exposure & Toxicity Inputs'!C5/1000)*'Exposure & Toxicity Inputs'!C6*'Exposure & Toxicity Inputs'!C7)/('Exposure & Toxicity Inputs'!C4*'Exposure & Toxicity Inputs'!C8)/'Exposure & Toxicity Inputs'!B18 -> 0.016290963 | H9: =(('Group Mean Concentrations'!E7/1000)*('Exposure & Toxicity Inputs'!B5/1000)*'Exposure & Toxicity Inputs'!B6*'Exposure & Toxicity Inputs'!B7)/('Exposure & Toxicity Inputs'!B4*'Exposure & Toxicity Inputs'!B8)/'Exposure & Toxicity Inputs'!B18 -> 0.0030617206 | I9: =(('Group Mean Concentrations'!E7/1000)*('Exposure & Toxicity Inputs'!C5/1000)*'Exposure & Toxicity Inputs'!C6*'Exposure & Toxicity Inputs'!C7)/('Exposure & Toxicity Inputs'!C4*'Exposure & Toxicity Inputs'!C8)/'Exposure & Toxicity Inputs'!B18 -> 0.0071440148 | J9: =(('Group Mean Concentrations'!F7/1000)*('Exposure & Toxicity Inputs'!B5/1000)*'Exposure & Toxicity Inputs'!B6*'Exposure & Toxicity Inputs'!B7)/('Exposure & Toxicity Inputs'!B4*'Exposure & Toxicity Inputs'!B8)/'Exposure & Toxicity Inputs'!B18 -> 0.0050280063 | K9: =(('Group Mean Concentrations'!F7/1000)*('Exposure & Toxicity Inputs'!C5/1000)*'Exposure & Toxicity Inputs'!C6*'Exposure & Toxicity Inputs'!C7)/('Exposure & Toxicity Inputs'!C4*'Exposure & Toxicity Inputs'!C8)/'Exposure & Toxicity Inputs'!B18 -> 0.011732015 | L9: =(('Group Mean Concentrations'!G7/1000)*('Exposure & Toxicity Inputs'!B5/1000)*'Exposure & Toxicity Inputs'!B6*'Exposure & Toxicity Inputs'!B7)/('Exposure & Toxicity Inputs'!B4*'Exposure & Toxicity Inputs'!B8)/'Exposure & Toxicity Inputs'!B18 -> 0.0069393206 | M9: =(('Group Mean Concentrations'!G7/1000)*('Exposure & Toxicity Inputs'!C5/1000)*'Exposure & Toxicity Inputs'!C6*'Exposure & Toxicity Inputs'!C7)/('Exposure & Toxicity Inputs'!C4*'Exposure & Toxicity Inputs'!C8)/'Exposure & Toxicity Inputs'!B18 -> 0.016191748 | N9: =(('Group Mean Concentrations'!H7/1000)*('Exposure & Toxicity Inputs'!B5/1000)*'Exposure & Toxicity Inputs'!B6*'Exposure & Toxicity Inputs'!B7)/('Exposure & Toxicity Inputs'!B4*'Exposure & Toxicity Inputs'!B8)/'Exposure & Toxicity Inputs'!B18 -> 0.0050096825 | O9: =(('Group Mean Concentrations'!H7/1000)*('Exposure & Toxicity Inputs'!C5/1000)*'Exposure & Toxicity Inputs'!C6*'Exposure & Toxicity Inputs'!C7)/('Exposure & Toxicity Inputs'!C4*'Exposure & Toxicity Inputs'!C8)/'Exposure & Toxicity Inputs'!B18 -> 0.011689259
A10: o,p'-DDE | B10: =(('Group Mean Concentrations'!B8/1000)*('Exposure & Toxicity Inputs'!B5/1000)*'Exposure & Toxicity Inputs'!B6*'Exposure & Toxicity Inputs'!B7)/('Exposure & Toxicity Inputs'!B4*'Exposure & Toxicity Inputs'!B8)/'Exposure & Toxicity Inputs'!B19 -> 0.0040056317 | C10: =(('Group Mean Concentrations'!B8/1000)*('Exposure & Toxicity Inputs'!C5/1000)*'Exposure & Toxicity Inputs'!C6*'Exposure & Toxicity Inputs'!C7)/('Exposure & Toxicity Inputs'!C4*'Exposure & Toxicity Inputs'!C8)/'Exposure & Toxicity Inputs'!B19 -> 0.0093464741 | D10: =(('Group Mean Concentrations'!C8/1000)*('Exposure & Toxicity Inputs'!B5/1000)*'Exposure & Toxicity Inputs'!B6*'Exposure & Toxicity Inputs'!B7)/('Exposure & Toxicity Inputs'!B4*'Exposure & Toxicity Inputs'!B8)/'Exposure & Toxicity Inputs'!B19 -> 0.010533606 | E10: =(('Group Mean Concentrations'!C8/1000)*('Exposure & Toxicity Inputs'!C5/1000)*'Exposure & Toxicity Inputs'!C6*'Exposure & Toxicity Inputs'!C7)/('Exposure & Toxicity Inputs'!C4*'Exposure & Toxicity Inputs'!C8)/'Exposure & Toxicity Inputs'!B19 -> 0.024578415 | F10: =(('Group Mean Concentrations'!D8/1000)*('Exposure & Toxicity Inputs'!B5/1000)*'Exposure & Toxicity Inputs'!B6*'Exposure & Toxicity Inputs'!B7)/('Exposure & Toxicity Inputs'!B4*'Exposure & Toxicity Inputs'!B8)/'Exposure & Toxicity Inputs'!B19 -> 0.01339541 | G10: =(('Group Mean Concentrations'!D8/1000)*('Exposure & Toxicity Inputs'!C5/1000)*'Exposure & Toxicity Inputs'!C6*'Exposure & Toxicity Inputs'!C7)/('Exposure & Toxicity Inputs'!C4*'Exposure & Toxicity Inputs'!C8)/'Exposure & Toxicity Inputs'!B19 -> 0.031255956 | H10: =(('Group Mean Concentrations'!E8/1000)*('Exposure & Toxicity Inputs'!B5/1000)*'Exposure & Toxicity Inputs'!B6*'Exposure & Toxicity Inputs'!B7)/('Exposure & Toxicity Inputs'!B4*'Exposure & Toxicity Inputs'!B8)/'Exposure & Toxicity Inputs'!B19 -> 0.0069942921 | I10: =(('Group Mean Concentrations'!E8/1000)*('Exposure & Toxicity Inputs'!C5/1000)*'Exposure & Toxicity Inputs'!C6*'Exposure & Toxicity Inputs'!C7)/('Exposure & Toxicity Inputs'!C4*'Exposure & Toxicity Inputs'!C8)/'Exposure & Toxicity Inputs'!B19 -> 0.016320015 | J10: =(('Group Mean Concentrations'!F8/1000)*('Exposure & Toxicity Inputs'!B5/1000)*'Exposure & Toxicity Inputs'!B6*'Exposure & Toxicity Inputs'!B7)/('Exposure & Toxicity Inputs'!B4*'Exposure & Toxicity Inputs'!B8)/'Exposure & Toxicity Inputs'!B19 -> 0.0092314413 | K10: =(('Group Mean Concentrations'!F8/1000)*('Exposure & Toxicity Inputs'!C5/1000)*'Exposure & Toxicity Inputs'!C6*'Exposure & Toxicity Inputs'!C7)/('Exposure & Toxicity Inputs'!C4*'Exposure & Toxicity Inputs'!C8)/'Exposure & Toxicity Inputs'!B19 -> 0.02154003 | L10: =(('Group Mean Concentrations'!G8/1000)*('Exposure & Toxicity Inputs'!B5/1000)*'Exposure & Toxicity Inputs'!B6*'Exposure & Toxicity Inputs'!B7)/('Exposure & Toxicity Inputs'!B4*'Exposure & Toxicity Inputs'!B8)/'Exposure & Toxicity Inputs'!B19 -> 0.011708914 | M10: =(('Group Mean Concentrations'!G8/1000)*('Exposure & Toxicity Inputs'!C5/1000)*'Exposure & Toxicity Inputs'!C6*'Exposure & Toxicity Inputs'!C7)/('Exposure & Toxicity Inputs'!C4*'Exposure & Toxicity Inputs'!C8)/'Exposure & Toxicity Inputs'!B19 -> 0.0273208 | N10: =(('Group Mean Concentrations'!H8/1000)*('Exposure & Toxicity Inputs'!B5/1000)*'Exposure & Toxicity Inputs'!B6*'Exposure & Toxicity Inputs'!B7)/('Exposure & Toxicity Inputs'!B4*'Exposure & Toxicity Inputs'!B8)/'Exposure & Toxicity Inputs'!B19 -> 0.0093115492 | O10: =(('Group Mean Concentrations'!H8/1000)*('Exposure & Toxicity Inputs'!C5/1000)*'Exposure & Toxicity Inputs'!C6*'Exposure & Toxicity Inputs'!C7)/('Exposure & Toxicity Inputs'!C4*'Exposure & Toxicity Inputs'!C8)/'Exposure & Toxicity Inputs'!B19 -> 0.021726948
A11: p,p'-DDE | B11: =(('Group Mean Concentrations'!B9/1000)*('Exposure & Toxicity Inputs'!B5/1000)*'Exposure & Toxicity Inputs'!B6*'Exposure & Toxicity Inputs'!B7)/('Exposure & Toxicity Inputs'!B4*'Exposure & Toxicity Inputs'!B8)/'Exposure & Toxicity Inputs'!B20 -> 0.0064826349 | C11: =(('Group Mean Concentrations'!B9/1000)*('Exposure & Toxicity Inputs'!C5/1000)*'Exposure & Toxicity Inputs'!C6*'Exposure & Toxicity Inputs'!C7)/('Exposure & Toxicity Inputs'!C4*'Exposure & Toxicity Inputs'!C8)/'Exposure & Toxicity Inputs'!B20 -> 0.015126148 | D11: =(('Group Mean Concentrations'!C9/1000)*('Exposure & Toxicity Inputs'!B5/1000)*'Exposure & Toxicity Inputs'!B6*'Exposure & Toxicity Inputs'!B7)/('Exposure & Toxicity Inputs'!B4*'Exposure & Toxicity Inputs'!B8)/'Exposure & Toxicity Inputs'!B20 -> 0.0087491492 | E11: =(('Group Mean Concentrations'!C9/1000)*('Exposure & Toxicity Inputs'!C5/1000)*'Exposure & Toxicity Inputs'!C6*'Exposure & Toxicity Inputs'!C7)/('Exposure & Toxicity Inputs'!C4*'Exposure & Toxicity Inputs'!C8)/'Exposure & Toxicity Inputs'!B20 -> 0.020414681 | F11: =(('Group Mean Concentrations'!D9/1000)*('Exposure & Toxicity Inputs'!B5/1000)*'Exposure & Toxicity Inputs'!B6*'Exposure & Toxicity Inputs'!B7)/('Exposure & Toxicity Inputs'!B4*'Exposure & Toxicity Inputs'!B8)/'Exposure & Toxicity Inputs'!B20 -> 0.013308254 | G11: =(('Group Mean Concentrations'!D9/1000)*('Exposure & Toxicity Inputs'!C5/1000)*'Exposure & Toxicity Inputs'!C6*'Exposure & Toxicity Inputs'!C7)/('Exposure & Toxicity Inputs'!C4*'Exposure & Toxicity Inputs'!C8)/'Exposure & Toxicity Inputs'!B20 -> 0.031052593 | H11: =(('Group Mean Concentrations'!E9/1000)*('Exposure & Toxicity Inputs'!B5/1000)*'Exposure & Toxicity Inputs'!B6*'Exposure & Toxicity Inputs'!B7)/('Exposure & Toxicity Inputs'!B4*'Exposure & Toxicity Inputs'!B8)/'Exposure & Toxicity Inputs'!B20 -> 0.0074218476 | I11: =(('Group Mean Concentrations'!E9/1000)*('Exposure & Toxicity Inputs'!C5/1000)*'Exposure & Toxicity Inputs'!C6*'Exposure & Toxicity Inputs'!C7)/('Exposure & Toxicity Inputs'!C4*'Exposure & Toxicity Inputs'!C8)/'Exposure & Toxicity Inputs'!B20 -> 0.017317644 | J11: =(('Group Mean Concentrations'!F9/1000)*('Exposure & Toxicity Inputs'!B5/1000)*'Exposure & Toxicity Inputs'!B6*'Exposure & Toxicity Inputs'!B7)/('Exposure & Toxicity Inputs'!B4*'Exposure & Toxicity Inputs'!B8)/'Exposure & Toxicity Inputs'!B20 -> 0.0075618603 | K11: =(('Group Mean Concentrations'!F9/1000)*('Exposure & Toxicity Inputs'!C5/1000)*'Exposure & Toxicity Inputs'!C6*'Exposure & Toxicity Inputs'!C7)/('Exposure & Toxicity Inputs'!C4*'Exposure & Toxicity Inputs'!C8)/'Exposure & Toxicity Inputs'!B20 -> 0.017644341 | L11: =(('Group Mean Concentrations'!G9/1000)*('Exposure & Toxicity Inputs'!B5/1000)*'Exposure & Toxicity Inputs'!B6*'Exposure & Toxicity Inputs'!B7)/('Exposure & Toxicity Inputs'!B4*'Exposure & Toxicity Inputs'!B8)/'Exposure & Toxicity Inputs'!B20 -> 0.01355633 | M11: =(('Group Mean Concentrations'!G9/1000)*('Exposure & Toxicity Inputs'!C5/1000)*'Exposure & Toxicity Inputs'!C6*'Exposure & Toxicity Inputs'!C7)/('Exposure & Toxicity Inputs'!C4*'Exposure & Toxicity Inputs'!C8)/'Exposure & Toxicity Inputs'!B20 -> 0.031631437 | N11: =(('Group Mean Concentrations'!H9/1000)*('Exposure & Toxicity Inputs'!B5/1000)*'Exposure & Toxicity Inputs'!B6*'Exposure & Toxicity Inputs'!B7)/('Exposure & Toxicity Inputs'!B4*'Exposure & Toxicity Inputs'!B8)/'Exposure & Toxicity Inputs'!B20 -> 0.009513346 | O11: =(('Group Mean Concentrations'!H9/1000)*('Exposure & Toxicity Inputs'!C5/1000)*'Exposure & Toxicity Inputs'!C6*'Exposure & Toxicity Inputs'!C7)/('Exposure & Toxicity Inputs'!C4*'Exposure & Toxicity Inputs'!C8)/'Exposure & Toxicity Inputs'!B20 -> 0.022197807
A12: α-HCH | B12: =(('Group Mean Concentrations'!B10/1000)*('Exposure & Toxicity Inputs'!B5/1000)*'Exposure & Toxicity Inputs'!B6*'Exposure & Toxicity Inputs'!B7)/('Exposure & Toxicity Inputs'!B4*'Exposure & Toxicity Inputs'!B8)/'Exposure & Toxicity Inputs'!B21 -> 0.0075033651 | C12: =(('Group Mean Concentrations'!B10/1000)*('Exposure & Toxicity Inputs'!C5/1000)*'Exposure & Toxicity Inputs'!C6*'Exposure & Toxicity Inputs'!C7)/('Exposure & Toxicity Inputs'!C4*'Exposure & Toxicity Inputs'!C8)/'Exposure & Toxicity Inputs'!B21 -> 0.017507852 | D12: =(('Group Mean Concentrations'!C10/1000)*('Exposure & Toxicity Inputs'!B5/1000)*'Exposure & Toxicity Inputs'!B6*'Exposure & Toxicity Inputs'!B7)/('Exposure & Toxicity Inputs'!B4*'Exposure & Toxicity Inputs'!B8)/'Exposure & Toxicity Inputs'!B21 -> 0.0064869418 | E12: =(('Group Mean Concentrations'!C10/1000)*('Exposure & Toxicity Inputs'!C5/1000)*'Exposure & Toxicity Inputs'!C6*'Exposure & Toxicity Inputs'!C7)/('Exposure & Toxicity Inputs'!C4*'Exposure & Toxicity Inputs'!C8)/'Exposure & Toxicity Inputs'!B21 -> 0.015136198 | F12: =(('Group Mean Concentrations'!D10/1000)*('Exposure & Toxicity Inputs'!B5/1000)*'Exposure & Toxicity Inputs'!B6*'Exposure & Toxicity Inputs'!B7)/('Exposure & Toxicity Inputs'!B4*'Exposure & Toxicity Inputs'!B8)/'Exposure & Toxicity Inputs'!B21 -> 0.013204106 | G12: =(('Group Mean Concentrations'!D10/1000)*('Exposure & Toxicity Inputs'!C5/1000)*'Exposure & Toxicity Inputs'!C6*'Exposure & Toxicity Inputs'!C7)/('Exposure & Toxicity Inputs'!C4*'Exposure & Toxicity Inputs'!C8)/'Exposure & Toxicity Inputs'!B21 -> 0.03080958 | H12: =(('Group Mean Concentrations'!E10/1000)*('Exposure & Toxicity Inputs'!B5/1000)*'Exposure & Toxicity Inputs'!B6*'Exposure & Toxicity Inputs'!B7)/('Exposure & Toxicity Inputs'!B4*'Exposure & Toxicity Inputs'!B8)/'Exposure & Toxicity Inputs'!B21 -> 0.0052269841 | I12: =(('Group Mean Concentrations'!E10/1000)*('Exposure & Toxicity Inputs'!C5/1000)*'Exposure & Toxicity Inputs'!C6*'Exposure & Toxicity Inputs'!C7)/('Exposure & Toxicity Inputs'!C4*'Exposure & Toxicity Inputs'!C8)/'Exposure & Toxicity Inputs'!B21 -> 0.012196296 | J12: =(('Group Mean Concentrations'!F10/1000)*('Exposure & Toxicity Inputs'!B5/1000)*'Exposure & Toxicity Inputs'!B6*'Exposure & Toxicity Inputs'!B7)/('Exposure & Toxicity Inputs'!B4*'Exposure & Toxicity Inputs'!B8)/'Exposure & Toxicity Inputs'!B21 -> 0.0064274286 | K12: =(('Group Mean Concentrations'!F10/1000)*('Exposure & Toxicity Inputs'!C5/1000)*'Exposure & Toxicity Inputs'!C6*'Exposure & Toxicity Inputs'!C7)/('Exposure & Toxicity Inputs'!C4*'Exposure & Toxicity Inputs'!C8)/'Exposure & Toxicity Inputs'!B21 -> 0.014997333 | L12: =(('Group Mean Concentrations'!G10/1000)*('Exposure & Toxicity Inputs'!B5/1000)*'Exposure & Toxicity Inputs'!B6*'Exposure & Toxicity Inputs'!B7)/('Exposure & Toxicity Inputs'!B4*'Exposure & Toxicity Inputs'!B8)/'Exposure & Toxicity Inputs'!B21 -> 0.01554 | M12: =(('Group Mean Concentrations'!G10/1000)*('Exposure & Toxicity Inputs'!C5/1000)*'Exposure & Toxicity Inputs'!C6*'Exposure & Toxicity Inputs'!C7)/('Exposure & Toxicity Inputs'!C4*'Exposure & Toxicity Inputs'!C8)/'Exposure & Toxicity Inputs'!B21 -> 0.03626 | N12: =(('Group Mean Concentrations'!H10/1000)*('Exposure & Toxicity Inputs'!B5/1000)*'Exposure & Toxicity Inputs'!B6*'Exposure & Toxicity Inputs'!B7)/('Exposure & Toxicity Inputs'!B4*'Exposure & Toxicity Inputs'!B8)/'Exposure & Toxicity Inputs'!B21 -> 0.0090648042 | O12: =(('Group Mean Concentrations'!H10/1000)*('Exposure & Toxicity Inputs'!C5/1000)*'Exposure & Toxicity Inputs'!C6*'Exposure & Toxicity Inputs'!C7)/('Exposure & Toxicity Inputs'!C4*'Exposure & Toxicity Inputs'!C8)/'Exposure & Toxicity Inputs'!B21 -> 0.02115121
A13: β-HCH | B13: =(('Group Mean Concentrations'!B11/1000)*('Exposure & Toxicity Inputs'!B5/1000)*'Exposure & Toxicity Inputs'!B6*'Exposure & Toxicity Inputs'!B7)/('Exposure & Toxicity Inputs'!B4*'Exposure & Toxicity Inputs'!B8)/'Exposure & Toxicity Inputs'!B22 -> 0.013557661 | C13: =(('Group Mean Concentrations'!B11/1000)*('Exposure & Toxicity Inputs'!C5/1000)*'Exposure & Toxicity Inputs'!C6*'Exposure & Toxicity Inputs'!C7)/('Exposure & Toxicity Inputs'!C4*'Exposure & Toxicity Inputs'!C8)/'Exposure & Toxicity Inputs'!B22 -> 0.031634543 | D13: =(('Group Mean Concentrations'!C11/1000)*('Exposure & Toxicity Inputs'!B5/1000)*'Exposure & Toxicity Inputs'!B6*'Exposure & Toxicity Inputs'!B7)/('Exposure & Toxicity Inputs'!B4*'Exposure & Toxicity Inputs'!B8)/'Exposure & Toxicity Inputs'!B22 -> 0.018180116 | E13: =(('Group Mean Concentrations'!C11/1000)*('Exposure & Toxicity Inputs'!C5/1000)*'Exposure & Toxicity Inputs'!C6*'Exposure & Toxicity Inputs'!C7)/('Exposure & Toxicity Inputs'!C4*'Exposure & Toxicity Inputs'!C8)/'Exposure & Toxicity Inputs'!B22 -> 0.042420272 | F13: =(('Group Mean Concentrations'!D11/1000)*('Exposure & Toxicity Inputs'!B5/1000)*'Exposure & Toxicity Inputs'!B6*'Exposure & Toxicity Inputs'!B7)/('Exposure & Toxicity Inputs'!B4*'Exposure & Toxicity Inputs'!B8)/'Exposure & Toxicity Inputs'!B22 -> 0.021644021 | G13: =(('Group Mean Concentrations'!D11/1000)*('Exposure & Toxicity Inputs'!C5/1000)*'Exposure & Toxicity Inputs'!C6*'Exposure & Toxicity Inputs'!C7)/('Exposure & Toxicity Inputs'!C4*'Exposure & Toxicity Inputs'!C8)/'Exposure & Toxicity Inputs'!B22 -> 0.050502716 | H13: =(('Group Mean Concentrations'!E11/1000)*('Exposure & Toxicity Inputs'!B5/1000)*'Exposure & Toxicity Inputs'!B6*'Exposure & Toxicity Inputs'!B7)/('Exposure & Toxicity Inputs'!B4*'Exposure & Toxicity Inputs'!B8)/'Exposure & Toxicity Inputs'!B22 -> 0.012750709 | I13: =(('Group Mean Concentrations'!E11/1000)*('Exposure & Toxicity Inputs'!C5/1000)*'Exposure & Toxicity Inputs'!C6*'Exposure & Toxicity Inputs'!C7)/('Exposure & Toxicity Inputs'!C4*'Exposure & Toxicity Inputs'!C8)/'Exposure & Toxicity Inputs'!B22 -> 0.029751654 | J13: =(('Group Mean Concentrations'!F11/1000)*('Exposure & Toxicity Inputs'!B5/1000)*'Exposure & Toxicity Inputs'!B6*'Exposure & Toxicity Inputs'!B7)/('Exposure & Toxicity Inputs'!B4*'Exposure & Toxicity Inputs'!B8)/'Exposure & Toxicity Inputs'!B22 -> 0.019940847 | K13: =(('Group Mean Concentrations'!F11/1000)*('Exposure & Toxicity Inputs'!C5/1000)*'Exposure & Toxicity Inputs'!C6*'Exposure & Toxicity Inputs'!C7)/('Exposure & Toxicity Inputs'!C4*'Exposure & Toxicity Inputs'!C8)/'Exposure & Toxicity Inputs'!B22 -> 0.046528642 | L13: =(('Group Mean Concentrations'!G11/1000)*('Exposure & Toxicity Inputs'!B5/1000)*'Exposure & Toxicity Inputs'!B6*'Exposure & Toxicity Inputs'!B7)/('Exposure & Toxicity Inputs'!B4*'Exposure & Toxicity Inputs'!B8)/'Exposure & Toxicity Inputs'!B22 -> 0.020690243 | M13: =(('Group Mean Concentrations'!G11/1000)*('Exposure & Toxicity Inputs'!C5/1000)*'Exposure & Toxicity Inputs'!C6*'Exposure & Toxicity Inputs'!C7)/('Exposure & Toxicity Inputs'!C4*'Exposure & Toxicity Inputs'!C8)/'Exposure & Toxicity Inputs'!B22 -> 0.048277235 | N13: =(('Group Mean Concentrations'!H11/1000)*('Exposure & Toxicity Inputs'!B5/1000)*'Exposure & Toxicity Inputs'!B6*'Exposure & Toxicity Inputs'!B7)/('Exposure & Toxicity Inputs'!B4*'Exposure & Toxicity Inputs'!B8)/'Exposure & Toxicity Inputs'!B22 -> 0.017793933 | O13: =(('Group Mean Concentrations'!H11/1000)*('Exposure & Toxicity Inputs'!C5/1000)*'Exposure & Toxicity Inputs'!C6*'Exposure & Toxicity Inputs'!C7)/('Exposure & Toxicity Inputs'!C4*'Exposure & Toxicity Inputs'!C8)/'Exposure & Toxicity Inputs'!B22 -> 0.041519177
A14: γ-HCH (Lindane) | B14: =(('Group Mean Concentrations'!B12/1000)*('Exposure & Toxicity Inputs'!B5/1000)*'Exposure & Toxicity Inputs'!B6*'Exposure & Toxicity Inputs'!B7)/('Exposure & Toxicity Inputs'!B4*'Exposure & Toxicity Inputs'!B8)/'Exposure & Toxicity Inputs'!B23 -> 0.0017619048 | C14: =(('Group Mean Concentrations'!B12/1000)*('Exposure & Toxicity Inputs'!C5/1000)*'Exposure & Toxicity Inputs'!C6*'Exposure & Toxicity Inputs'!C7)/('Exposure & Toxicity Inputs'!C4*'Exposure & Toxicity Inputs'!C8)/'Exposure & Toxicity Inputs'!B23 -> 0.0041111111 | D14: =(('Group Mean Concentrations'!C12/1000)*('Exposure & Toxicity Inputs'!B5/1000)*'Exposure & Toxicity Inputs'!B6*'Exposure & Toxicity Inputs'!B7)/('Exposure & Toxicity Inputs'!B4*'Exposure & Toxicity Inputs'!B8)/'Exposure & Toxicity Inputs'!B23 -> 0.0017619048 | E14: =(('Group Mean Concentrations'!C12/1000)*('Exposure & Toxicity Inputs'!C5/1000)*'Exposure & Toxicity Inputs'!C6*'Exposure & Toxicity Inputs'!C7)/('Exposure & Toxicity Inputs'!C4*'Exposure & Toxicity Inputs'!C8)/'Exposure & Toxicity Inputs'!B23 -> 0.0041111111 | F14: =(('Group Mean Concentrations'!D12/1000)*('Exposure & Toxicity Inputs'!B5/1000)*'Exposure & Toxicity Inputs'!B6*'Exposure & Toxicity Inputs'!B7)/('Exposure & Toxicity Inputs'!B4*'Exposure & Toxicity Inputs'!B8)/'Exposure & Toxicity Inputs'!B23 -> 0.0059607196 | G14: =(('Group Mean Concentrations'!D12/1000)*('Exposure & Toxicity Inputs'!C5/1000)*'Exposure & Toxicity Inputs'!C6*'Exposure & Toxicity Inputs'!C7)/('Exposure & Toxicity Inputs'!C4*'Exposure & Toxicity Inputs'!C8)/'Exposure & Toxicity Inputs'!B23 -> 0.013908346 | H14: =(('Group Mean Concentrations'!E12/1000)*('Exposure & Toxicity Inputs'!B5/1000)*'Exposure & Toxicity Inputs'!B6*'Exposure & Toxicity Inputs'!B7)/('Exposure & Toxicity Inputs'!B4*'Exposure & Toxicity Inputs'!B8)/'Exposure & Toxicity Inputs'!B23 -> 0.0017619048 | I14: =(('Group Mean Concentrations'!E12/1000)*('Exposure & Toxicity Inputs'!C5/1000)*'Exposure & Toxicity Inputs'!C6*'Exposure & Toxicity Inputs'!C7)/('Exposure & Toxicity Inputs'!C4*'Exposure & Toxicity Inputs'!C8)/'Exposure & Toxicity Inputs'!B23 -> 0.0041111111 | J14: =(('Group Mean Concentrations'!F12/1000)*('Exposure & Toxicity Inputs'!B5/1000)*'Exposure & Toxicity Inputs'!B6*'Exposure & Toxicity Inputs'!B7)/('Exposure & Toxicity Inputs'!B4*'Exposure & Toxicity Inputs'!B8)/'Exposure & Toxicity Inputs'!B23 -> 0.0033785503 | K14: =(('Group Mean Concentrations'!F12/1000)*('Exposure & Toxicity Inputs'!C5/1000)*'Exposure & Toxicity Inputs'!C6*'Exposure & Toxicity Inputs'!C7)/('Exposure & Toxicity Inputs'!C4*'Exposure & Toxicity Inputs'!C8)/'Exposure & Toxicity Inputs'!B23 -> 0.007883284 | L14: =(('Group Mean Concentrations'!G12/1000)*('Exposure & Toxicity Inputs'!B5/1000)*'Exposure & Toxicity Inputs'!B6*'Exposure & Toxicity Inputs'!B7)/('Exposure & Toxicity Inputs'!B4*'Exposure & Toxicity Inputs'!B8)/'Exposure & Toxicity Inputs'!B23 -> 0.0043440741 | M14: =(('Group Mean Concentrations'!G12/1000)*('Exposure & Toxicity Inputs'!C5/1000)*'Exposure & Toxicity Inputs'!C6*'Exposure & Toxicity Inputs'!C7)/('Exposure & Toxicity Inputs'!C4*'Exposure & Toxicity Inputs'!C8)/'Exposure & Toxicity Inputs'!B23 -> 0.010136173 | N14: =(('Group Mean Concentrations'!H12/1000)*('Exposure & Toxicity Inputs'!B5/1000)*'Exposure & Toxicity Inputs'!B6*'Exposure & Toxicity Inputs'!B7)/('Exposure & Toxicity Inputs'!B4*'Exposure & Toxicity Inputs'!B8)/'Exposure & Toxicity Inputs'!B23 -> 0.0031615097 | O14: =(('Group Mean Concentrations'!H12/1000)*('Exposure & Toxicity Inputs'!C5/1000)*'Exposure & Toxicity Inputs'!C6*'Exposure & Toxicity Inputs'!C7)/('Exposure & Toxicity Inputs'!C4*'Exposure & Toxicity Inputs'!C8)/'Exposure & Toxicity Inputs'!B23 -> 0.007376856
