Workbook

Sheet README
A1: Halda River — Organochlorine pesticides (OCPs) in surface water: full calculation workbook
A3: Purpose: every number in the thesis chapter 'OCP residues in surface water' is reproduced here with live Excel formulas so that it recalculates if any input changes.
A4: Unit assumption: raw concentrations (sheet Raw_Data) are in ng/L. Cell Parameters!B4 converts ng/L → µg/L; change it if the laboratory reported another unit.
A5: Colour code: blue text = hard-coded inputs (measured data, exposure parameters, toxicity values, guideline values); black text = formulas.
A7: Sheets:
A8: Raw_Data — 33 samples × 14 OCPs (from Water.xlsx) with ΣOCP and class sums.
A9: Descriptive_Stats — mean, SD, min, max, detection frequency per compound; class contribution (%).
A10: Zone_Site_Means — mean and SD of each compound and ΣOCP by zone and by site (AVERAGEIFS / SUMPRODUCT formulas).
A11: Diagnostic_Ratios — DDT/(DDD+DDE), (DDD+DDE)/ΣDDT, α- and β-HCH share of ΣHCH per site.
A12: Parameters — exposure factors (adult/child), RfD, CSF, log Kow, MW, Potts–Guy Kp, PNEC and guideline values.
A13: Health_Risk — CDI (ingestion), DAD (dermal), THQ, LADD and CR per compound for every grouping (overall, zones, sites) and receptor.
A14: Health_Summary — HI (ΣTHQ) and ΣCR by grouping and receptor (SUMIFS over Health_Risk).
... A20: Sources: USEPA (1989) RAGS Part A; USEPA (2004) RAGS Part E; USEPA (2011) Exposure Factors Handbook; USEPA IRIS; USEPA National Recommended Water Quality Criteria; EU Directive 2013/39/EU; CCME (1999, updated) CEQGs; WHO (2017) Guidelines for Drinking-water Quality; Hernando et al. (2006) Talanta 69:334–342.

Sheet Raw_Data
A1: Sample ID | B1: Zone | C1: Site | D1: o,p'-DDT | E1: p,p'-DDT | F1: o,p'-DDD | G1: p,p'-DDD | H1: o,p'-DDE | I1: p,p'-DDE | J1: α-HCH | K1: β-HCH | L1: γ-HCH (Lindane) | M1: δ-HCH | N1: Aldrin | O1: Dieldrin | P1: Heptachlor | Q1: Heptachlor epoxide | R1: ΣOCP | S1: ΣDDT | T1: ΣHCH | U1: ΣDRN | V1: ΣHPT
A2: BWR1 | B2: Up-stream | C2: Bhujpur Dam | D2: 2.136 | E2: 2.656 | F2: 1.643 | G2: 1.796 | H2: 5.134 | I2: 8.059 | J2: 2.708 | K2: 5.329 | L2: 0.5 | M2: 0.5 | N2: 0.5 | O2: 1.453 | P2: 0.5 | Q2: 1.639 | R2: =SUM(D2:Q2) -> 34.553 | S2: =SUM(D2:I2) -> 21.424 | T2: =SUM(J2:M2) -> 9.037 | U2: =SUM(N2:O2) -> 1.953 | V2: =SUM(P2:Q2) -> 2.139
A3: BWR2 | B3: Up-stream | C3: Bhujpur Dam | D3: 1.083 | E3: 1.854 | F3: 1.863 | G3: 3.489 | H3: 3.712 | I3: 6.426 | J3: 2.739 | K3: 3.467 | L3: 0.5 | M3: 0.5 | N3: 0.5 | O3: 1.542 | P3: 0.5 | Q3: 2.216 | R3: =SUM(D3:Q3) -> 30.391 | S3: =SUM(D3:I3) -> 18.427 | T3: =SUM(J3:M3) -> 7.206 | U3: =SUM(N3:O3) -> 2.042 | V3: =SUM(P3:Q3) -> 2.716
A4: BWR3 | B4: Up-stream | C4: Bhujpur Dam | D4: 2.271 | E4: 2.887 | F4: 2.213 | G4: 3.813 | H4: 4.623 | I4: 8.543 | J4: 2.809 | K4: 3.566 | L4: 0.5 | M4: 0.5 | N4: 0.5 | O4: 1.295 | P4: 0.5 | Q4: 2.035 | R4: =SUM(D4:Q4) -> 36.055 | S4: =SUM(D4:I4) -> 24.35 | T4: =SUM(J4:M4) -> 7.375 | U4: =SUM(N4:O4) -> 1.795 | V4: =SUM(P4:Q4) -> 2.535
A5: EWR1 | B5: Up-stream | C5: Ekkhuliya | D5: 0.5 | E5: 0.5 | F5: 0.5 | G5: 0.5 | H5: 2.822 | I5: 5.909 | J5: 1.416 | K5: 2.936 | L5: 0.5 | M5: 0.5 | N5: 0.5 | O5: 0.5 | P5: 0.5 | Q5: 0.5 | R5: =SUM(D5:Q5) -> 18.083 | S5: =SUM(D5:I5) -> 10.731 | T5: =SUM(J5:M5) -> 5.352 | U5: =SUM(N5:O5) -> 1 | V5: =SUM(P5:Q5) -> 1
A6: EWR2 | B6: Up-stream | C6: Ekkhuliya | D6: 0.5 | E6: 0.5 | F6: 0.5 | G6: 0.5 | H6: 2.959 | I6: 5.601 | J6: 1.471 | K6: 1.993 | L6: 0.5 | M6: 0.5 | N6: 0.5 | O6: 0.5 | P6: 0.5 | Q6: 0.5 | R6: =SUM(D6:Q6) -> 17.024 | S6: =SUM(D6:I6) -> 10.56 | T6: =SUM(J6:M6) -> 4.464 | U6: =SUM(N6:O6) -> 1 | V6: =SUM(P6:Q6) -> 1
A7: EWR3 | B7: Up-stream | C7: Ekkhuliya | D7: 0.5 | E7: 0.5 | F7: 0.5 | G7: 0.5 | H7: 2.7 | I7: 6.138 | J7: 1.376 | K7: 2.384 | L7: 0.5 | M7: 0.5 | N7: 0.5 | O7: 0.5 | P7: 0.5 | Q7: 0.5 | R7: =SUM(D7:Q7) -> 17.598 | S7: =SUM(D7:I7) -> 10.838 | T7: =SUM(J7:M7) -> 4.76 | U7: =SUM(N7:O7) -> 1 | V7: =SUM(P7:Q7) -> 1
A8: NZWR1 | B8: Up-stream | C8: Nazirhat | D8: 5.253 | E8: 4.991 | F8: 3.133 | G8: 3.967 | H8: 7.431 | I8: 12.636 | J8: 6.47 | K8: 12.711 | L8: 2.528 | M8: 3.696 | N8: 3.574 | O8: 5.374 | P8: 5.387 | Q8: 7.339 | R8: =SUM(D8:Q8) -> 84.49 | S8: =SUM(D8:I8) -> 37.411 | T8: =SUM(J8:M8) -> 25.405 | U8: =SUM(N8:O8) -> 8.948 | V8: =SUM(P8:Q8) -> 12.726
A9: NZWR2 | B9: Up-stream | C9: Nazirhat | D9: 5.836 | E9: 7.991 | F9: 4.067 | G9: 5.272 | H9: 7.345 | I9: 13.504 | J9: 6.162 | K9: 12.133 | L9: 3.287 | M9: 3.825 | N9: 3.631 | O9: 7.463 | P9: 5.382 | Q9: 7.141 | R9: =SUM(D9:Q9) -> 93.039 | S9: =SUM(D9:I9) -> 44.015 | T9: =SUM(J9:M9) -> 25.407 | U9: =SUM(N9:O9) -> 11.094 | V9: =SUM(P9:Q9) -> 12.523
A10: NZWR3 | B10: Up-stream | C10: Nazirhat | D10: 6.098 | E10: 7.439 | F10: 3.073 | G10: 3.459 | H10: 7.426 | I10: 13.556 | J10: 5.665 | K10: 11.169 | L10: 2.546 | M10: 3.832 | N10: 4.316 | O10: 7.748 | P10: 5.298 | Q10: 7.203 | R10: =SUM(D10:Q10) -> 88.828 | S10: =SUM(D10:I10) -> 41.051 | T10: =SUM(J10:M10) -> 23.212 | U10: =SUM(N10:O10) -> 12.064 | V10: =SUM(P10:Q10) -> 12.501
A11: SWR1 | B11: Mid-stream | C11: Sekandar Para | D11: 2.936 | E11: 3.026 | F11: 0.5 | G11: 3.18 | H11: 5.101 | I11: 8.767 | J11: 2.157 | K11: 4.246 | L11: 0.5 | M11: 0.5 | N11: 1.7149201 | O11: 3.647 | P11: 0.5 | Q11: 0.5 | R11: =SUM(D11:Q11) -> 37.27492 | S11: =SUM(D11:I11) -> 23.51 | T11: =SUM(J11:M11) -> 7.403 | U11: =SUM(N11:O11) -> 5.3619201 | V11: =SUM(P11:Q11) -> 1
A12: SWR2 | B12: Mid-stream | C12: Sekandar Para | D12: 2.946 | E12: 4.043 | F12: 0.5 | G12: 6.148 | H12: 5.107 | I12: 11.814 | J12: 2.174 | K12: 4.158 | L12: 0.5 | M12: 0.5 | N12: 1.916 | O12: 2.914 | P12: 0.5 | Q12: 0.5 | R12: =SUM(D12:Q12) -> 43.72 | S12: =SUM(D12:I12) -> 30.558 | T12: =SUM(J12:M12) -> 7.332 | U12: =SUM(N12:O12) -> 4.83 | V12: =SUM(P12:Q12) -> 1
A13: SWR3 | B13: Mid-stream | C13: Sekandar Para | D13: 3.453 | E13: 3.911 | F13: 0.5 | G13: 3.813 | H13: 5.556 | I13: 7.144 | J13: 3.392 | K13: 6.601 | L13: 0.5 | M13: 0.5 | N13: 0.5 | O13: 3.263 | P13: 0.5 | Q13: 0.5 | R13: =SUM(D13:Q13) -> 40.133 | S13: =SUM(D13:I13) -> 24.377 | T13: =SUM(J13:M13) -> 10.993 | U13: =SUM(N13:O13) -> 3.763 | V13: =SUM(P13:Q13) -> 1
... A34: KWR3 | B34: Down-stream | C34: Kalurghat | D34: 11.138 | E34: 10.056 | F34: 9.325 | G34: 10.611 | H34: 9.983 | I34: 23.15 | J34: 7.921 | K34: 14.478 | L34: 5.286 | M34: 13.217 | N34: 6.749 | O34: 9.478 | P34: 5.547 | Q34: 8.234 | R34: =SUM(D34:Q34) -> 145.173 | S34: =SUM(D34:I34) -> 74.263 | T34: =SUM(J34:M34) -> 40.902 | U34: =SUM(N34:O34) -> 16.227 | V34: =SUM(P34:Q34) -> 13.781

Sheet Descriptive_Stats
A1: Descriptive statistics of OCPs in Halda River water (ng/L, n = 33)
A3: Compound | B3: n | C3: Mean | D3: SD | E3: Min | F3: Max | G3: Detections (>0) | H3: Detection frequency (%) | I3: Mean ± SD (text) | J3: Range (text)
A4: o,p'-DDT | B4: =COUNT(Raw_Data!$D$2:$D$34) -> 33 | C4: =AVERAGE(Raw_Data!$D$2:$D$34) -> 4.4101515 | D4: =STDEV(Raw_Data!$D$2:$D$34) -> 2.4156279 | E4: =MIN(Raw_Data!$D$2:$D$34) -> 0.5 | F4: =MAX(Raw_Data!$D$2:$D$34) -> 11.138 | G4: =COUNTIF(Raw_Data!$D$2:$D$34,">0") -> 33 | H4: =G4/B4*100 -> 100 | I4: =IF(G4=0,"nd",TEXT(C4,"0.00")&" ± "&TEXT(D4,"0.00")) -> 4.41 ± 2.42 | J4: =IF(G4=0,"nd",IF(E4=0,"nd","" & TEXT(E4,"0.00"))&"–"&TEXT(F4,"0.00")) -> 0.50–11.14
A5: p,p'-DDT | B5: =COUNT(Raw_Data!$E$2:$E$34) -> 33 | C5: =AVERAGE(Raw_Data!$E$2:$E$34) -> 5.2184 | D5: =STDEV(Raw_Data!$E$2:$E$34) -> 3.4028986 | E5: =MIN(Raw_Data!$E$2:$E$34) -> 0.5 | F5: =MAX(Raw_Data!$E$2:$E$34) -> 15.7972 | G5: =COUNTIF(Raw_Data!$E$2:$E$34,">0") -> 33 | H5: =G5/B5*100 -> 100 | I5: =IF(G5=0,"nd",TEXT(C5,"0.00")&" ± "&TEXT(D5,"0.00")) -> 5.22 ± 3.40 | J5: =IF(G5=0,"nd",IF(E5=0,"nd","" & TEXT(E5,"0.00"))&"–"&TEXT(F5,"0.00")) -> 0.50–15.80
A6: o,p'-DDD | B6: =COUNT(Raw_Data!$F$2:$F$34) -> 33 | C6: =AVERAGE(Raw_Data!$F$2:$F$34) -> 3.7881515 | D6: =STDEV(Raw_Data!$F$2:$F$34) -> 2.4956825 | E6: =MIN(Raw_Data!$F$2:$F$34) -> 0.5 | F6: =MAX(Raw_Data!$F$2:$F$34) -> 9.546 | G6: =COUNTIF(Raw_Data!$F$2:$F$34,">0") -> 33 | H6: =G6/B6*100 -> 100 | I6: =IF(G6=0,"nd",TEXT(C6,"0.00")&" ± "&TEXT(D6,"0.00")) -> 3.79 ± 2.50 | J6: =IF(G6=0,"nd",IF(E6=0,"nd","" & TEXT(E6,"0.00"))&"–"&TEXT(F6,"0.00")) -> 0.50–9.55
A7: p,p'-DDD | B7: =COUNT(Raw_Data!$G$2:$G$34) -> 33 | C7: =AVERAGE(Raw_Data!$G$2:$G$34) -> 4.7992424 | D7: =STDEV(Raw_Data!$G$2:$G$34) -> 2.7944567 | E7: =MIN(Raw_Data!$G$2:$G$34) -> 0.5 | F7: =MAX(Raw_Data!$G$2:$G$34) -> 10.612 | G7: =COUNTIF(Raw_Data!$G$2:$G$34,">0") -> 33 | H7: =G7/B7*100 -> 100 | I7: =IF(G7=0,"nd",TEXT(C7,"0.00")&" ± "&TEXT(D7,"0.00")) -> 4.80 ± 2.79 | J7: =IF(G7=0,"nd",IF(E7=0,"nd","" & TEXT(E7,"0.00"))&"–"&TEXT(F7,"0.00")) -> 0.50–10.61
A8: o,p'-DDE | B8: =COUNT(Raw_Data!$H$2:$H$34) -> 33 | C8: =AVERAGE(Raw_Data!$H$2:$H$34) -> 6.2361212 | D8: =STDEV(Raw_Data!$H$2:$H$34) -> 1.7665886 | E8: =MIN(Raw_Data!$H$2:$H$34) -> 2.7 | F8: =MAX(Raw_Data!$H$2:$H$34) -> 9.983 | G8: =COUNTIF(Raw_Data!$H$2:$H$34,">0") -> 33 | H8: =G8/B8*100 -> 100 | I8: =IF(G8=0,"nd",TEXT(C8,"0.00")&" ± "&TEXT(D8,"0.00")) -> 6.24 ± 1.77 | J8: =IF(G8=0,"nd",IF(E8=0,"nd","" & TEXT(E8,"0.00"))&"–"&TEXT(F8,"0.00")) -> 2.70–9.98
A9: p,p'-DDE | B9: =COUNT(Raw_Data!$I$2:$I$34) -> 33 | C9: =AVERAGE(Raw_Data!$I$2:$I$34) -> 13.251939 | D9: =STDEV(Raw_Data!$I$2:$I$34) -> 4.3157645 | E9: =MIN(Raw_Data!$I$2:$I$34) -> 5.601 | F9: =MAX(Raw_Data!$I$2:$I$34) -> 23.15 | G9: =COUNTIF(Raw_Data!$I$2:$I$34,">0") -> 33 | H9: =G9/B9*100 -> 100 | I9: =IF(G9=0,"nd",TEXT(C9,"0.00")&" ± "&TEXT(D9,"0.00")) -> 13.25 ± 4.32 | J9: =IF(G9=0,"nd",IF(E9=0,"nd","" & TEXT(E9,"0.00"))&"–"&TEXT(F9,"0.00")) -> 5.60–23.15
A10: α-HCH | B10: =COUNT(Raw_Data!$J$2:$J$34) -> 33 | C10: =AVERAGE(Raw_Data!$J$2:$J$34) -> 4.7611364 | D10: =STDEV(Raw_Data!$J$2:$J$34) -> 2.1584912 | E10: =MIN(Raw_Data!$J$2:$J$34) -> 1.376 | F10: =MAX(Raw_Data!$J$2:$J$34) -> 9.437 | G10: =COUNTIF(Raw_Data!$J$2:$J$34,">0") -> 33 | H10: =G10/B10*100 -> 100 | I10: =IF(G10=0,"nd",TEXT(C10,"0.00")&" ± "&TEXT(D10,"0.00")) -> 4.76 ± 2.16 | J10: =IF(G10=0,"nd",IF(E10=0,"nd","" & TEXT(E10,"0.00"))&"–"&TEXT(F10,"0.00")) -> 1.38–9.44
A11: β-HCH | B11: =COUNT(Raw_Data!$K$2:$K$34) -> 33 | C11: =AVERAGE(Raw_Data!$K$2:$K$34) -> 8.6328182 | D11: =STDEV(Raw_Data!$K$2:$K$34) -> 3.7915793 | E11: =MIN(Raw_Data!$K$2:$K$34) -> 1.993 | F11: =MAX(Raw_Data!$K$2:$K$34) -> 14.618 | G11: =COUNTIF(Raw_Data!$K$2:$K$34,">0") -> 33 | H11: =G11/B11*100 -> 100 | I11: =IF(G11=0,"nd",TEXT(C11,"0.00")&" ± "&TEXT(D11,"0.00")) -> 8.63 ± 3.79 | J11: =IF(G11=0,"nd",IF(E11=0,"nd","" & TEXT(E11,"0.00"))&"–"&TEXT(F11,"0.00")) -> 1.99–14.62
A12: γ-HCH (Lindane) | B12: =COUNT(Raw_Data!$L$2:$L$34) -> 33 | C12: =AVERAGE(Raw_Data!$L$2:$L$34) -> 2.0428485 | D12: =STDEV(Raw_Data!$L$2:$L$34) -> 1.5272575 | E12: =MIN(Raw_Data!$L$2:$L$34) -> 0.5 | F12: =MAX(Raw_Data!$L$2:$L$34) -> 5.476 | G12: =COUNTIF(Raw_Data!$L$2:$L$34,">0") -> 33 | H12: =G12/B12*100 -> 100 | I12: =IF(G12=0,"nd",TEXT(C12,"0.00")&" ± "&TEXT(D12,"0.00")) -> 2.04 ± 1.53 | J12: =IF(G12=0,"nd",IF(E12=0,"nd","" & TEXT(E12,"0.00"))&"–"&TEXT(F12,"0.00")) -> 0.50–5.48
A13: δ-HCH | B13: =COUNT(Raw_Data!$M$2:$M$34) -> 33 | C13: =AVERAGE(Raw_Data!$M$2:$M$34) -> 4.0948091 | D13: =STDEV(Raw_Data!$M$2:$M$34) -> 3.6984503 | E13: =MIN(Raw_Data!$M$2:$M$34) -> 0.5 | F13: =MAX(Raw_Data!$M$2:$M$34) -> 14.612 | G13: =COUNTIF(Raw_Data!$M$2:$M$34,">0") -> 33 | H13: =G13/B13*100 -> 100 | I13: =IF(G13=0,"nd",TEXT(C13,"0.00")&" ± "&TEXT(D13,"0.00")) -> 4.09 ± 3.70 | J13: =IF(G13=0,"nd",IF(E13=0,"nd","" & TEXT(E13,"0.00"))&"–"&TEXT(F13,"0.00")) -> 0.50–14.61
A14: Aldrin | B14: =COUNT(Raw_Data!$N$2:$N$34) -> 33 | C14: =AVERAGE(Raw_Data!$N$2:$N$34) -> 2.2773006 | D14: =STDEV(Raw_Data!$N$2:$N$34) -> 1.8628537 | E14: =MIN(Raw_Data!$N$2:$N$34) -> 0.5 | F14: =MAX(Raw_Data!$N$2:$N$34) -> 6.749 | G14: =COUNTIF(Raw_Data!$N$2:$N$34,">0") -> 33 | H14: =G14/B14*100 -> 100 | I14: =IF(G14=0,"nd",TEXT(C14,"0.00")&" ± "&TEXT(D14,"0.00")) -> 2.28 ± 1.86 | J14: =IF(G14=0,"nd",IF(E14=0,"nd","" & TEXT(E14,"0.00"))&"–"&TEXT(F14,"0.00")) -> 0.50–6.75
A15: Dieldrin | B15: =COUNT(Raw_Data!$O$2:$O$34) -> 33 | C15: =AVERAGE(Raw_Data!$O$2:$O$34) -> 3.9256061 | D15: =STDEV(Raw_Data!$O$2:$O$34) -> 2.423572 | E15: =MIN(Raw_Data!$O$2:$O$34) -> 0.5 | F15: =MAX(Raw_Data!$O$2:$O$34) -> 9.478 | G15: =COUNTIF(Raw_Data!$O$2:$O$34,">0") -> 33 | H15: =G15/B15*100 -> 100 | I15: =IF(G15=0,"nd",TEXT(C15,"0.00")&" ± "&TEXT(D15,"0.00")) -> 3.93 ± 2.42 | J15: =IF(G15=0,"nd",IF(E15=0,"nd","" & TEXT(E15,"0.00"))&"–"&TEXT(F15,"0.00")) -> 0.50–9.48
A16: Heptachlor | B16: =COUNT(Raw_Data!$P$2:$P$34) -> 33 | C16: =AVERAGE(Raw_Data!$P$2:$P$34) -> 2.5017576 | D16: =STDEV(Raw_Data!$P$2:$P$34) -> 2.0489792 | E16: =MIN(Raw_Data!$P$2:$P$34) -> 0.5 | F16: =MAX(Raw_Data!$P$2:$P$34) -> 6.846 | G16: =COUNTIF(Raw_Data!$P$2:$P$34,">0") -> 33 | H16: =G16/B16*100 -> 100 | I16: =IF(G16=0,"nd",TEXT(C16,"0.00")&" ± "&TEXT(D16,"0.00")) -> 2.50 ± 2.05 | J16: =IF(G16=0,"nd",IF(E16=0,"nd","" & TEXT(E16,"0.00"))&"–"&TEXT(F16,"0.00")) -> 0.50–6.85
A17: Heptachlor epoxide | B17: =COUNT(Raw_Data!$Q$2:$Q$34) -> 33 | C17: =AVERAGE(Raw_Data!$Q$2:$Q$34) -> 4.0036667 | D17: =STDEV(Raw_Data!$Q$2:$Q$34) -> 2.5960437 | E17: =MIN(Raw_Data!$Q$2:$Q$34) -> 0.5 | F17: =MAX(Raw_Data!$Q$2:$Q$34) -> 10.176 | G17: =COUNTIF(Raw_Data!$Q$2:$Q$34,">0") -> 33 | H17: =G17/B17*100 -> 100 | I17: =IF(G17=0,"nd",TEXT(C17,"0.00")&" ± "&TEXT(D17,"0.00")) -> 4.00 ± 2.60 | J17: =IF(G17=0,"nd",IF(E17=0,"nd","" & TEXT(E17,"0.00"))&"–"&TEXT(F17,"0.00")) -> 0.50–10.18
A18: ΣOCP | B18: =COUNT(Raw_Data!$R$2:$R$34) -> 33 | C18: =AVERAGE(Raw_Data!$R$2:$R$34) -> 69.943949 | D18: =STDEV(Raw_Data!$R$2:$R$34) -> 34.218848 | E18: =MIN(Raw_Data!$R$2:$R$34) -> 17.024 | F18: =MAX(Raw_Data!$R$2:$R$34) -> 145.173 | G18: =COUNTIF(Raw_Data!$R$2:$R$34,">0") -> 33 | H18: =G18/B18*100 -> 100 | I18: =IF(G18=0,"nd",TEXT(C18,"0.00")&" ± "&TEXT(D18,"0.00")) -> 69.94 ± 34.22 | J18: =IF(G18=0,"nd",IF(E18=0,"nd","" & TEXT(E18,"0.00"))&"–"&TEXT(F18,"0.00")) -> 17.02–145.17
A20: Class contribution to ΣOCP (%)
A21: Class | B21: Sum of concentrations (all samples) | C21: Share of ΣOCP (%)
A22: ΣDDT | B22: =SUM(Raw_Data!$S$2:$S$34) -> 1244.2322 | C22: =B22/SUM(Raw_Data!$R$2:$R$34)*100 -> 53.90603
A23: ΣHCH | B23: =SUM(Raw_Data!$T$2:$T$34) -> 644.5432 | C23: =B23/SUM(Raw_Data!$R$2:$R$34)*100 -> 27.924663
A24: ΣDRN | B24: =SUM(Raw_Data!$U$2:$U$34) -> 204.69592 | C24: =B24/SUM(Raw_Data!$R$2:$R$34)*100 -> 8.8683964
A25: ΣHPT | B25: =SUM(Raw_Data!$V$2:$V$34) -> 214.679 | C25: =B25/SUM(Raw_Data!$R$2:$R$34)*100 -> 9.3009107

Sheet Zone_Site_Means
A1: Mean and SD of each OCP and ΣOCP by zone and by site (ng/L)
A3: Group | B3: Type | C3: n | D3: Mean o,p'-DDT | E3: Mean p,p'-DDT | F3: Mean o,p'-DDD | G3: Mean p,p'-DDD | H3: Mean o,p'-DDE | I3: Mean p,p'-DDE | J3: Mean α-HCH | K3: Mean β-HCH | L3: Mean γ-HCH (Lindane) | M3: Mean δ-HCH | N3: Mean Aldrin | O3: Mean Dieldrin | P3: Mean Heptachlor | Q3: Mean Heptachlor epoxide | R3: Mean ΣOCP | S3: SD o,p'-DDT | T3: SD p,p'-DDT | U3: SD o,p'-DDD | V3: SD p,p'-DDD | W3: SD o,p'-DDE | X3: SD p,p'-DDE | Y3: SD α-HCH | Z3: SD β-HCH | AA3: SD γ-HCH (Lindane) | AB3: SD δ-HCH | AC3: SD Aldrin | AD3: SD Dieldrin | AE3: SD Heptachlor | AF3: SD Heptachlor epoxide | AG3: SD ΣOCP | AH3: Max o,p'-DDT | AI3: Max p,p'-DDT | AJ3: Max o,p'-DDD | AK3: Max p,p'-DDD | AL3: Max o,p'-DDE | AM3: Max p,p'-DDE | AN3: Max α-HCH | AO3: Max β-HCH | AP3: Max γ-HCH (Lindane) | AQ3: Max δ-HCH | AR3: Max Aldrin | AS3: Max Dieldrin | AT3: Max Heptachlor | AU3: Max Heptachlor epoxide | AV3: Max ΣOCP
A4: Overall | B4: All | C4: =COUNT(Raw_Data!$R$2:$R$34) -> 33 | D4: =AVERAGE(Raw_Data!$D$2:$D$34) -> 4.4101515 | E4: =AVERAGE(Raw_Data!$E$2:$E$34) -> 5.2184 | F4: =AVERAGE(Raw_Data!$F$2:$F$34) -> 3.7881515 | G4: =AVERAGE(Raw_Data!$G$2:$G$34) -> 4.7992424 | H4: =AVERAGE(Raw_Data!$H$2:$H$34) -> 6.2361212 | I4: =AVERAGE(Raw_Data!$I$2:$I$34) -> 13.251939 | J4: =AVERAGE(Raw_Data!$J$2:$J$34) -> 4.7611364 | K4: =AVERAGE(Raw_Data!$K$2:$K$34) -> 8.6328182 | L4: =AVERAGE(Raw_Data!$L$2:$L$34) -> 2.0428485 | M4: =AVERAGE(Raw_Data!$M$2:$M$34) -> 4.0948091 | N4: =AVERAGE(Raw_Data!$N$2:$N$34) -> 2.2773006 | O4: =AVERAGE(Raw_Data!$O$2:$O$34) -> 3.9256061 | P4: =AVERAGE(Raw_Data!$P$2:$P$34) -> 2.5017576 | Q4: =AVERAGE(Raw_Data!$Q$2:$Q$34) -> 4.0036667 | R4: =AVERAGE(Raw_Data!$R$2:$R$34) -> 69.943949 | S4: =STDEV(Raw_Data!$D$2:$D$34) -> 2.4156279 | T4: =STDEV(Raw_Data!$E$2:$E$34) -> 3.4028986 | U4: =STDEV(Raw_Data!$F$2:$F$34) -> 2.4956825 | V4: =STDEV(Raw_Data!$G$2:$G$34) -> 2.7944567 | W4: =STDEV(Raw_Data!$H$2:$H$34) -> 1.7665886 | X4: =STDEV(Raw_Data!$I$2:$I$34) -> 4.3157645 | Y4: =STDEV(Raw_Data!$J$2:$J$34) -> 2.1584912 | Z4: =STDEV(Raw_Data!$K$2:$K$34) -> 3.7915793 | AA4: =STDEV(Raw_Data!$L$2:$L$34) -> 1.5272575 | AB4: =STDEV(Raw_Data!$M$2:$M$34) -> 3.6984503 | AC4: =STDEV(Raw_Data!$N$2:$N$34) -> 1.8628537 | AD4: =STDEV(Raw_Data!$O$2:$O$34) -> 2.423572 | AE4: =STDEV(Raw_Data!$P$2:$P$34) -> 2.0489792 | AF4: =STDEV(Raw_Data!$Q$2:$Q$34) -> 2.5960437 | AG4: =STDEV(Raw_Data!$R$2:$R$34) -> 34.218848 | AH4: =MAX(Raw_Data!$D$2:$D$34) -> 11.138 | AI4: =MAX(Raw_Data!$E$2:$E$34) -> 15.7972 | AJ4: =MAX(Raw_Data!$F$2:$F$34) -> 9.546 | AK4: =MAX(Raw_Data!$G$2:$G$34) -> 10.612 | AL4: =MAX(Raw_Data!$H$2:$H$34) -> 9.983 | AM4: =MAX(Raw_Data!$I$2:$I$34) -> 23.15 | AN4: =MAX(Raw_Data!$J$2:$J$34) -> 9.437 | AO4: =MAX(Raw_Data!$K$2:$K$34) -> 14.618 | AP4: =MAX(Raw_Data!$L$2:$L$34) -> 5.476 | AQ4: =MAX(Raw_Data!$M$2:$M$34) -> 14.612 | AR4: =MAX(Raw_Data!$N$2:$N$34) -> 6.749 | AS4: =MAX(Raw_Data!$O$2:$O$34) -> 9.478 | AT4: =MAX(Raw_Data!$P$2:$P$34) -> 6.846 | AU4: =MAX(Raw_Data!$Q$2:$Q$34) -> 10.176 | AV4: =MAX(Raw_Data!$R$2:$R$34) -> 145.173
A5: Up-stream | B5: Zone | C5: =COUNTIF(Raw_Data!$B$2:$B$34,$A5) -> 9 | D5: =AVERAGEIF(Raw_Data!$B$2:$B$34,$A5,Raw_Data!$D$2:$D$34) -> 2.6863333 | E5: =AVERAGEIF(Raw_Data!$B$2:$B$34,$A5,Raw_Data!$E$2:$E$34) -> 3.2575556 | F5: =AVERAGEIF(Raw_Data!$B$2:$B$34,$A5,Raw_Data!$F$2:$F$34) -> 1.9435556 | G5: =AVERAGEIF(Raw_Data!$B$2:$B$34,$A5,Raw_Data!$G$2:$G$34) -> 2.5884444 | H5: =AVERAGEIF(Raw_Data!$B$2:$B$34,$A5,Raw_Data!$H$2:$H$34) -> 4.9057778 | I5: =AVERAGEIF(Raw_Data!$B$2:$B$34,$A5,Raw_Data!$I$2:$I$34) -> 8.9302222 | J5: =AVERAGEIF(Raw_Data!$B$2:$B$34,$A5,Raw_Data!$J$2:$J$34) -> 3.424 | K5: =AVERAGEIF(Raw_Data!$B$2:$B$34,$A5,Raw_Data!$K$2:$K$34) -> 6.1875556 | L5: =AVERAGEIF(Raw_Data!$B$2:$B$34,$A5,Raw_Data!$L$2:$L$34) -> 1.2623333 | M5: =AVERAGEIF(Raw_Data!$B$2:$B$34,$A5,Raw_Data!$M$2:$M$34) -> 1.5947778 | N5: =AVERAGEIF(Raw_Data!$B$2:$B$34,$A5,Raw_Data!$N$2:$N$34) -> 1.6134444 | O5: =AVERAGEIF(Raw_Data!$B$2:$B$34,$A5,Raw_Data!$O$2:$O$34) -> 2.9305556 | P5: =AVERAGEIF(Raw_Data!$B$2:$B$34,$A5,Raw_Data!$P$2:$P$34) -> 2.1185556 | Q5: =AVERAGEIF(Raw_Data!$B$2:$B$34,$A5,Raw_Data!$Q$2:$Q$34) -> 3.2303333 | R5: =AVERAGEIF(Raw_Data!$B$2:$B$34,$A5,Raw_Data!$R$2:$R$34) -> 46.673444 | S5: =SQRT(SUMPRODUCT((Raw_Data!$B$2:$B$34=$A5)*(Raw_Data!$D$2:$D$34-D5)^2)/($C5-1)) -> 2.3857351 | T5: =SQRT(SUMPRODUCT((Raw_Data!$B$2:$B$34=$A5)*(Raw_Data!$E$2:$E$34-E5)^2)/($C5-1)) -> 2.9192527 | U5: =SQRT(SUMPRODUCT((Raw_Data!$B$2:$B$34=$A5)*(Raw_Data!$F$2:$F$34-F5)^2)/($C5-1)) -> 1.304819 | V5: =SQRT(SUMPRODUCT((Raw_Data!$B$2:$B$34=$A5)*(Raw_Data!$G$2:$G$34-G5)^2)/($C5-1)) -> 1.7987168 | W5: =SQRT(SUMPRODUCT((Raw_Data!$B$2:$B$34=$A5)*(Raw_Data!$H$2:$H$34-H5)^2)/($C5-1)) -> 2.0381596 | X5: =SQRT(SUMPRODUCT((Raw_Data!$B$2:$B$34=$A5)*(Raw_Data!$I$2:$I$34-I5)^2)/($C5-1)) -> 3.3770949 | Y5: =SQRT(SUMPRODUCT((Raw_Data!$B$2:$B$34=$A5)*(Raw_Data!$J$2:$J$34-J5)^2)/($C5-1)) -> 2.0975439 | Z5: =SQRT(SUMPRODUCT((Raw_Data!$B$2:$B$34=$A5)*(Raw_Data!$K$2:$K$34-K5)^2)/($C5-1)) -> 4.4772126 | AA5: =SQRT(SUMPRODUCT((Raw_Data!$B$2:$B$34=$A5)*(Raw_Data!$L$2:$L$34-L5)^2)/($C5-1)) -> 1.1638245 | AB5: =SQRT(SUMPRODUCT((Raw_Data!$B$2:$B$34=$A5)*(Raw_Data!$M$2:$M$34-M5)^2)/($C5-1)) -> 1.642613 | AC5: =SQRT(SUMPRODUCT((Raw_Data!$B$2:$B$34=$A5)*(Raw_Data!$N$2:$N$34-N5)^2)/($C5-1)) -> 1.6828795 | AD5: =SQRT(SUMPRODUCT((Raw_Data!$B$2:$B$34=$A5)*(Raw_Data!$O$2:$O$34-O5)^2)/($C5-1)) -> 3.0461111 | AE5: =SQRT(SUMPRODUCT((Raw_Data!$B$2:$B$34=$A5)*(Raw_Data!$P$2:$P$34-P5)^2)/($C5-1)) -> 2.4279621 | AF5: =SQRT(SUMPRODUCT((Raw_Data!$B$2:$B$34=$A5)*(Raw_Data!$Q$2:$Q$34-Q5)^2)/($C5-1)) -> 3.0681984 | AG5: =SQRT(SUMPRODUCT((Raw_Data!$B$2:$B$34=$A5)*(Raw_Data!$R$2:$R$34-R5)^2)/($C5-1)) -> 32.449041 | AH5: =SUMPRODUCT(MAX((Raw_Data!$B$2:$B$34=$A5)*Raw_Data!$D$2:$D$34)) -> 6.098 | AI5: =SUMPRODUCT(MAX((Raw_Data!$B$2:$B$34=$A5)*Raw_Data!$E$2:$E$34)) -> 7.991 | AJ5: =SUMPRODUCT(MAX((Raw_Data!$B$2:$B$34=$A5)*Raw_Data!$F$2:$F$34)) -> 4.067 | AK5: =SUMPRODUCT(MAX((Raw_Data!$B$2:$B$34=$A5)*Raw_Data!$G$2:$G$34)) -> 5.272 | AL5: =SUMPRODUCT(MAX((Raw_Data!$B$2:$B$34=$A5)*Raw_Data!$H$2:$H$34)) -> 7.431 | AM5: =SUMPRODUCT(MAX((Raw_Data!$B$2:$B$34=$A5)*Raw_Data!$I$2:$I$34)) -> 13.556 | AN5: =SUMPRODUCT(MAX((Raw_Data!$B$2:$B$34=$A5)*Raw_Data!$J$2:$J$34)) -> 6.47 | AO5: =SUMPRODUCT(MAX((Raw_Data!$B$2:$B$34=$A5)*Raw_Data!$K$2:$K$34)) -> 12.711 | AP5: =SUMPRODUCT(MAX((Raw_Data!$B$2:$B$34=$A5)*Raw_Data!$L$2:$L$34)) -> 3.287 | AQ5: =SUMPRODUCT(MAX((Raw_Data!$B$2:$B$34=$A5)*Raw_Data!$M$2:$M$34)) -> 3.832 | AR5: =SUMPRODUCT(MAX((Raw_Data!$B$2:$B$34=$A5)*Raw_Data!$N$2:$N$34)) -> 4.316 | AS5: =SUMPRODUCT(MAX((Raw_Data!$B$2:$B$34=$A5)*Raw_Data!$O$2:$O$34)) -> 7.748 | AT5: =SUMPRODUCT(MAX((Raw_Data!$B$2:$B$34=$A5)*Raw_Data!$P$2:$P$34)) -> 5.387 | AU5: =SUMPRODUCT(MAX((Raw_Data!$B$2:$B$34=$A5)*Raw_Data!$Q$2:$Q$34)) -> 7.339 | AV5: =SUMPRODUCT(MAX((Raw_Data!$B$2:$B$34=$A5)*Raw_Data!$R$2:$R$34)) -> 93.039
A6: Mid-stream | B6: Zone | C6: =COUNTIF(Raw_Data!$B$2:$B$34,$A6) -> 9 | D6: =AVERAGEIF(Raw_Data!$B$2:$B$34,$A6,Raw_Data!$D$2:$D$34) -> 3.3127778 | E6: =AVERAGEIF(Raw_Data!$B$2:$B$34,$A6,Raw_Data!$E$2:$E$34) -> 3.6304444 | F6: =AVERAGEIF(Raw_Data!$B$2:$B$34,$A6,Raw_Data!$F$2:$F$34) -> 2.05 | G6: =AVERAGEIF(Raw_Data!$B$2:$B$34,$A6,Raw_Data!$G$2:$G$34) -> 3.7487778 | H6: =AVERAGEIF(Raw_Data!$B$2:$B$34,$A6,Raw_Data!$H$2:$H$34) -> 5.7722222 | I6: =AVERAGEIF(Raw_Data!$B$2:$B$34,$A6,Raw_Data!$I$2:$I$34) -> 12.331778 | J6: =AVERAGEIF(Raw_Data!$B$2:$B$34,$A6,Raw_Data!$J$2:$J$34) -> 3.4182222 | K6: =AVERAGEIF(Raw_Data!$B$2:$B$34,$A6,Raw_Data!$K$2:$K$34) -> 6.392 | L6: =AVERAGEIF(Raw_Data!$B$2:$B$34,$A6,Raw_Data!$L$2:$L$34) -> 0.87033333 | M6: =AVERAGEIF(Raw_Data!$B$2:$B$34,$A6,Raw_Data!$M$2:$M$34) -> 2.0175222 | N6: =AVERAGEIF(Raw_Data!$B$2:$B$34,$A6,Raw_Data!$N$2:$N$34) -> 1.1774356 | O6: =AVERAGEIF(Raw_Data!$B$2:$B$34,$A6,Raw_Data!$O$2:$O$34) -> 2.8312222 | P6: =AVERAGEIF(Raw_Data!$B$2:$B$34,$A6,Raw_Data!$P$2:$P$34) -> 1.2031111 | Q6: =AVERAGEIF(Raw_Data!$B$2:$B$34,$A6,Raw_Data!$Q$2:$Q$34) -> 2.3713333 | R6: =AVERAGEIF(Raw_Data!$B$2:$B$34,$A6,Raw_Data!$R$2:$R$34) -> 51.12718 | S6: =SQRT(SUMPRODUCT((Raw_Data!$B$2:$B$34=$A6)*(Raw_Data!$D$2:$D$34-D6)^2)/($C6-1)) -> 0.58939774 | T6: =SQRT(SUMPRODUCT((Raw_Data!$B$2:$B$34=$A6)*(Raw_Data!$E$2:$E$34-E6)^2)/($C6-1)) -> 0.7184092 | U6: =SQRT(SUMPRODUCT((Raw_Data!$B$2:$B$34=$A6)*(Raw_Data!$F$2:$F$34-F6)^2)/($C6-1)) -> 1.286073 | V6: =SQRT(SUMPRODUCT((Raw_Data!$B$2:$B$34=$A6)*(Raw_Data!$G$2:$G$34-G6)^2)/($C6-1)) -> 1.0552047 | W6: =SQRT(SUMPRODUCT((Raw_Data!$B$2:$B$34=$A6)*(Raw_Data!$H$2:$H$34-H6)^2)/($C6-1)) -> 0.93336472 | X6: =SQRT(SUMPRODUCT((Raw_Data!$B$2:$B$34=$A6)*(Raw_Data!$I$2:$I$34-I6)^2)/($C6-1)) -> 2.7005909 | Y6: =SQRT(SUMPRODUCT((Raw_Data!$B$2:$B$34=$A6)*(Raw_Data!$J$2:$J$34-J6)^2)/($C6-1)) -> 1.0810243 | Z6: =SQRT(SUMPRODUCT((Raw_Data!$B$2:$B$34=$A6)*(Raw_Data!$K$2:$K$34-K6)^2)/($C6-1)) -> 1.5949177 | AA6: =SQRT(SUMPRODUCT((Raw_Data!$B$2:$B$34=$A6)*(Raw_Data!$L$2:$L$34-L6)^2)/($C6-1)) -> 0.57456766 | AB6: =SQRT(SUMPRODUCT((Raw_Data!$B$2:$B$34=$A6)*(Raw_Data!$M$2:$M$34-M6)^2)/($C6-1)) -> 1.1582429 | AC6: =SQRT(SUMPRODUCT((Raw_Data!$B$2:$B$34=$A6)*(Raw_Data!$N$2:$N$34-N6)^2)/($C6-1)) -> 0.6654031 | AD6: =SQRT(SUMPRODUCT((Raw_Data!$B$2:$B$34=$A6)*(Raw_Data!$O$2:$O$34-O6)^2)/($C6-1)) -> 0.76687446 | AE6: =SQRT(SUMPRODUCT((Raw_Data!$B$2:$B$34=$A6)*(Raw_Data!$P$2:$P$34-P6)^2)/($C6-1)) -> 0.66208127 | AF6: =SQRT(SUMPRODUCT((Raw_Data!$B$2:$B$34=$A6)*(Raw_Data!$Q$2:$Q$34-Q6)^2)/($C6-1)) -> 1.4356599 | AG6: =SQRT(SUMPRODUCT((Raw_Data!$B$2:$B$34=$A6)*(Raw_Data!$R$2:$R$34-R6)^2)/($C6-1)) -> 9.7203091 | AH6: =SUMPRODUCT(MAX((Raw_Data!$B$2:$B$34=$A6)*Raw_Data!$D$2:$D$34)) -> 4.352 | AI6: =SUMPRODUCT(MAX((Raw_Data!$B$2:$B$34=$A6)*Raw_Data!$E$2:$E$34)) -> 4.354 | AJ6: =SUMPRODUCT(MAX((Raw_Data!$B$2:$B$34=$A6)*Raw_Data!$F$2:$F$34)) -> 3.733 | AK6: =SUMPRODUCT(MAX((Raw_Data!$B$2:$B$34=$A6)*Raw_Data!$G$2:$G$34)) -> 6.148 | AL6: =SUMPRODUCT(MAX((Raw_Data!$B$2:$B$34=$A6)*Raw_Data!$H$2:$H$34)) -> 7.447 | AM6: =SUMPRODUCT(MAX((Raw_Data!$B$2:$B$34=$A6)*Raw_Data!$I$2:$I$34)) -> 14.781 | AN6: =SUMPRODUCT(MAX((Raw_Data!$B$2:$B$34=$A6)*Raw_Data!$J$2:$J$34)) -> 5.52 | AO6: =SUMPRODUCT(MAX((Raw_Data!$B$2:$B$34=$A6)*Raw_Data!$K$2:$K$34)) -> 8.312 | AP6: =SUMPRODUCT(MAX((Raw_Data!$B$2:$B$34=$A6)*Raw_Data!$L$2:$L$34)) -> 1.936 | AQ6: =SUMPRODUCT(MAX((Raw_Data!$B$2:$B$34=$A6)*Raw_Data!$M$2:$M$34)) -> 3.307 | AR6: =SUMPRODUCT(MAX((Raw_Data!$B$2:$B$34=$A6)*Raw_Data!$N$2:$N$34)) -> 1.967 | AS6: =SUMPRODUCT(MAX((Raw_Data!$B$2:$B$34=$A6)*Raw_Data!$O$2:$O$34)) -> 3.647 | AT6: =SUMPRODUCT(MAX((Raw_Data!$B$2:$B$34=$A6)*Raw_Data!$P$2:$P$34)) -> 2.273 | AU6: =SUMPRODUCT(MAX((Raw_Data!$B$2:$B$34=$A6)*Raw_Data!$Q$2:$Q$34)) -> 3.884 | AV6: =SUMPRODUCT(MAX((Raw_Data!$B$2:$B$34=$A6)*Raw_Data!$R$2:$R$34)) -> 64.309
A7: Down-stream | B7: Zone | C7: =COUNTIF(Raw_Data!$B$2:$B$34,$A7) -> 15 | D7: =AVERAGEIF(Raw_Data!$B$2:$B$34,$A7,Raw_Data!$D$2:$D$34) -> 6.1028667 | E7: =AVERAGEIF(Raw_Data!$B$2:$B$34,$A7,Raw_Data!$E$2:$E$34) -> 7.34768 | F7: =AVERAGEIF(Raw_Data!$B$2:$B$34,$A7,Raw_Data!$F$2:$F$34) -> 5.9378 | G7: =AVERAGEIF(Raw_Data!$B$2:$B$34,$A7,Raw_Data!$G$2:$G$34) -> 6.756 | H7: =AVERAGEIF(Raw_Data!$B$2:$B$34,$A7,Raw_Data!$H$2:$H$34) -> 7.3126667 | I7: =AVERAGEIF(Raw_Data!$B$2:$B$34,$A7,Raw_Data!$I$2:$I$34) -> 16.397067 | J7: =AVERAGEIF(Raw_Data!$B$2:$B$34,$A7,Raw_Data!$J$2:$J$34) -> 6.3691667 | K7: =AVERAGEIF(Raw_Data!$B$2:$B$34,$A7,Raw_Data!$K$2:$K$34) -> 11.444467 | L7: =AVERAGEIF(Raw_Data!$B$2:$B$34,$A7,Raw_Data!$L$2:$L$34) -> 3.2146667 | M7: =AVERAGEIF(Raw_Data!$B$2:$B$34,$A7,Raw_Data!$M$2:$M$34) -> 6.8412 | N7: =AVERAGEIF(Raw_Data!$B$2:$B$34,$A7,Raw_Data!$N$2:$N$34) -> 3.3355333 | O7: =AVERAGEIF(Raw_Data!$B$2:$B$34,$A7,Raw_Data!$O$2:$O$34) -> 5.1792667 | P7: =AVERAGEIF(Raw_Data!$B$2:$B$34,$A7,Raw_Data!$P$2:$P$34) -> 3.5108667 | Q7: =AVERAGEIF(Raw_Data!$B$2:$B$34,$A7,Raw_Data!$Q$2:$Q$34) -> 5.4470667 | R7: =AVERAGEIF(Raw_Data!$B$2:$B$34,$A7,Raw_Data!$R$2:$R$34) -> 95.196313 | S7: =SQRT(SUMPRODUCT((Raw_Data!$B$2:$B$34=$A7)*(Raw_Data!$D$2:$D$34-D7)^2)/($C7-1)) -> 2.0328379 | T7: =SQRT(SUMPRODUCT((Raw_Data!$B$2:$B$34=$A7)*(Raw_Data!$E$2:$E$34-E7)^2)/($C7-1)) -> 3.5146601 | U7: =SQRT(SUMPRODUCT((Raw_Data!$B$2:$B$34=$A7)*(Raw_Data!$F$2:$F$34-F7)^2)/($C7-1)) -> 1.7993915 | V7: =SQRT(SUMPRODUCT((Raw_Data!$B$2:$B$34=$A7)*(Raw_Data!$G$2:$G$34-G7)^2)/($C7-1)) -> 2.7221772 | W7: =SQRT(SUMPRODUCT((Raw_Data!$B$2:$B$34=$A7)*(Raw_Data!$H$2:$H$34-H7)^2)/($C7-1)) -> 1.3205848 | X7: =SQRT(SUMPRODUCT((Raw_Data!$B$2:$B$34=$A7)*(Raw_Data!$I$2:$I$34-I7)^2)/($C7-1)) -> 2.9562262 | Y7: =SQRT(SUMPRODUCT((Raw_Data!$B$2:$B$34=$A7)*(Raw_Data!$J$2:$J$34-J7)^2)/($C7-1)) -> 1.5454004 | Z7: =SQRT(SUMPRODUCT((Raw_Data!$B$2:$B$34=$A7)*(Raw_Data!$K$2:$K$34-K7)^2)/($C7-1)) -> 2.0999168 | AA7: =SQRT(SUMPRODUCT((Raw_Data!$B$2:$B$34=$A7)*(Raw_Data!$L$2:$L$34-L7)^2)/($C7-1)) -> 1.2736406 | AB7: =SQRT(SUMPRODUCT((Raw_Data!$B$2:$B$34=$A7)*(Raw_Data!$M$2:$M$34-M7)^2)/($C7-1)) -> 3.7527897 | AC7: =SQRT(SUMPRODUCT((Raw_Data!$B$2:$B$34=$A7)*(Raw_Data!$N$2:$N$34-N7)^2)/($C7-1)) -> 1.9493018 | AD7: =SQRT(SUMPRODUCT((Raw_Data!$B$2:$B$34=$A7)*(Raw_Data!$O$2:$O$34-O7)^2)/($C7-1)) -> 2.1672586 | AE7: =SQRT(SUMPRODUCT((Raw_Data!$B$2:$B$34=$A7)*(Raw_Data!$P$2:$P$34-P7)^2)/($C7-1)) -> 1.925484 | AF7: =SQRT(SUMPRODUCT((Raw_Data!$B$2:$B$34=$A7)*(Raw_Data!$Q$2:$Q$34-Q7)^2)/($C7-1)) -> 2.1254988 | AG7: =SQRT(SUMPRODUCT((Raw_Data!$B$2:$B$34=$A7)*(Raw_Data!$R$2:$R$34-R7)^2)/($C7-1)) -> 27.600253 | AH7: =SUMPRODUCT(MAX((Raw_Data!$B$2:$B$34=$A7)*Raw_Data!$D$2:$D$34)) -> 11.138 | AI7: =SUMPRODUCT(MAX((Raw_Data!$B$2:$B$34=$A7)*Raw_Data!$E$2:$E$34)) -> 15.7972 | AJ7: =SUMPRODUCT(MAX((Raw_Data!$B$2:$B$34=$A7)*Raw_Data!$F$2:$F$34)) -> 9.546 | AK7: =SUMPRODUCT(MAX((Raw_Data!$B$2:$B$34=$A7)*Raw_Data!$G$2:$G$34)) -> 10.612 | AL7: =SUMPRODUCT(MAX((Raw_Data!$B$2:$B$34=$A7)*Raw_Data!$H$2:$H$34)) -> 9.983 | AM7: =SUMPRODUCT(MAX((Raw_Data!$B$2:$B$34=$A7)*Raw_Data!$I$2:$I$34)) -> 23.15 | AN7: =SUMPRODUCT(MAX((Raw_Data!$B$2:$B$34=$A7)*Raw_Data!$J$2:$J$34)) -> 9.437 | AO7: =SUMPRODUCT(MAX((Raw_Data!$B$2:$B$34=$A7)*Raw_Data!$K$2:$K$34)) -> 14.618 | AP7: =SUMPRODUCT(MAX((Raw_Data!$B$2:$B$34=$A7)*Raw_Data!$L$2:$L$34)) -> 5.476 | AQ7: =SUMPRODUCT(MAX((Raw_Data!$B$2:$B$34=$A7)*Raw_Data!$M$2:$M$34)) -> 14.612 | AR7: =SUMPRODUCT(MAX((Raw_Data!$B$2:$B$34=$A7)*Raw_Data!$N$2:$N$34)) -> 6.749 | AS7: =SUMPRODUCT(MAX((Raw_Data!$B$2:$B$34=$A7)*Raw_Data!$O$2:$O$34)) -> 9.478 | AT7: =SUMPRODUCT(MAX((Raw_Data!$B$2:$B$34=$A7)*Raw_Data!$P$2:$P$34)) -> 6.846 | AU7: =SUMPRODUCT(MAX((Raw_Data!$B$2:$B$34=$A7)*Raw_Data!$Q$2:$Q$34)) -> 10.176 | AV7: =SUMPRODUCT(MAX((Raw_Data!$B$2:$B$34=$A7)*Raw_Data!$R$2:$R$34)) -> 145.173
A8: Bhujpur Dam | B8: Site | C8: =COUNTIF(Raw_Data!$C$2:$C$34,$A8) -> 3 | D8: =AVERAGEIF(Raw_Data!$C$2:$C$34,$A8,Raw_Data!$D$2:$D$34) -> 1.83 | E8: =AVERAGEIF(Raw_Data!$C$2:$C$34,$A8,Raw_Data!$E$2:$E$34) -> 2.4656667 | F8: =AVERAGEIF(Raw_Data!$C$2:$C$34,$A8,Raw_Data!$F$2:$F$34) -> 1.9063333 | G8: =AVERAGEIF(Raw_Data!$C$2:$C$34,$A8,Raw_Data!$G$2:$G$34) -> 3.0326667 | H8: =AVERAGEIF(Raw_Data!$C$2:$C$34,$A8,Raw_Data!$H$2:$H$34) -> 4.4896667 | I8: =AVERAGEIF(Raw_Data!$C$2:$C$34,$A8,Raw_Data!$I$2:$I$34) -> 7.676 | J8: =AVERAGEIF(Raw_Data!$C$2:$C$34,$A8,Raw_Data!$J$2:$J$34) -> 2.752 | K8: =AVERAGEIF(Raw_Data!$C$2:$C$34,$A8,Raw_Data!$K$2:$K$34) -> 4.1206667 | L8: =AVERAGEIF(Raw_Data!$C$2:$C$34,$A8,Raw_Data!$L$2:$L$34) -> 0.5 | M8: =AVERAGEIF(Raw_Data!$C$2:$C$34,$A8,Raw_Data!$M$2:$M$34) -> 0.5 | N8: =AVERAGEIF(Raw_Data!$C$2:$C$34,$A8,Raw_Data!$N$2:$N$34) -> 0.5 | O8: =AVERAGEIF(Raw_Data!$C$2:$C$34,$A8,Raw_Data!$O$2:$O$34) -> 1.43 | P8: =AVERAGEIF(Raw_Data!$C$2:$C$34,$A8,Raw_Data!$P$2:$P$34) -> 0.5 | Q8: =AVERAGEIF(Raw_Data!$C$2:$C$34,$A8,Raw_Data!$Q$2:$Q$34) -> 1.9633333 | R8: =AVERAGEIF(Raw_Data!$C$2:$C$34,$A8,Raw_Data!$R$2:$R$34) -> 33.666333 | S8: =SQRT(SUMPRODUCT((Raw_Data!$C$2:$C$34=$A8)*(Raw_Data!$D$2:$D$34-D8)^2)/($C8-1)) -> 0.65043293 | T8: =SQRT(SUMPRODUCT((Raw_Data!$C$2:$C$34=$A8)*(Raw_Data!$E$2:$E$34-E8)^2)/($C8-1)) -> 0.54216449 | U8: =SQRT(SUMPRODUCT((Raw_Data!$C$2:$C$34=$A8)*(Raw_Data!$F$2:$F$34-F8)^2)/($C8-1)) -> 0.28746014 | V8: =SQRT(SUMPRODUCT((Raw_Data!$C$2:$C$34=$A8)*(Raw_Data!$G$2:$G$34-G8)^2)/($C8-1)) -> 1.0831677 | W8: =SQRT(SUMPRODUCT((Raw_Data!$C$2:$C$34=$A8)*(Raw_Data!$H$2:$H$34-H8)^2)/($C8-1)) -> 0.72031544 | X8: =SQRT(SUMPRODUCT((Raw_Data!$C$2:$C$34=$A8)*(Raw_Data!$I$2:$I$34-I8)^2)/($C8-1)) -> 1.1092515 | Y8: =SQRT(SUMPRODUCT((Raw_Data!$C$2:$C$34=$A8)*(Raw_Data!$J$2:$J$34-J8)^2)/($C8-1)) -> 0.051739733 | Z8: =SQRT(SUMPRODUCT((Raw_Data!$C$2:$C$34=$A8)*(Raw_Data!$K$2:$K$34-K8)^2)/($C8-1)) -> 1.0476175 | AA8: =SQRT(SUMPRODUCT((Raw_Data!$C$2:$C$34=$A8)*(Raw_Data!$L$2:$L$34-L8)^2)/($C8-1)) -> 0 | AB8: =SQRT(SUMPRODUCT((Raw_Data!$C$2:$C$34=$A8)*(Raw_Data!$M$2:$M$34-M8)^2)/($C8-1)) -> 0 | AC8: =SQRT(SUMPRODUCT((Raw_Data!$C$2:$C$34=$A8)*(Raw_Data!$N$2:$N$34-N8)^2)/($C8-1)) -> 0 | AD8: =SQRT(SUMPRODUCT((Raw_Data!$C$2:$C$34=$A8)*(Raw_Data!$O$2:$O$34-O8)^2)/($C8-1)) -> 0.12509596 | AE8: =SQRT(SUMPRODUCT((Raw_Data!$C$2:$C$34=$A8)*(Raw_Data!$P$2:$P$34-P8)^2)/($C8-1)) -> 0 | AF8: =SQRT(SUMPRODUCT((Raw_Data!$C$2:$C$34=$A8)*(Raw_Data!$Q$2:$Q$34-Q8)^2)/($C8-1)) -> 0.29510055 | AG8: =SQRT(SUMPRODUCT((Raw_Data!$C$2:$C$34=$A8)*(Raw_Data!$R$2:$R$34-R8)^2)/($C8-1)) -> 2.9342558 | AH8: =SUMPRODUCT(MAX((Raw_Data!$C$2:$C$34=$A8)*Raw_Data!$D$2:$D$34)) -> 2.271 | AI8: =SUMPRODUCT(MAX((Raw_Data!$C$2:$C$34=$A8)*Raw_Data!$E$2:$E$34)) -> 2.887 | AJ8: =SUMPRODUCT(MAX((Raw_Data!$C$2:$C$34=$A8)*Raw_Data!$F$2:$F$34)) -> 2.213 | AK8: =SUMPRODUCT(MAX((Raw_Data!$C$2:$C$34=$A8)*Raw_Data!$G$2:$G$34)) -> 3.813 | AL8: =SUMPRODUCT(MAX((Raw_Data!$C$2:$C$34=$A8)*Raw_Data!$H$2:$H$34)) -> 5.134 | AM8: =SUMPRODUCT(MAX((Raw_Data!$C$2:$C$34=$A8)*Raw_Data!$I$2:$I$34)) -> 8.543 | AN8: =SUMPRODUCT(MAX((Raw_Data!$C$2:$C$34=$A8)*Raw_Data!$J$2:$J$34)) -> 2.809 | AO8: =SUMPRODUCT(MAX((Raw_Data!$C$2:$C$34=$A8)*Raw_Data!$K$2:$K$34)) -> 5.329 | AP8: =SUMPRODUCT(MAX((Raw_Data!$C$2:$C$34=$A8)*Raw_Data!$L$2:$L$34)) -> 0.5 | AQ8: =SUMPRODUCT(MAX((Raw_Data!$C$2:$C$34=$A8)*Raw_Data!$M$2:$M$34)) -> 0.5 | AR8: =SUMPRODUCT(MAX((Raw_Data!$C$2:$C$34=$A8)*Raw_Data!$N$2:$N$34)) -> 0.5 | AS8: =SUMPRODUCT(MAX((Raw_Data!$C$2:$C$34=$A8)*Raw_Data!$O$2:$O$34)) -> 1.542 | AT8: =SUMPRODUCT(MAX((Raw_Data!$C$2:$C$34=$A8)*Raw_Data!$P$2:$P$34)) -> 0.5 | AU8: =SUMPRODUCT(MAX((Raw_Data!$C$2:$C$34=$A8)*Raw_Data!$Q$2:$Q$34)) -> 2.216 | AV8: =SUMPRODUCT(MAX((Raw_Data!$C$2:$C$34=$A8)*Raw_Data!$R$2:$R$34)) -> 36.055
A9: Ekkhuliya | B9: Site | C9: =COUNTIF(Raw_Data!$C$2:$C$34,$A9) -> 3 | D9: =AVERAGEIF(Raw_Data!$C$2:$C$34,$A9,Raw_Data!$D$2:$D$34) -> 0.5 | E9: =AVERAGEIF(Raw_Data!$C$2:$C$34,$A9,Raw_Data!$E$2:$E$34) -> 0.5 | F9: =AVERAGEIF(Raw_Data!$C$2:$C$34,$A9,Raw_Data!$F$2:$F$34) -> 0.5 | G9: =AVERAGEIF(Raw_Data!$C$2:$C$34,$A9,Raw_Data!$G$2:$G$34) -> 0.5 | H9: =AVERAGEIF(Raw_Data!$C$2:$C$34,$A9,Raw_Data!$H$2:$H$34) -> 2.827 | I9: =AVERAGEIF(Raw_Data!$C$2:$C$34,$A9,Raw_Data!$I$2:$I$34) -> 5.8826667 | J9: =AVERAGEIF(Raw_Data!$C$2:$C$34,$A9,Raw_Data!$J$2:$J$34) -> 1.421 | K9: =AVERAGEIF(Raw_Data!$C$2:$C$34,$A9,Raw_Data!$K$2:$K$34) -> 2.4376667 | L9: =AVERAGEIF(Raw_Data!$C$2:$C$34,$A9,Raw_Data!$L$2:$L$34) -> 0.5 | M9: =AVERAGEIF(Raw_Data!$C$2:$C$34,$A9,Raw_Data!$M$2:$M$34) -> 0.5 | N9: =AVERAGEIF(Raw_Data!$C$2:$C$34,$A9,Raw_Data!$N$2:$N$34) -> 0.5 | O9: =AVERAGEIF(Raw_Data!$C$2:$C$34,$A9,Raw_Data!$O$2:$O$34) -> 0.5 | P9: =AVERAGEIF(Raw_Data!$C$2:$C$34,$A9,Raw_Data!$P$2:$P$34) -> 0.5 | Q9: =AVERAGEIF(Raw_Data!$C$2:$C$34,$A9,Raw_Data!$Q$2:$Q$34) -> 0.5 | R9: =AVERAGEIF(Raw_Data!$C$2:$C$34,$A9,Raw_Data!$R$2:$R$34) -> 17.568333 | S9: =SQRT(SUMPRODUCT((Raw_Data!$C$2:$C$34=$A9)*(Raw_Data!$D$2:$D$34-D9)^2)/($C9-1)) -> 0 | T9: =SQRT(SUMPRODUCT((Raw_Data!$C$2:$C$34=$A9)*(Raw_Data!$E$2:$E$34-E9)^2)/($C9-1)) -> 0 | U9: =SQRT(SUMPRODUCT((Raw_Data!$C$2:$C$34=$A9)*(Raw_Data!$F$2:$F$34-F9)^2)/($C9-1)) -> 0 | V9: =SQRT(SUMPRODUCT((Raw_Data!$C$2:$C$34=$A9)*(Raw_Data!$G$2:$G$34-G9)^2)/($C9-1)) -> 0 | W9: =SQRT(SUMPRODUCT((Raw_Data!$C$2:$C$34=$A9)*(Raw_Data!$H$2:$H$34-H9)^2)/($C9-1)) -> 0.12957237 | X9: =SQRT(SUMPRODUCT((Raw_Data!$C$2:$C$34=$A9)*(Raw_Data!$I$2:$I$34-I9)^2)/($C9-1)) -> 0.26946676 | Y9: =SQRT(SUMPRODUCT((Raw_Data!$C$2:$C$34=$A9)*(Raw_Data!$J$2:$J$34-J9)^2)/($C9-1)) -> 0.04769696 | Z9: =SQRT(SUMPRODUCT((Raw_Data!$C$2:$C$34=$A9)*(Raw_Data!$K$2:$K$34-K9)^2)/($C9-1)) -> 0.47378511 | AA9: =SQRT(SUMPRODUCT((Raw_Data!$C$2:$C$34=$A9)*(Raw_Data!$L$2:$L$34-L9)^2)/($C9-1)) -> 0 | AB9: =SQRT(SUMPRODUCT((Raw_Data!$C$2:$C$34=$A9)*(Raw_Data!$M$2:$M$34-M9)^2)/($C9-1)) -> 0 | AC9: =SQRT(SUMPRODUCT((Raw_Data!$C$2:$C$34=$A9)*(Raw_Data!$N$2:$N$34-N9)^2)/($C9-1)) -> 0 | AD9: =SQRT(SUMPRODUCT((Raw_Data!$C$2:$C$34=$A9)*(Raw_Data!$O$2:$O$34-O9)^2)/($C9-1)) -> 0 | AE9: =SQRT(SUMPRODUCT((Raw_Data!$C$2:$C$34=$A9)*(Raw_Data!$P$2:$P$34-P9)^2)/($C9-1)) -> 0 | AF9: =SQRT(SUMPRODUCT((Raw_Data!$C$2:$C$34=$A9)*(Raw_Data!$Q$2:$Q$34-Q9)^2)/($C9-1)) -> 0 | AG9: =SQRT(SUMPRODUCT((Raw_Data!$C$2:$C$34=$A9)*(Raw_Data!$R$2:$R$34-R9)^2)/($C9-1)) -> 0.53012294 | AH9: =SUMPRODUCT(MAX((Raw_Data!$C$2:$C$34=$A9)*Raw_Data!$D$2:$D$34)) -> 0.5 | AI9: =SUMPRODUCT(MAX((Raw_Data!$C$2:$C$34=$A9)*Raw_Data!$E$2:$E$34)) -> 0.5 | AJ9: =SUMPRODUCT(MAX((Raw_Data!$C$2:$C$34=$A9)*Raw_Data!$F$2:$F$34)) -> 0.5 | AK9: =SUMPRODUCT(MAX((Raw_Data!$C$2:$C$34=$A9)*Raw_Data!$G$2:$G$34)) -> 0.5 | AL9: =SUMPRODUCT(MAX((Raw_Data!$C$2:$C$34=$A9)*Raw_Data!$H$2:$H$34)) -> 2.959 | AM9: =SUMPRODUCT(MAX((Raw_Data!$C$2:$C$34=$A9)*Raw_Data!$I$2:$I$34)) -> 6.138 | AN9: =SUMPRODUCT(MAX((Raw_Data!$C$2:$C$34=$A9)*Raw_Data!$J$2:$J$34)) -> 1.471 | AO9: =SUMPRODUCT(MAX((Raw_Data!$C$2:$C$34=$A9)*Raw_Data!$K$2:$K$34)) -> 2.936 | AP9: =SUMPRODUCT(MAX((Raw_Data!$C$2:$C$34=$A9)*Raw_Data!$L$2:$L$34)) -> 0.5 | AQ9: =SUMPRODUCT(MAX((Raw_Data!$C$2:$C$34=$A9)*Raw_Data!$M$2:$M$34)) -> 0.5 | AR9: =SUMPRODUCT(MAX((Raw_Data!$C$2:$C$34=$A9)*Raw_Data!$N$2:$N$34)) -> 0.5 | AS9: =SUMPRODUCT(MAX((Raw_Data!$C$2:$C$34=$A9)*Raw_Data!$O$2:$O$34)) -> 0.5 | AT9: =SUMPRODUCT(MAX((Raw_Data!$C$2:$C$34=$A9)*Raw_Data!$P$2:$P$34)) -> 0.5 | AU9: =SUMPRODUCT(MAX((Raw_Data!$C$2:$C$34=$A9)*Raw_Data!$Q$2:$Q$34)) -> 0.5 | AV9: =SUMPRODUCT(MAX((Raw_Data!$C$2:$C$34=$A9)*Raw_Data!$R$2:$R$34)) -> 18.083
A10: Nazirhat | B10: Site | C10: =COUNTIF(Raw_Data!$C$2:$C$34,$A10) -> 3 | D10: =AVERAGEIF(Raw_Data!$C$2:$C$34,$A10,Raw_Data!$D$2:$D$34) -> 5.729 | E10: =AVERAGEIF(Raw_Data!$C$2:$C$34,$A10,Raw_Data!$E$2:$E$34) -> 6.807 | F10: =AVERAGEIF(Raw_Data!$C$2:$C$34,$A10,Raw_Data!$F$2:$F$34) -> 3.4243333 | G10: =AVERAGEIF(Raw_Data!$C$2:$C$34,$A10,Raw_Data!$G$2:$G$34) -> 4.2326667 | H10: =AVERAGEIF(Raw_Data!$C$2:$C$34,$A10,Raw_Data!$H$2:$H$34) -> 7.4006667 | I10: =AVERAGEIF(Raw_Data!$C$2:$C$34,$A10,Raw_Data!$I$2:$I$34) -> 13.232 | J10: =AVERAGEIF(Raw_Data!$C$2:$C$34,$A10,Raw_Data!$J$2:$J$34) -> 6.099 | K10: =AVERAGEIF(Raw_Data!$C$2:$C$34,$A10,Raw_Data!$K$2:$K$34) -> 12.004333 | L10: =AVERAGEIF(Raw_Data!$C$2:$C$34,$A10,Raw_Data!$L$2:$L$34) -> 2.787 | M10: =AVERAGEIF(Raw_Data!$C$2:$C$34,$A10,Raw_Data!$M$2:$M$34) -> 3.7843333 | N10: =AVERAGEIF(Raw_Data!$C$2:$C$34,$A10,Raw_Data!$N$2:$N$34) -> 3.8403333 | O10: =AVERAGEIF(Raw_Data!$C$2:$C$34,$A10,Raw_Data!$O$2:$O$34) -> 6.8616667 | P10: =AVERAGEIF(Raw_Data!$C$2:$C$34,$A10,Raw_Data!$P$2:$P$34) -> 5.3556667 | Q10: =AVERAGEIF(Raw_Data!$C$2:$C$34,$A10,Raw_Data!$Q$2:$Q$34) -> 7.2276667 | R10: =AVERAGEIF(Raw_Data!$C$2:$C$34,$A10,Raw_Data!$R$2:$R$34) -> 88.785667 | S10: =SQRT(SUMPRODUCT((Raw_Data!$C$2:$C$34=$A10)*(Raw_Data!$D$2:$D$34-D10)^2)/($C10-1)) -> 0.43254248 | T10: =SQRT(SUMPRODUCT((Raw_Data!$C$2:$C$34=$A10)*(Raw_Data!$E$2:$E$34-E10)^2)/($C10-1)) -> 1.5967367 | U10: =SQRT(SUMPRODUCT((Raw_Data!$C$2:$C$34=$A10)*(Raw_Data!$F$2:$F$34-F10)^2)/($C10-1)) -> 0.5573736 | V10: =SQRT(SUMPRODUCT((Raw_Data!$C$2:$C$34=$A10)*(Raw_Data!$G$2:$G$34-G10)^2)/($C10-1)) -> 0.93524132 | W10: =SQRT(SUMPRODUCT((Raw_Data!$C$2:$C$34=$A10)*(Raw_Data!$H$2:$H$34-H10)^2)/($C10-1)) -> 0.048273526 | X10: =SQRT(SUMPRODUCT((Raw_Data!$C$2:$C$34=$A10)*(Raw_Data!$I$2:$I$34-I10)^2)/($C10-1)) -> 0.51680557 | Y10: =SQRT(SUMPRODUCT((Raw_Data!$C$2:$C$34=$A10)*(Raw_Data!$J$2:$J$34-J10)^2)/($C10-1)) -> 0.40618099 | Z10: =SQRT(SUMPRODUCT((Raw_Data!$C$2:$C$34=$A10)*(Raw_Data!$K$2:$K$34-K10)^2)/($C10-1)) -> 0.77901048 | AA10: =SQRT(SUMPRODUCT((Raw_Data!$C$2:$C$34=$A10)*(Raw_Data!$L$2:$L$34-L10)^2)/($C10-1)) -> 0.43310622 | AB10: =SQRT(SUMPRODUCT((Raw_Data!$C$2:$C$34=$A10)*(Raw_Data!$M$2:$M$34-M10)^2)/($C10-1)) -> 0.076578935 | AC10: =SQRT(SUMPRODUCT((Raw_Data!$C$2:$C$34=$A10)*(Raw_Data!$N$2:$N$34-N10)^2)/($C10-1)) -> 0.41292413 | AD10: =SQRT(SUMPRODUCT((Raw_Data!$C$2:$C$34=$A10)*(Raw_Data!$O$2:$O$34-O10)^2)/($C10-1)) -> 1.2962138 | AE10: =SQRT(SUMPRODUCT((Raw_Data!$C$2:$C$34=$A10)*(Raw_Data!$P$2:$P$34-P10)^2)/($C10-1)) -> 0.050003333 | AF10: =SQRT(SUMPRODUCT((Raw_Data!$C$2:$C$34=$A10)*(Raw_Data!$Q$2:$Q$34-Q10)^2)/($C10-1)) -> 0.10127849 | AG10: =SQRT(SUMPRODUCT((Raw_Data!$C$2:$C$34=$A10)*(Raw_Data!$R$2:$R$34-R10)^2)/($C10-1)) -> 4.2746572 | AH10: =SUMPRODUCT(MAX((Raw_Data!$C$2:$C$34=$A10)*Raw_Data!$D$2:$D$34)) -> 6.098 | AI10: =SUMPRODUCT(MAX((Raw_Data!$C$2:$C$34=$A10)*Raw_Data!$E$2:$E$34)) -> 7.991 | AJ10: =SUMPRODUCT(MAX((Raw_Data!$C$2:$C$34=$A10)*Raw_Data!$F$2:$F$34)) -> 4.067 | AK10: =SUMPRODUCT(MAX((Raw_Data!$C$2:$C$34=$A10)*Raw_Data!$G$2:$G$34)) -> 5.272 | AL10: =SUMPRODUCT(MAX((Raw_Data!$C$2:$C$34=$A10)*Raw_Data!$H$2:$H$34)) -> 7.431 | AM10: =SUMPRODUCT(MAX((Raw_Data!$C$2:$C$34=$A10)*Raw_Data!$I$2:$I$34)) -> 13.556 | AN10: =SUMPRODUCT(MAX((Raw_Data!$C$2:$C$34=$A10)*Raw_Data!$J$2:$J$34)) -> 6.47 | AO10: =SUMPRODUCT(MAX((Raw_Data!$C$2:$C$34=$A10)*Raw_Data!$K$2:$K$34)) -> 12.711 | AP10: =SUMPRODUCT(MAX((Raw_Data!$C$2:$C$34=$A10)*Raw_Data!$L$2:$L$34)) -> 3.287 | AQ10: =SUMPRODUCT(MAX((Raw_Data!$C$2:$C$34=$A10)*Raw_Data!$M$2:$M$34)) -> 3.832 | AR10: =SUMPRODUCT(MAX((Raw_Data!$C$2:$C$34=$A10)*Raw_Data!$N$2:$N$34)) -> 4.316 | AS10: =SUMPRODUCT(MAX((Raw_Data!$C$2:$C$34=$A10)*Raw_Data!$O$2:$O$34)) -> 7.748 | AT10: =SUMPRODUCT(MAX((Raw_Data!$C$2:$C$34=$A10)*Raw_Data!$P$2:$P$34)) -> 5.387 | AU10: =SUMPRODUCT(MAX((Raw_Data!$C$2:$C$34=$A10)*Raw_Data!$Q$2:$Q$34)) -> 7.339 | AV10: =SUMPRODUCT(MAX((Raw_Data!$C$2:$C$34=$A10)*Raw_Data!$R$2:$R$34)) -> 93.039
A11: Sekandar Para | B11: Site | C11: =COUNTIF(Raw_Data!$C$2:$C$34,$A11) -> 3 | D11: =AVERAGEIF(Raw_Data!$C$2:$C$34,$A11,Raw_Data!$D$2:$D$34) -> 3.1116667 | E11: =AVERAGEIF(Raw_Data!$C$2:$C$34,$A11,Raw_Data!$E$2:$E$34) -> 3.66 | F11: =AVERAGEIF(Raw_Data!$C$2:$C$34,$A11,Raw_Data!$F$2:$F$34) -> 0.5 | G11: =AVERAGEIF(Raw_Data!$C$2:$C$34,$A11,Raw_Data!$G$2:$G$34) -> 4.3803333 | H11: =AVERAGEIF(Raw_Data!$C$2:$C$34,$A11,Raw_Data!$H$2:$H$34) -> 5.2546667 | I11: =AVERAGEIF(Raw_Data!$C$2:$C$34,$A11,Raw_Data!$I$2:$I$34) -> 9.2416667 | J11: =AVERAGEIF(Raw_Data!$C$2:$C$34,$A11,Raw_Data!$J$2:$J$34) -> 2.5743333 | K11: =AVERAGEIF(Raw_Data!$C$2:$C$34,$A11,Raw_Data!$K$2:$K$34) -> 5.0016667 | L11: =AVERAGEIF(Raw_Data!$C$2:$C$34,$A11,Raw_Data!$L$2:$L$34) -> 0.5 | M11: =AVERAGEIF(Raw_Data!$C$2:$C$34,$A11,Raw_Data!$M$2:$M$34) -> 0.5 | N11: =AVERAGEIF(Raw_Data!$C$2:$C$34,$A11,Raw_Data!$N$2:$N$34) -> 1.3769734 | O11: =AVERAGEIF(Raw_Data!$C$2:$C$34,$A11,Raw_Data!$O$2:$O$34) -> 3.2746667 | P11: =AVERAGEIF(Raw_Data!$C$2:$C$34,$A11,Raw_Data!$P$2:$P$34) -> 0.5 | Q11: =AVERAGEIF(Raw_Data!$C$2:$C$34,$A11,Raw_Data!$Q$2:$Q$34) -> 0.5 | R11: =AVERAGEIF(Raw_Data!$C$2:$C$34,$A11,Raw_Data!$R$2:$R$34) -> 40.375973 | S11: =SQRT(SUMPRODUCT((Raw_Data!$C$2:$C$34=$A11)*(Raw_Data!$D$2:$D$34-D11)^2)/($C11-1)) -> 0.29564562 | T11: =SQRT(SUMPRODUCT((Raw_Data!$C$2:$C$34=$A11)*(Raw_Data!$E$2:$E$34-E11)^2)/($C11-1)) -> 0.55301266 | U11: =SQRT(SUMPRODUCT((Raw_Data!$C$2:$C$34=$A11)*(Raw_Data!$F$2:$F$34-F11)^2)/($C11-1)) -> 0 | V11: =SQRT(SUMPRODUCT((Raw_Data!$C$2:$C$34=$A11)*(Raw_Data!$G$2:$G$34-G11)^2)/($C11-1)) -> 1.5632199 | W11: =SQRT(SUMPRODUCT((Raw_Data!$C$2:$C$34=$A11)*(Raw_Data!$H$2:$H$34-H11)^2)/($C11-1)) -> 0.26097956 | X11: =SQRT(SUMPRODUCT((Raw_Data!$C$2:$C$34=$A11)*(Raw_Data!$I$2:$I$34-I11)^2)/($C11-1)) -> 2.3709083 | Y11: =SQRT(SUMPRODUCT((Raw_Data!$C$2:$C$34=$A11)*(Raw_Data!$J$2:$J$34-J11)^2)/($C11-1)) -> 0.70817112 | Z11: =SQRT(SUMPRODUCT((Raw_Data!$C$2:$C$34=$A11)*(Raw_Data!$K$2:$K$34-K11)^2)/($C11-1)) -> 1.385762 | AA11: =SQRT(SUMPRODUCT((Raw_Data!$C$2:$C$34=$A11)*(Raw_Data!$L$2:$L$34-L11)^2)/($C11-1)) -> 0 | AB11: =SQRT(SUMPRODUCT((Raw_Data!$C$2:$C$34=$A11)*(Raw_Data!$M$2:$M$34-M11)^2)/($C11-1)) -> 0 | AC11: =SQRT(SUMPRODUCT((Raw_Data!$C$2:$C$34=$A11)*(Raw_Data!$N$2:$N$34-N11)^2)/($C11-1)) -> 0.76610703 | AD11: =SQRT(SUMPRODUCT((Raw_Data!$C$2:$C$34=$A11)*(Raw_Data!$O$2:$O$34-O11)^2)/($C11-1)) -> 0.36663924 | AE11: =SQRT(SUMPRODUCT((Raw_Data!$C$2:$C$34=$A11)*(Raw_Data!$P$2:$P$34-P11)^2)/($C11-1)) -> 0 | AF11: =SQRT(SUMPRODUCT((Raw_Data!$C$2:$C$34=$A11)*(Raw_Data!$Q$2:$Q$34-Q11)^2)/($C11-1)) -> 0 | AG11: =SQRT(SUMPRODUCT((Raw_Data!$C$2:$C$34=$A11)*(Raw_Data!$R$2:$R$34-R11)^2)/($C11-1)) -> 3.2294026 | AH11: =SUMPRODUCT(MAX((Raw_Data!$C$2:$C$34=$A11)*Raw_Data!$D$2:$D$34)) -> 3.453 | AI11: =SUMPRODUCT(MAX((Raw_Data!$C$2:$C$34=$A11)*Raw_Data!$E$2:$E$34)) -> 4.043 | AJ11: =SUMPRODUCT(MAX((Raw_Data!$C$2:$C$34=$A11)*Raw_Data!$F$2:$F$34)) -> 0.5 | AK11: =SUMPRODUCT(MAX((Raw_Data!$C$2:$C$34=$A11)*Raw_Data!$G$2:$G$34)) -> 6.148 | AL11: =SUMPRODUCT(MAX((Raw_Data!$C$2:$C$34=$A11)*Raw_Data!$H$2:$H$34)) -> 5.556 | AM11: =SUMPRODUCT(MAX((Raw_Data!$C$2:$C$34=$A11)*Raw_Data!$I$2:$I$34)) -> 11.814 | AN11: =SUMPRODUCT(MAX((Raw_Data!$C$2:$C$34=$A11)*Raw_Data!$J$2:$J$34)) -> 3.392 | AO11: =SUMPRODUCT(MAX((Raw_Data!$C$2:$C$34=$A11)*Raw_Data!$K$2:$K$34)) -> 6.601 | AP11: =SUMPRODUCT(MAX((Raw_Data!$C$2:$C$34=$A11)*Raw_Data!$L$2:$L$34)) -> 0.5 | AQ11: =SUMPRODUCT(MAX((Raw_Data!$C$2:$C$34=$A11)*Raw_Data!$M$2:$M$34)) -> 0.5 | AR11: =SUMPRODUCT(MAX((Raw_Data!$C$2:$C$34=$A11)*Raw_Data!$N$2:$N$34)) -> 1.916 | AS11: =SUMPRODUCT(MAX((Raw_Data!$C$2:$C$34=$A11)*Raw_Data!$O$2:$O$34)) -> 3.647 | AT11: =SUMPRODUCT(MAX((Raw_Data!$C$2:$C$34=$A11)*Raw_Data!$P$2:$P$34)) -> 0.5 | AU11: =SUMPRODUCT(MAX((Raw_Data!$C$2:$C$34=$A11)*Raw_Data!$Q$2:$Q$34)) -> 0.5 | AV11: =SUMPRODUCT(MAX((Raw_Data!$C$2:$C$34=$A11)*Raw_Data!$R$2:$R$34)) -> 43.72
A12: Nichintapur | B12: Site | C12: =COUNTIF(Raw_Data!$C$2:$C$34,$A12) -> 3 | D12: =AVERAGEIF(Raw_Data!$C$2:$C$34,$A12,Raw_Data!$D$2:$D$34) -> 3.275 | E12: =AVERAGEIF(Raw_Data!$C$2:$C$34,$A12,Raw_Data!$E$2:$E$34) -> 3.005 | F12: =AVERAGEIF(Raw_Data!$C$2:$C$34,$A12,Raw_Data!$F$2:$F$34) -> 2.234 | G12: =AVERAGEIF(Raw_Data!$C$2:$C$34,$A12,Raw_Data!$G$2:$G$34) -> 3.0563333 | H12: =AVERAGEIF(Raw_Data!$C$2:$C$34,$A12,Raw_Data!$H$2:$H$34) -> 5.929 | I12: =AVERAGEIF(Raw_Data!$C$2:$C$34,$A12,Raw_Data!$I$2:$I$34) -> 13.360333 | J12: =AVERAGEIF(Raw_Data!$C$2:$C$34,$A12,Raw_Data!$J$2:$J$34) -> 3.294 | K12: =AVERAGEIF(Raw_Data!$C$2:$C$34,$A12,Raw_Data!$K$2:$K$34) -> 6.521 | L12: =AVERAGEIF(Raw_Data!$C$2:$C$34,$A12,Raw_Data!$L$2:$L$34) -> 0.5 | M12: =AVERAGEIF(Raw_Data!$C$2:$C$34,$A12,Raw_Data!$M$2:$M$34) -> 2.6125667 | N12: =AVERAGEIF(Raw_Data!$C$2:$C$34,$A12,Raw_Data!$N$2:$N$34) -> 0.5 | O12: =AVERAGEIF(Raw_Data!$C$2:$C$34,$A12,Raw_Data!$O$2:$O$34) -> 1.9316667 | P12: =AVERAGEIF(Raw_Data!$C$2:$C$34,$A12,Raw_Data!$P$2:$P$34) -> 1.2693333 | Q12: =AVERAGEIF(Raw_Data!$C$2:$C$34,$A12,Raw_Data!$Q$2:$Q$34) -> 3.4523333 | R12: =AVERAGEIF(Raw_Data!$C$2:$C$34,$A12,Raw_Data!$R$2:$R$34) -> 50.940567 | S12: =SQRT(SUMPRODUCT((Raw_Data!$C$2:$C$34=$A12)*(Raw_Data!$D$2:$D$34-D12)^2)/($C12-1)) -> 1.0088543 | T12: =SQRT(SUMPRODUCT((Raw_Data!$C$2:$C$34=$A12)*(Raw_Data!$E$2:$E$34-E12)^2)/($C12-1)) -> 0.76797331 | U12: =SQRT(SUMPRODUCT((Raw_Data!$C$2:$C$34=$A12)*(Raw_Data!$F$2:$F$34-F12)^2)/($C12-1)) -> 0.21656408 | V12: =SQRT(SUMPRODUCT((Raw_Data!$C$2:$C$34=$A12)*(Raw_Data!$G$2:$G$34-G12)^2)/($C12-1)) -> 0.6065314 | W12: =SQRT(SUMPRODUCT((Raw_Data!$C$2:$C$34=$A12)*(Raw_Data!$H$2:$H$34-H12)^2)/($C12-1)) -> 0.36762345 | X12: =SQRT(SUMPRODUCT((Raw_Data!$C$2:$C$34=$A12)*(Raw_Data!$I$2:$I$34-I12)^2)/($C12-1)) -> 0.98582673 | Y12: =SQRT(SUMPRODUCT((Raw_Data!$C$2:$C$34=$A12)*(Raw_Data!$J$2:$J$34-J12)^2)/($C12-1)) -> 0.72200208 | Z12: =SQRT(SUMPRODUCT((Raw_Data!$C$2:$C$34=$A12)*(Raw_Data!$K$2:$K$34-K12)^2)/($C12-1)) -> 1.4160858 | AA12: =SQRT(SUMPRODUCT((Raw_Data!$C$2:$C$34=$A12)*(Raw_Data!$L$2:$L$34-L12)^2)/($C12-1)) -> 0 | AB12: =SQRT(SUMPRODUCT((Raw_Data!$C$2:$C$34=$A12)*(Raw_Data!$M$2:$M$34-M12)^2)/($C12-1)) -> 0.056638003 | AC12: =SQRT(SUMPRODUCT((Raw_Data!$C$2:$C$34=$A12)*(Raw_Data!$N$2:$N$34-N12)^2)/($C12-1)) -> 0 | AD12: =SQRT(SUMPRODUCT((Raw_Data!$C$2:$C$34=$A12)*(Raw_Data!$O$2:$O$34-O12)^2)/($C12-1)) -> 0.53920899 | AE12: =SQRT(SUMPRODUCT((Raw_Data!$C$2:$C$34=$A12)*(Raw_Data!$P$2:$P$34-P12)^2)/($C12-1)) -> 0.081989837 | AF12: =SQRT(SUMPRODUCT((Raw_Data!$C$2:$C$34=$A12)*(Raw_Data!$Q$2:$Q$34-Q12)^2)/($C12-1)) -> 0.4494467 | AG12: =SQRT(SUMPRODUCT((Raw_Data!$C$2:$C$34=$A12)*(Raw_Data!$R$2:$R$34-R12)^2)/($C12-1)) -> 1.7378056 | AH12: =SUMPRODUCT(MAX((Raw_Data!$C$2:$C$34=$A12)*Raw_Data!$D$2:$D$34)) -> 4.352 | AI12: =SUMPRODUCT(MAX((Raw_Data!$C$2:$C$34=$A12)*Raw_Data!$E$2:$E$34)) -> 3.546 | AJ12: =SUMPRODUCT(MAX((Raw_Data!$C$2:$C$34=$A12)*Raw_Data!$F$2:$F$34)) -> 2.364 | AK12: =SUMPRODUCT(MAX((Raw_Data!$C$2:$C$34=$A12)*Raw_Data!$G$2:$G$34)) -> 3.412 | AL12: =SUMPRODUCT(MAX((Raw_Data!$C$2:$C$34=$A12)*Raw_Data!$H$2:$H$34)) -> 6.302 | AM12: =SUMPRODUCT(MAX((Raw_Data!$C$2:$C$34=$A12)*Raw_Data!$I$2:$I$34)) -> 13.931 | AN12: =SUMPRODUCT(MAX((Raw_Data!$C$2:$C$34=$A12)*Raw_Data!$J$2:$J$34)) -> 4.127 | AO12: =SUMPRODUCT(MAX((Raw_Data!$C$2:$C$34=$A12)*Raw_Data!$K$2:$K$34)) -> 8.156 | AP12: =SUMPRODUCT(MAX((Raw_Data!$C$2:$C$34=$A12)*Raw_Data!$L$2:$L$34)) -> 0.5 | AQ12: =SUMPRODUCT(MAX((Raw_Data!$C$2:$C$34=$A12)*Raw_Data!$M$2:$M$34)) -> 2.673 | AR12: =SUMPRODUCT(MAX((Raw_Data!$C$2:$C$34=$A12)*Raw_Data!$N$2:$N$34)) -> 0.5 | AS12: =SUMPRODUCT(MAX((Raw_Data!$C$2:$C$34=$A12)*Raw_Data!$O$2:$O$34)) -> 2.437 | AT12: =SUMPRODUCT(MAX((Raw_Data!$C$2:$C$34=$A12)*Raw_Data!$P$2:$P$34)) -> 1.364 | AU12: =SUMPRODUCT(MAX((Raw_Data!$C$2:$C$34=$A12)*Raw_Data!$Q$2:$Q$34)) -> 3.884 | AV12: =SUMPRODUCT(MAX((Raw_Data!$C$2:$C$34=$A12)*Raw_Data!$R$2:$R$34)) -> 52.5977
A13: Nadimpur | B13: Site | C13: =COUNTIF(Raw_Data!$C$2:$C$34,$A13) -> 3 | D13: =AVERAGEIF(Raw_Data!$C$2:$C$34,$A13,Raw_Data!$D$2:$D$34) -> 3.5516667 | E13: =AVERAGEIF(Raw_Data!$C$2:$C$34,$A13,Raw_Data!$E$2:$E$34) -> 4.2263333 | F13: =AVERAGEIF(Raw_Data!$C$2:$C$34,$A13,Raw_Data!$F$2:$F$34) -> 3.416 | G13: =AVERAGEIF(Raw_Data!$C$2:$C$34,$A13,Raw_Data!$G$2:$G$34) -> 3.8096667 | H13: =AVERAGEIF(Raw_Data!$C$2:$C$34,$A13,Raw_Data!$H$2:$H$34) -> 6.133 | I13: =AVERAGEIF(Raw_Data!$C$2:$C$34,$A13,Raw_Data!$I$2:$I$34) -> 14.393333 | J13: =AVERAGEIF(Raw_Data!$C$2:$C$34,$A13,Raw_Data!$J$2:$J$34) -> 4.3863333 | K13: =AVERAGEIF(Raw_Data!$C$2:$C$34,$A13,Raw_Data!$K$2:$K$34) -> 7.6533333 | L13: =AVERAGEIF(Raw_Data!$C$2:$C$34,$A13,Raw_Data!$L$2:$L$34) -> 1.611 | M13: =AVERAGEIF(Raw_Data!$C$2:$C$34,$A13,Raw_Data!$M$2:$M$34) -> 2.94 | N13: =AVERAGEIF(Raw_Data!$C$2:$C$34,$A13,Raw_Data!$N$2:$N$34) -> 1.6553333 | O13: =AVERAGEIF(Raw_Data!$C$2:$C$34,$A13,Raw_Data!$O$2:$O$34) -> 3.2873333 | P13: =AVERAGEIF(Raw_Data!$C$2:$C$34,$A13,Raw_Data!$P$2:$P$34) -> 1.84 | Q13: =AVERAGEIF(Raw_Data!$C$2:$C$34,$A13,Raw_Data!$Q$2:$Q$34) -> 3.1616667 | R13: =AVERAGEIF(Raw_Data!$C$2:$C$34,$A13,Raw_Data!$R$2:$R$34) -> 62.065 | S13: =SQRT(SUMPRODUCT((Raw_Data!$C$2:$C$34=$A13)*(Raw_Data!$D$2:$D$34-D13)^2)/($C13-1)) -> 0.36871986 | T13: =SQRT(SUMPRODUCT((Raw_Data!$C$2:$C$34=$A13)*(Raw_Data!$E$2:$E$34-E13)^2)/($C13-1)) -> 0.21939538 | U13: =SQRT(SUMPRODUCT((Raw_Data!$C$2:$C$34=$A13)*(Raw_Data!$F$2:$F$34-F13)^2)/($C13-1)) -> 0.33995147 | V13: =SQRT(SUMPRODUCT((Raw_Data!$C$2:$C$34=$A13)*(Raw_Data!$G$2:$G$34-G13)^2)/($C13-1)) -> 0.56499322 | W13: =SQRT(SUMPRODUCT((Raw_Data!$C$2:$C$34=$A13)*(Raw_Data!$H$2:$H$34-H13)^2)/($C13-1)) -> 1.6271189 | X13: =SQRT(SUMPRODUCT((Raw_Data!$C$2:$C$34=$A13)*(Raw_Data!$I$2:$I$34-I13)^2)/($C13-1)) -> 0.54278572 | Y13: =SQRT(SUMPRODUCT((Raw_Data!$C$2:$C$34=$A13)*(Raw_Data!$J$2:$J$34-J13)^2)/($C13-1)) -> 1.0744451 | Z13: =SQRT(SUMPRODUCT((Raw_Data!$C$2:$C$34=$A13)*(Raw_Data!$K$2:$K$34-K13)^2)/($C13-1)) -> 0.96874678 | AA13: =SQRT(SUMPRODUCT((Raw_Data!$C$2:$C$34=$A13)*(Raw_Data!$L$2:$L$34-L13)^2)/($C13-1)) -> 0.29358304 | AB13: =SQRT(SUMPRODUCT((Raw_Data!$C$2:$C$34=$A13)*(Raw_Data!$M$2:$M$34-M13)^2)/($C13-1)) -> 0.31784116 | AC13: =SQRT(SUMPRODUCT((Raw_Data!$C$2:$C$34=$A13)*(Raw_Data!$N$2:$N$34-N13)^2)/($C13-1)) -> 0.30568666 | AD13: =SQRT(SUMPRODUCT((Raw_Data!$C$2:$C$34=$A13)*(Raw_Data!$O$2:$O$34-O13)^2)/($C13-1)) -> 0.32618144 | AE13: =SQRT(SUMPRODUCT((Raw_Data!$C$2:$C$34=$A13)*(Raw_Data!$P$2:$P$34-P13)^2)/($C13-1)) -> 0.62459347 | AF13: =SQRT(SUMPRODUCT((Raw_Data!$C$2:$C$34=$A13)*(Raw_Data!$Q$2:$Q$34-Q13)^2)/($C13-1)) -> 0.31600686 | AG13: =SQRT(SUMPRODUCT((Raw_Data!$C$2:$C$34=$A13)*(Raw_Data!$R$2:$R$34-R13)^2)/($C13-1)) -> 3.4058569 | AH13: =SUMPRODUCT(MAX((Raw_Data!$C$2:$C$34=$A13)*Raw_Data!$D$2:$D$34)) -> 3.956 | AI13: =SUMPRODUCT(MAX((Raw_Data!$C$2:$C$34=$A13)*Raw_Data!$E$2:$E$34)) -> 4.354 | AJ13: =SUMPRODUCT(MAX((Raw_Data!$C$2:$C$34=$A13)*Raw_Data!$F$2:$F$34)) -> 3.733 | AK13: =SUMPRODUCT(MAX((Raw_Data!$C$2:$C$34=$A13)*Raw_Data!$G$2:$G$34)) -> 4.393 | AL13: =SUMPRODUCT(MAX((Raw_Data!$C$2:$C$34=$A13)*Raw_Data!$H$2:$H$34)) -> 7.447 | AM13: =SUMPRODUCT(MAX((Raw_Data!$C$2:$C$34=$A13)*Raw_Data!$I$2:$I$34)) -> 14.781 | AN13: =SUMPRODUCT(MAX((Raw_Data!$C$2:$C$34=$A13)*Raw_Data!$J$2:$J$34)) -> 5.52 | AO13: =SUMPRODUCT(MAX((Raw_Data!$C$2:$C$34=$A13)*Raw_Data!$K$2:$K$34)) -> 8.312 | AP13: =SUMPRODUCT(MAX((Raw_Data!$C$2:$C$34=$A13)*Raw_Data!$L$2:$L$34)) -> 1.936 | AQ13: =SUMPRODUCT(MAX((Raw_Data!$C$2:$C$34=$A13)*Raw_Data!$M$2:$M$34)) -> 3.307 | AR13: =SUMPRODUCT(MAX((Raw_Data!$C$2:$C$34=$A13)*Raw_Data!$N$2:$N$34)) -> 1.967 | AS13: =SUMPRODUCT(MAX((Raw_Data!$C$2:$C$34=$A13)*Raw_Data!$O$2:$O$34)) -> 3.625 | AT13: =SUMPRODUCT(MAX((Raw_Data!$C$2:$C$34=$A13)*Raw_Data!$P$2:$P$34)) -> 2.273 | AU13: =SUMPRODUCT(MAX((Raw_Data!$C$2:$C$34=$A13)*Raw_Data!$Q$2:$Q$34)) -> 3.508 | AV13: =SUMPRODUCT(MAX((Raw_Data!$C$2:$C$34=$A13)*Raw_Data!$R$2:$R$34)) -> 64.309
A14: West Binajuri | B14: Site | C14: =COUNTIF(Raw_Data!$C$2:$C$34,$A14) -> 3 | D14: =AVERAGEIF(Raw_Data!$C$2:$C$34,$A14,Raw_Data!$D$2:$D$34) -> 4.111 | E14: =AVERAGEIF(Raw_Data!$C$2:$C$34,$A14,Raw_Data!$E$2:$E$34) -> 4.158 | F14: =AVERAGEIF(Raw_Data!$C$2:$C$34,$A14,Raw_Data!$F$2:$F$34) -> 4.8386667 | G14: =AVERAGEIF(Raw_Data!$C$2:$C$34,$A14,Raw_Data!$G$2:$G$34) -> 4.027 | H14: =AVERAGEIF(Raw_Data!$C$2:$C$34,$A14,Raw_Data!$H$2:$H$34) -> 6.0986667 | I14: =AVERAGEIF(Raw_Data!$C$2:$C$34,$A14,Raw_Data!$I$2:$I$34) -> 14.029667 | J14: =AVERAGEIF(Raw_Data!$C$2:$C$34,$A14,Raw_Data!$J$2:$J$34) -> 5.5881667 | K14: =AVERAGEIF(Raw_Data!$C$2:$C$34,$A14,Raw_Data!$K$2:$K$34) -> 11.009 | L14: =AVERAGEIF(Raw_Data!$C$2:$C$34,$A14,Raw_Data!$L$2:$L$34) -> 2.2913333 | M14: =AVERAGEIF(Raw_Data!$C$2:$C$34,$A14,Raw_Data!$M$2:$M$34) -> 3.4736667 | N14: =AVERAGEIF(Raw_Data!$C$2:$C$34,$A14,Raw_Data!$N$2:$N$34) -> 1.5573333 | O14: =AVERAGEIF(Raw_Data!$C$2:$C$34,$A14,Raw_Data!$O$2:$O$34) -> 2.6923333 | P14: =AVERAGEIF(Raw_Data!$C$2:$C$34,$A14,Raw_Data!$P$2:$P$34) -> 0.5 | Q14: =AVERAGEIF(Raw_Data!$C$2:$C$34,$A14,Raw_Data!$Q$2:$Q$34) -> 2.865 | R14: =AVERAGEIF(Raw_Data!$C$2:$C$34,$A14,Raw_Data!$R$2:$R$34) -> 67.239833 | S14: =SQRT(SUMPRODUCT((Raw_Data!$C$2:$C$34=$A14)*(Raw_Data!$D$2:$D$34-D14)^2)/($C14-1)) -> 0.22095022 | T14: =SQRT(SUMPRODUCT((Raw_Data!$C$2:$C$34=$A14)*(Raw_Data!$E$2:$E$34-E14)^2)/($C14-1)) -> 1.0463866 | U14: =SQRT(SUMPRODUCT((Raw_Data!$C$2:$C$34=$A14)*(Raw_Data!$F$2:$F$34-F14)^2)/($C14-1)) -> 0.4185228 | V14: =SQRT(SUMPRODUCT((Raw_Data!$C$2:$C$34=$A14)*(Raw_Data!$G$2:$G$34-G14)^2)/($C14-1)) -> 1.6393368 | W14: =SQRT(SUMPRODUCT((Raw_Data!$C$2:$C$34=$A14)*(Raw_Data!$H$2:$H$34-H14)^2)/($C14-1)) -> 0.45243379 | X14: =SQRT(SUMPRODUCT((Raw_Data!$C$2:$C$34=$A14)*(Raw_Data!$I$2:$I$34-I14)^2)/($C14-1)) -> 0.49873874 | Y14: =SQRT(SUMPRODUCT((Raw_Data!$C$2:$C$34=$A14)*(Raw_Data!$J$2:$J$34-J14)^2)/($C14-1)) -> 0.5341934 | Z14: =SQRT(SUMPRODUCT((Raw_Data!$C$2:$C$34=$A14)*(Raw_Data!$K$2:$K$34-K14)^2)/($C14-1)) -> 1.0470057 | AA14: =SQRT(SUMPRODUCT((Raw_Data!$C$2:$C$34=$A14)*(Raw_Data!$L$2:$L$34-L14)^2)/($C14-1)) -> 0.39727111 | AB14: =SQRT(SUMPRODUCT((Raw_Data!$C$2:$C$34=$A14)*(Raw_Data!$M$2:$M$34-M14)^2)/($C14-1)) -> 1.0160976 | AC14: =SQRT(SUMPRODUCT((Raw_Data!$C$2:$C$34=$A14)*(Raw_Data!$N$2:$N$34-N14)^2)/($C14-1)) -> 0.98390311 | AD14: =SQRT(SUMPRODUCT((Raw_Data!$C$2:$C$34=$A14)*(Raw_Data!$O$2:$O$34-O14)^2)/($C14-1)) -> 0.32126676 | AE14: =SQRT(SUMPRODUCT((Raw_Data!$C$2:$C$34=$A14)*(Raw_Data!$P$2:$P$34-P14)^2)/($C14-1)) -> 0 | AF14: =SQRT(SUMPRODUCT((Raw_Data!$C$2:$C$34=$A14)*(Raw_Data!$Q$2:$Q$34-Q14)^2)/($C14-1)) -> 0.8685557 | AG14: =SQRT(SUMPRODUCT((Raw_Data!$C$2:$C$34=$A14)*(Raw_Data!$R$2:$R$34-R14)^2)/($C14-1)) -> 0.67009371 | AH14: =SUMPRODUCT(MAX((Raw_Data!$C$2:$C$34=$A14)*Raw_Data!$D$2:$D$34)) -> 4.364 | AI14: =SUMPRODUCT(MAX((Raw_Data!$C$2:$C$34=$A14)*Raw_Data!$E$2:$E$34)) -> 5.323 | AJ14: =SUMPRODUCT(MAX((Raw_Data!$C$2:$C$34=$A14)*Raw_Data!$F$2:$F$34)) -> 5.186 | AK14: =SUMPRODUCT(MAX((Raw_Data!$C$2:$C$34=$A14)*Raw_Data!$G$2:$G$34)) -> 5.332 | AL14: =SUMPRODUCT(MAX((Raw_Data!$C$2:$C$34=$A14)*Raw_Data!$H$2:$H$34)) -> 6.621 | AM14: =SUMPRODUCT(MAX((Raw_Data!$C$2:$C$34=$A14)*Raw_Data!$I$2:$I$34)) -> 14.466 | AN14: =SUMPRODUCT(MAX((Raw_Data!$C$2:$C$34=$A14)*Raw_Data!$J$2:$J$34)) -> 6.198 | AO14: =SUMPRODUCT(MAX((Raw_Data!$C$2:$C$34=$A14)*Raw_Data!$K$2:$K$34)) -> 12.205 | AP14: =SUMPRODUCT(MAX((Raw_Data!$C$2:$C$34=$A14)*Raw_Data!$L$2:$L$34)) -> 2.537 | AQ14: =SUMPRODUCT(MAX((Raw_Data!$C$2:$C$34=$A14)*Raw_Data!$M$2:$M$34)) -> 4.631 | AR14: =SUMPRODUCT(MAX((Raw_Data!$C$2:$C$34=$A14)*Raw_Data!$N$2:$N$34)) -> 2.446 | AS14: =SUMPRODUCT(MAX((Raw_Data!$C$2:$C$34=$A14)*Raw_Data!$O$2:$O$34)) -> 2.977 | AT14: =SUMPRODUCT(MAX((Raw_Data!$C$2:$C$34=$A14)*Raw_Data!$P$2:$P$34)) -> 0.5 | AU14: =SUMPRODUCT(MAX((Raw_Data!$C$2:$C$34=$A14)*Raw_Data!$Q$2:$Q$34)) -> 3.702 | AV14: =SUMPRODUCT(MAX((Raw_Data!$C$2:$C$34=$A14)*Raw_Data!$R$2:$R$34)) -> 67.935
