Workbook

Sheet README
A1: Halda River OCP Risk Assessment — Sediment: calculation workbook
A3: Companion workbook to the Results chapter "OCP Residues in Surface Sediment, Ecological Risk and Human Health Risk". Every derived number in the chapter is reproduced here with live formulas.
A5: SHEETS
A6: Raw Data ............ 33 sediment samples (11 sites × 3 replicates) × 14 OCPs, µg/kg, as supplied (0 = below detection limit). ΣDDT, ΣHCH, ΣCyclodiene, ΣOCP and per-sample mPEL-Q are formulas.
A7: Descriptive Stats ... mean, SD, median, range, detection frequency per compound; class composition (%).
A8: Site Means .......... mean and SD per site (n = 3) for every compound and class sum.
A9: Zone Means .......... mean, SD and n per zone; class composition by zone.
A10: Group Means ......... single lookup table of mean concentrations for the 11 sites, 3 zones and overall — feeds the risk sheets.
A11: Statistics .......... Kruskal–Wallis test of ΣOCP across zones (formula-based, rank method) and Spearman correlation with site order; SciPy results for cross-check and pairwise Mann–Whitney tests.
A12: Diagnostic Ratios ... DDT/(DDD+DDE), (DDD+DDE)/ΣDDT, DDD/(DDD+DDE), α/γ-HCH, α/β-HCH, β-HCH share.
A13: SQG ................. sediment quality guidelines (TEL/PEL-type values) with sources and surrogate flags — editable inputs.
A14: Ecological Risk ..... RQ = C/TEL, RQ-PEL = C/PEL, risk class, mean PEL-quotient (mPEL-Q), ΣRQ, exceedance counts, per-compound exceedance frequency.
... A23: NOTE: the Kruskal–Wallis H and p on the Statistics sheet are computed with worksheet formulas (rank method, tie-corrected) and agree with the SciPy values listed beside them. Mann–Whitney U tests are reported from SciPy (scipy.stats.mannwhitneyu, two-sided) as values.

Sheet Raw Data
A1: Raw sediment OCP concentrations (µg/kg, wet weight; 0 = not detected)
A2: Source: Sediment.xlsx supplied by the researcher. Blue = input data. Columns R–V are formulas.
A4: Zone | B4: Site | C4: Sample ID | D4: o,p'-DDT | E4: p,p'-DDT | F4: o,p'-DDD | G4: p,p'-DDD | H4: o,p'-DDE | I4: p,p'-DDE | J4: α-HCH | K4: β-HCH | L4: γ-HCH (Lindane) | M4: δ-HCH | N4: Aldrin | O4: Dieldrin | P4: Heptachlor | Q4: Heptachlor epoxide | R4: ΣDDT | S4: ΣHCH | T4: ΣDRN | U4: ΣOCP | V4: mPEL-Q (sample) | W4: ΣHPT
A5: Up-stream | B5: Bhujpur Dam | C5: BSR1 | D5: 3.236 | E5: 6.367 | F5: 2.036 | G5: 2.24 | H5: 7.643 | I5: 11.445 | J5: 3.291 | K5: 6.484 | L5: 0.5 | M5: 0.5 | N5: 0.5 | O5: 0.5 | P5: 0.5 | Q5: 1.836 | R5: =D5+E5+F5+G5+H5+I5 -> 32.967 | S5: =J5+K5+L5+M5 -> 10.775 | T5: =N5+O5 -> 1 | U5: =SUM(D5:Q5) -> 47.078 | V5: =(D5/SQG!$D$5+E5/SQG!$D$6+F5/SQG!$D$7+G5/SQG!$D$8+H5/SQG!$D$9+I5/SQG!$D$10+J5/SQG!$D$11+K5/SQG!$D$12+L5/SQG!$D$13+M5/SQG!$D$14+N5/SQG!$D$15+O5/SQG!$D$16+P5/SQG!$D$17+Q5/SQG!$D$18)/14 -> 0.47911186 | W5: =P5+Q5 -> 2.336
A6: Up-stream | B6: Bhujpur Dam | C6: BSR2 | D6: 1.364 | E6: 5.93 | F6: 4.475 | G6: 4.352 | H6: 8.472 | I6: 9.141 | J6: 2.113 | K6: 4.163 | L6: 0.5 | M6: 0.5 | N6: 0.5 | O6: 1.342 | P6: 0.5 | Q6: 2.511 | R6: =D6+E6+F6+G6+H6+I6 -> 33.734 | S6: =J6+K6+L6+M6 -> 7.276 | T6: =N6+O6 -> 1.842 | U6: =SUM(D6:Q6) -> 45.863 | V6: =(D6/SQG!$D$5+E6/SQG!$D$6+F6/SQG!$D$7+G6/SQG!$D$8+H6/SQG!$D$9+I6/SQG!$D$10+J6/SQG!$D$11+K6/SQG!$D$12+L6/SQG!$D$13+M6/SQG!$D$14+N6/SQG!$D$15+O6/SQG!$D$16+P6/SQG!$D$17+Q6/SQG!$D$18)/14 -> 0.49210842 | W6: =P6+Q6 -> 3.011
A7: Up-stream | B7: Bhujpur Dam | C7: BSR3 | D7: 3.784 | E7: 6.937 | F7: 4.837 | G7: 4.756 | H7: 8.253 | I7: 12.065 | J7: 2.188 | K7: 4.31 | L7: 0.5 | M7: 0.5 | N7: 0.5 | O7: 1.293 | P7: 0.5 | Q7: 2.274 | R7: =D7+E7+F7+G7+H7+I7 -> 40.632 | S7: =J7+K7+L7+M7 -> 7.498 | T7: =N7+O7 -> 1.793 | U7: =SUM(D7:Q7) -> 52.697 | V7: =(D7/SQG!$D$5+E7/SQG!$D$6+F7/SQG!$D$7+G7/SQG!$D$8+H7/SQG!$D$9+I7/SQG!$D$10+J7/SQG!$D$11+K7/SQG!$D$12+L7/SQG!$D$13+M7/SQG!$D$14+N7/SQG!$D$15+O7/SQG!$D$16+P7/SQG!$D$17+Q7/SQG!$D$18)/14 -> 0.57188045 | W7: =P7+Q7 -> 2.774
A8: Up-stream | B8: Ekkhuliya | C8: ESR1 | D8: 0.5 | E8: 4.728 | F8: 0.5 | G8: 0.5 | H8: 7.255 | I8: 8.344 | J8: 0.5 | K8: 0.985 | L8: 0.5 | M8: 0.5 | N8: 0.5 | O8: 0.5 | P8: 0.5 | Q8: 0.5 | R8: =D8+E8+F8+G8+H8+I8 -> 21.827 | S8: =J8+K8+L8+M8 -> 2.485 | T8: =N8+O8 -> 1 | U8: =SUM(D8:Q8) -> 26.312 | V8: =(D8/SQG!$D$5+E8/SQG!$D$6+F8/SQG!$D$7+G8/SQG!$D$8+H8/SQG!$D$9+I8/SQG!$D$10+J8/SQG!$D$11+K8/SQG!$D$12+L8/SQG!$D$13+M8/SQG!$D$14+N8/SQG!$D$15+O8/SQG!$D$16+P8/SQG!$D$17+Q8/SQG!$D$18)/14 -> 0.31048861 | W8: =P8+Q8 -> 1
A9: Up-stream | B9: Ekkhuliya | C9: ESR2 | D9: 0.5 | E9: 4.278 | F9: 0.5 | G9: 0.5 | H9: 7.426 | I9: 7.921 | J9: 0.5 | K9: 0.985 | L9: 0.5 | M9: 0.5 | N9: 0.5 | O9: 0.5 | P9: 0.5 | Q9: 0.5 | R9: =D9+E9+F9+G9+H9+I9 -> 21.125 | S9: =J9+K9+L9+M9 -> 2.485 | T9: =N9+O9 -> 1 | U9: =SUM(D9:Q9) -> 25.61 | V9: =(D9/SQG!$D$5+E9/SQG!$D$6+F9/SQG!$D$7+G9/SQG!$D$8+H9/SQG!$D$9+I9/SQG!$D$10+J9/SQG!$D$11+K9/SQG!$D$12+L9/SQG!$D$13+M9/SQG!$D$14+N9/SQG!$D$15+O9/SQG!$D$16+P9/SQG!$D$17+Q9/SQG!$D$18)/14 -> 0.3010834 | W9: =P9+Q9 -> 1
A10: Up-stream | B10: Ekkhuliya | C10: ESR3 | D10: 0.5 | E10: 5.022 | F10: 0.5 | G10: 0.5 | H10: 7.103 | I10: 8.742 | J10: 0.5 | K10: 0.985 | L10: 0.5 | M10: 0.5 | N10: 0.5 | O10: 0.5 | P10: 0.5 | Q10: 0.5 | R10: =D10+E10+F10+G10+H10+I10 -> 22.367 | S10: =J10+K10+L10+M10 -> 2.485 | T10: =N10+O10 -> 1 | U10: =SUM(D10:Q10) -> 26.852 | V10: =(D10/SQG!$D$5+E10/SQG!$D$6+F10/SQG!$D$7+G10/SQG!$D$8+H10/SQG!$D$9+I10/SQG!$D$10+J10/SQG!$D$11+K10/SQG!$D$12+L10/SQG!$D$13+M10/SQG!$D$14+N10/SQG!$D$15+O10/SQG!$D$16+P10/SQG!$D$17+Q10/SQG!$D$18)/14 -> 0.3174943 | W10: =P10+Q10 -> 1
A11: Up-stream | B11: Nazirhat | C11: NZSR1 | D11: 7.374 | E11: 11.566 | F11: 7.364 | G11: 8.948 | H11: 9.267 | I11: 17.866 | J11: 7.862 | K11: 15.489 | L11: 3.037 | M11: 4.139 | N11: 3.989 | O11: 7.938 | P11: 6.779 | Q11: 8.298 | R11: =D11+E11+F11+G11+H11+I11 -> 62.385 | S11: =J11+K11+L11+M11 -> 30.527 | T11: =N11+O11 -> 11.927 | U11: =SUM(D11:Q11) -> 119.916 | V11: =(D11/SQG!$D$5+E11/SQG!$D$6+F11/SQG!$D$7+G11/SQG!$D$8+H11/SQG!$D$9+I11/SQG!$D$10+J11/SQG!$D$11+K11/SQG!$D$12+L11/SQG!$D$13+M11/SQG!$D$14+N11/SQG!$D$15+O11/SQG!$D$16+P11/SQG!$D$17+Q11/SQG!$D$18)/14 -> 1.3598052 | W11: =P11+Q11 -> 15.077
A12: Up-stream | B12: Nazirhat | C12: NZSR2 | D12: 7.384 | E12: 13.893 | F12: 8.038 | G12: 8.576 | H12: 9.153 | I12: 19.093 | J12: 7.487 | K12: 14.75 | L12: 5.036 | M12: 4.347 | N12: 4.157 | O12: 7.425 | P12: 6.637 | Q12: 11.253 | R12: =D12+E12+F12+G12+H12+I12 -> 66.137 | S12: =J12+K12+L12+M12 -> 31.62 | T12: =N12+O12 -> 11.582 | U12: =SUM(D12:Q12) -> 127.229 | V12: =(D12/SQG!$D$5+E12/SQG!$D$6+F12/SQG!$D$7+G12/SQG!$D$8+H12/SQG!$D$9+I12/SQG!$D$10+J12/SQG!$D$11+K12/SQG!$D$12+L12/SQG!$D$13+M12/SQG!$D$14+N12/SQG!$D$15+O12/SQG!$D$16+P12/SQG!$D$17+Q12/SQG!$D$18)/14 -> 1.5801737 | W12: =P12+Q12 -> 17.89
A13: Up-stream | B13: Nazirhat | C13: NZSR3 | D13: 7.927 | E13: 9.297 | F13: 5.645 | G13: 8.314 | H13: 9.253 | I13: 19.172 | J13: 6.887 | K13: 13.567 | L13: 2.998 | M13: 4.351 | N13: 4.947 | O13: 6.035 | P13: 6.773 | Q13: 9.121 | R13: =D13+E13+F13+G13+H13+I13 -> 59.608 | S13: =J13+K13+L13+M13 -> 27.803 | T13: =N13+O13 -> 10.982 | U13: =SUM(D13:Q13) -> 114.287 | V13: =(D13/SQG!$D$5+E13/SQG!$D$6+F13/SQG!$D$7+G13/SQG!$D$8+H13/SQG!$D$9+I13/SQG!$D$10+J13/SQG!$D$11+K13/SQG!$D$12+L13/SQG!$D$13+M13/SQG!$D$14+N13/SQG!$D$15+O13/SQG!$D$16+P13/SQG!$D$17+Q13/SQG!$D$18)/14 -> 1.3265629 | W13: =P13+Q13 -> 15.894
A14: Mid-stream | B14: Sekandar Para | C14: SSR1 | D14: 3.364 | E14: 6.047 | F14: 0.5 | G14: 3.966 | H14: 6.356 | I14: 12.113 | J14: 2.618 | K14: 5.155 | L14: 0.5 | M14: 0.5 | N14: 1.931 | O14: 3.241 | P14: 0.5 | Q14: 0.5 | R14: =D14+E14+F14+G14+H14+I14 -> 32.346 | S14: =J14+K14+L14+M14 -> 8.773 | T14: =N14+O14 -> 5.172 | U14: =SUM(D14:Q14) -> 47.291 | V14: =(D14/SQG!$D$5+E14/SQG!$D$6+F14/SQG!$D$7+G14/SQG!$D$8+H14/SQG!$D$9+I14/SQG!$D$10+J14/SQG!$D$11+K14/SQG!$D$12+L14/SQG!$D$13+M14/SQG!$D$14+N14/SQG!$D$15+O14/SQG!$D$16+P14/SQG!$D$17+Q14/SQG!$D$18)/14 -> 0.4661514 | W14: =P14+Q14 -> 1
A15: Mid-stream | B15: Sekandar Para | C15: SSR2 | D15: 3.893 | E15: 7.384 | F15: 0.5 | G15: 7.668 | H15: 6.364 | I15: 16.787 | J15: 2.562 | K15: 5.047 | L15: 0.5 | M15: 0.5 | N15: 1.113 | O15: 3.984 | P15: 0.5 | Q15: 0.5 | R15: =D15+E15+F15+G15+H15+I15 -> 42.596 | S15: =J15+K15+L15+M15 -> 8.609 | T15: =N15+O15 -> 5.097 | U15: =SUM(D15:Q15) -> 57.302 | V15: =(D15/SQG!$D$5+E15/SQG!$D$6+F15/SQG!$D$7+G15/SQG!$D$8+H15/SQG!$D$9+I15/SQG!$D$10+J15/SQG!$D$11+K15/SQG!$D$12+L15/SQG!$D$13+M15/SQG!$D$14+N15/SQG!$D$15+O15/SQG!$D$16+P15/SQG!$D$17+Q15/SQG!$D$18)/14 -> 0.58186121 | W15: =P15+Q15 -> 1
A16: Mid-stream | B16: Sekandar Para | C16: SSR3 | D16: 5.637 | E16: 4.938 | F16: 0.5 | G16: 4.756 | H16: 6.924 | I16: 10.1 | J16: 4.119 | K16: 8.115 | L16: 0.5 | M16: 0.5 | N16: 0.5 | O16: 2.846 | P16: 0.5 | Q16: 0.5 | R16: =D16+E16+F16+G16+H16+I16 -> 32.855 | S16: =J16+K16+L16+M16 -> 13.234 | T16: =N16+O16 -> 3.346 | U16: =SUM(D16:Q16) -> 50.435 | V16: =(D16/SQG!$D$5+E16/SQG!$D$6+F16/SQG!$D$7+G16/SQG!$D$8+H16/SQG!$D$9+I16/SQG!$D$10+J16/SQG!$D$11+K16/SQG!$D$12+L16/SQG!$D$13+M16/SQG!$D$14+N16/SQG!$D$15+O16/SQG!$D$16+P16/SQG!$D$17+Q16/SQG!$D$18)/14 -> 0.47149286 | W16: =P16+Q16 -> 1
... A37: Down-stream | B37: Kalurghat | C37: KSR3 | D37: 13.048 | E37: 14.111 | F37: 11.325 | G37: 9.493 | H37: 12.437 | I37: 32.735 | J37: 8.893 | K37: 17.52 | L37: 4.977 | M37: 14.908 | N37: 7.584 | O37: 11.475 | P37: 11.57 | Q37: 13.546 | R37: =D37+E37+F37+G37+H37+I37 -> 93.149 | S37: =J37+K37+L37+M37 -> 46.298 | T37: =N37+O37 -> 19.059 | U37: =SUM(D37:Q37) -> 183.622 | V37: =(D37/SQG!$D$5+E37/SQG!$D$6+F37/SQG!$D$7+G37/SQG!$D$8+H37/SQG!$D$9+I37/SQG!$D$10+J37/SQG!$D$11+K37/SQG!$D$12+L37/SQG!$D$13+M37/SQG!$D$14+N37/SQG!$D$15+O37/SQG!$D$16+P37/SQG!$D$17+Q37/SQG!$D$18)/14 -> 2.1226346 | W37: =P37+Q37 -> 25.116

Sheet Descriptive Stats
A1: Descriptive statistics of OCPs in sediment (µg/kg, n = 33)
A2: All cells are formulas on the Raw Data sheet. Detection frequency = share of samples with concentration > 0.
A4: Compound | B4: Mean | C4: SD | D4: Median | E4: Min | F4: Max | G4: n detected | H4: Detection frequency (%) | I4: Share of ΣOCP (%)
A5: o,p'-DDT | B5: =AVERAGE('Raw Data'!D$5:D$37) -> 6.9943939 | C5: =STDEV('Raw Data'!D$5:D$37) -> 3.5152525 | D5: =MEDIAN('Raw Data'!D$5:D$37) -> 7.374 | E5: =MIN('Raw Data'!D$5:D$37) -> 0.5 | F5: =MAX('Raw Data'!D$5:D$37) -> 13.048 | G5: =COUNTIF('Raw Data'!D$5:D$37,">0") -> 33 | H5: =G5/COUNT('Raw Data'!D$5:D$37)*100 -> 100 | I5: =B5/$B$22*100 -> 7.6835041
A6: p,p'-DDT | B6: =AVERAGE('Raw Data'!E$5:E$37) -> 9.2050303 | C6: =STDEV('Raw Data'!E$5:E$37) -> 2.9431853 | D6: =MEDIAN('Raw Data'!E$5:E$37) -> 9.044 | E6: =MIN('Raw Data'!E$5:E$37) -> 4.278 | F6: =MAX('Raw Data'!E$5:E$37) -> 14.374 | G6: =COUNTIF('Raw Data'!E$5:E$37,">0") -> 33 | H6: =G6/COUNT('Raw Data'!E$5:E$37)*100 -> 100 | I6: =B6/$B$22*100 -> 10.11194
A7: o,p'-DDD | B7: =AVERAGE('Raw Data'!F$5:F$37) -> 5.3420303 | C7: =STDEV('Raw Data'!F$5:F$37) -> 3.7713779 | D7: =MEDIAN('Raw Data'!F$5:F$37) -> 6.047 | E7: =MIN('Raw Data'!F$5:F$37) -> 0.5 | F7: =MAX('Raw Data'!F$5:F$37) -> 11.843 | G7: =COUNTIF('Raw Data'!F$5:F$37,">0") -> 33 | H7: =G7/COUNT('Raw Data'!F$5:F$37)*100 -> 100 | I7: =B7/$B$22*100 -> 5.8683443
A8: p,p'-DDD | B8: =AVERAGE('Raw Data'!G$5:G$37) -> 5.5593939 | C8: =STDEV('Raw Data'!G$5:G$37) -> 2.8017918 | D8: =MEDIAN('Raw Data'!G$5:G$37) -> 5.48 | E8: =MIN('Raw Data'!G$5:G$37) -> 0.5 | F8: =MAX('Raw Data'!G$5:G$37) -> 9.872 | G8: =COUNTIF('Raw Data'!G$5:G$37,">0") -> 33 | H8: =G8/COUNT('Raw Data'!G$5:G$37)*100 -> 100 | I8: =B8/$B$22*100 -> 6.1071233
A9: o,p'-DDE | B9: =AVERAGE('Raw Data'!H$5:H$37) -> 8.3409091 | C9: =STDEV('Raw Data'!H$5:H$37) -> 1.5404943 | D9: =MEDIAN('Raw Data'!H$5:H$37) -> 8.251 | E9: =MIN('Raw Data'!H$5:H$37) -> 5.374 | F9: =MAX('Raw Data'!H$5:H$37) -> 12.437 | G9: =COUNTIF('Raw Data'!H$5:H$37,">0") -> 33 | H9: =G9/COUNT('Raw Data'!H$5:H$37)*100 -> 100 | I9: =B9/$B$22*100 -> 9.1626823
A10: p,p'-DDE | B10: =AVERAGE('Raw Data'!I$5:I$37) -> 18.737273 | C10: =STDEV('Raw Data'!I$5:I$37) -> 6.1004838 | D10: =MEDIAN('Raw Data'!I$5:I$37) -> 19.48 | E10: =MIN('Raw Data'!I$5:I$37) -> 7.921 | F10: =MAX('Raw Data'!I$5:I$37) -> 32.735 | G10: =COUNTIF('Raw Data'!I$5:I$37,">0") -> 33 | H10: =G10/COUNT('Raw Data'!I$5:I$37)*100 -> 100 | I10: =B10/$B$22*100 -> 20.583329
A11: α-HCH | B11: =AVERAGE('Raw Data'!J$5:J$37) -> 5.2813636 | C11: =STDEV('Raw Data'!J$5:J$37) -> 2.5135387 | D11: =MEDIAN('Raw Data'!J$5:J$37) -> 5.731 | E11: =MIN('Raw Data'!J$5:J$37) -> 0.5 | F11: =MAX('Raw Data'!J$5:J$37) -> 9.014 | G11: =COUNTIF('Raw Data'!J$5:J$37,">0") -> 33 | H11: =G11/COUNT('Raw Data'!J$5:J$37)*100 -> 100 | I11: =B11/$B$22*100 -> 5.8017006
A12: β-HCH | B12: =AVERAGE('Raw Data'!K$5:K$37) -> 10.419485 | C12: =STDEV('Raw Data'!K$5:K$37) -> 4.9616194 | D12: =MEDIAN('Raw Data'!K$5:K$37) -> 11.291 | E12: =MIN('Raw Data'!K$5:K$37) -> 0.985 | F12: =MAX('Raw Data'!K$5:K$37) -> 17.757 | G12: =COUNTIF('Raw Data'!K$5:K$37,">0") -> 33 | H12: =G12/COUNT('Raw Data'!K$5:K$37)*100 -> 100 | I12: =B12/$B$22*100 -> 11.446046
A13: γ-HCH (Lindane) | B13: =AVERAGE('Raw Data'!L$5:L$37) -> 1.9577273 | C13: =STDEV('Raw Data'!L$5:L$37) -> 1.5744588 | D13: =MEDIAN('Raw Data'!L$5:L$37) -> 2.046 | E13: =MIN('Raw Data'!L$5:L$37) -> 0.5 | F13: =MAX('Raw Data'!L$5:L$37) -> 5.036 | G13: =COUNTIF('Raw Data'!L$5:L$37,">0") -> 33 | H13: =G13/COUNT('Raw Data'!L$5:L$37)*100 -> 100 | I13: =B13/$B$22*100 -> 2.1506089
A14: δ-HCH | B14: =AVERAGE('Raw Data'!M$5:M$37) -> 4.5849394 | C14: =STDEV('Raw Data'!M$5:M$37) -> 4.2316967 | D14: =MEDIAN('Raw Data'!M$5:M$37) -> 3.477 | E14: =MIN('Raw Data'!M$5:M$37) -> 0.5 | F14: =MAX('Raw Data'!M$5:M$37) -> 16.699 | G14: =COUNTIF('Raw Data'!M$5:M$37,">0") -> 33 | H14: =G14/COUNT('Raw Data'!M$5:M$37)*100 -> 100 | I14: =B14/$B$22*100 -> 5.0366624
A15: Aldrin | B15: =AVERAGE('Raw Data'!N$5:N$37) -> 2.528697 | C15: =STDEV('Raw Data'!N$5:N$37) -> 2.2642055 | D15: =MEDIAN('Raw Data'!N$5:N$37) -> 1.946 | E15: =MIN('Raw Data'!N$5:N$37) -> 0.5 | F15: =MAX('Raw Data'!N$5:N$37) -> 8.452 | G15: =COUNTIF('Raw Data'!N$5:N$37,">0") -> 33 | H15: =G15/COUNT('Raw Data'!N$5:N$37)*100 -> 100 | I15: =B15/$B$22*100 -> 2.7778323
A16: Dieldrin | B16: =AVERAGE('Raw Data'!O$5:O$37) -> 4.1012727 | C16: =STDEV('Raw Data'!O$5:O$37) -> 3.1667255 | D16: =MEDIAN('Raw Data'!O$5:O$37) -> 3.465 | E16: =MIN('Raw Data'!O$5:O$37) -> 0.5 | F16: =MAX('Raw Data'!O$5:O$37) -> 11.475 | G16: =COUNTIF('Raw Data'!O$5:O$37,">0") -> 33 | H16: =G16/COUNT('Raw Data'!O$5:O$37)*100 -> 100 | I16: =B16/$B$22*100 -> 4.5053433
A17: Heptachlor | B17: =AVERAGE('Raw Data'!P$5:P$37) -> 2.8690909 | C17: =STDEV('Raw Data'!P$5:P$37) -> 2.9895673 | D17: =MEDIAN('Raw Data'!P$5:P$37) -> 1.715 | E17: =MIN('Raw Data'!P$5:P$37) -> 0.5 | F17: =MAX('Raw Data'!P$5:P$37) -> 11.57 | G17: =COUNTIF('Raw Data'!P$5:P$37,">0") -> 33 | H17: =G17/COUNT('Raw Data'!P$5:P$37)*100 -> 100 | I17: =B17/$B$22*100 -> 3.151763
A18: Heptachlor epoxide | B18: =AVERAGE('Raw Data'!Q$5:Q$37) -> 5.109697 | C18: =STDEV('Raw Data'!Q$5:Q$37) -> 3.9189 | D18: =MEDIAN('Raw Data'!Q$5:Q$37) -> 4.111 | E18: =MIN('Raw Data'!Q$5:Q$37) -> 0.5 | F18: =MAX('Raw Data'!Q$5:Q$37) -> 13.836 | G18: =COUNTIF('Raw Data'!Q$5:Q$37,">0") -> 33 | H18: =G18/COUNT('Raw Data'!Q$5:Q$37)*100 -> 100 | I18: =B18/$B$22*100 -> 5.6131208
A19: ΣDDT | B19: =AVERAGE('Raw Data'!R$5:R$37) -> 54.17903 | C19: =STDEV('Raw Data'!R$5:R$37) -> 18.36913 | D19: =MEDIAN('Raw Data'!R$5:R$37) -> 54.286 | E19: =MIN('Raw Data'!R$5:R$37) -> 21.125 | F19: =MAX('Raw Data'!R$5:R$37) -> 93.149 | G19: =COUNTIF('Raw Data'!R$5:R$37,">0") -> 33 | H19: =G19/COUNT('Raw Data'!R$5:R$37)*100 -> 100 | I19: =B19/$B$22*100 -> 59.516923
A20: ΣHCH | B20: =AVERAGE('Raw Data'!S$5:S$37) -> 22.243515 | C20: =STDEV('Raw Data'!S$5:S$37) -> 12.282143 | D20: =MEDIAN('Raw Data'!S$5:S$37) -> 23.736 | E20: =MIN('Raw Data'!S$5:S$37) -> 2.485 | F20: =MAX('Raw Data'!S$5:S$37) -> 47.852 | G20: =COUNTIF('Raw Data'!S$5:S$37,">0") -> 33 | H20: =G20/COUNT('Raw Data'!S$5:S$37)*100 -> 100 | I20: =B20/$B$22*100 -> 24.435018
A21: ΣDRN | B21: =AVERAGE('Raw Data'!T$5:T$37) -> 6.6299697 | C21: =STDEV('Raw Data'!T$5:T$37) -> 5.2941812 | D21: =MEDIAN('Raw Data'!T$5:T$37) -> 5.172 | E21: =MIN('Raw Data'!T$5:T$37) -> 1 | F21: =MAX('Raw Data'!T$5:T$37) -> 19.059 | G21: =COUNTIF('Raw Data'!T$5:T$37,">0") -> 33 | H21: =G21/COUNT('Raw Data'!T$5:T$37)*100 -> 100 | I21: =B21/$B$22*100 -> 7.2831757
A22: ΣOCP | B22: =AVERAGE('Raw Data'!U$5:U$37) -> 91.031303 | C22: =STDEV('Raw Data'!U$5:U$37) -> 41.045978 | D22: =MEDIAN('Raw Data'!U$5:U$37) -> 84.424 | E22: =MIN('Raw Data'!U$5:U$37) -> 25.61 | F22: =MAX('Raw Data'!U$5:U$37) -> 183.622 | G22: =COUNTIF('Raw Data'!U$5:U$37,">0") -> 33 | H22: =G22/COUNT('Raw Data'!U$5:U$37)*100 -> 100 | I22: =B22/$B$22*100 -> 100
A23: ΣHPT | B23: =AVERAGE('Raw Data'!W$5:W$37) -> 7.9787879 | C23: =STDEV('Raw Data'!W$5:W$37) -> 6.7644453 | D23: =MEDIAN('Raw Data'!W$5:W$37) -> 5.579 | E23: =MIN('Raw Data'!W$5:W$37) -> 1 | F23: =MAX('Raw Data'!W$5:W$37) -> 25.116 | G23: =COUNTIF('Raw Data'!W$5:W$37,">0") -> 33 | H23: =G23/COUNT('Raw Data'!W$5:W$37)*100 -> 100 | I23: =B23/$B$22*100 -> 8.7648837
A24: ΣDDT = o,p'- and p,p'-DDT, -DDD, -DDE; ΣHCH = α, β, γ, δ-HCH; ΣCyclodiene = aldrin, dieldrin, heptachlor, heptachlor epoxide.

Sheet Site Means
A1: Site-wise mean and SD (µg/kg, n = 3 per site)
A2: Formulas reference the contiguous block of the three replicate rows of each site on the Raw Data sheet.
A4: Site | B4: Zone | C4: Rows | D4: o,p'-DDT | E4: p,p'-DDT | F4: o,p'-DDD | G4: p,p'-DDD | H4: o,p'-DDE | I4: p,p'-DDE | J4: α-HCH | K4: β-HCH | L4: γ-HCH (Lindane) | M4: δ-HCH | N4: Aldrin | O4: Dieldrin | P4: Heptachlor | Q4: Heptachlor epoxide | R4: ΣDDT | S4: ΣHCH | T4: ΣDRN | U4: ΣOCP | W4: ΣHPT
A5: Bhujpur Dam | B5: Up-stream | C5: 5–7 | D5: =AVERAGE('Raw Data'!D5:D7) -> 2.7946667 | E5: =AVERAGE('Raw Data'!E5:E7) -> 6.4113333 | F5: =AVERAGE('Raw Data'!F5:F7) -> 3.7826667 | G5: =AVERAGE('Raw Data'!G5:G7) -> 3.7826667 | H5: =AVERAGE('Raw Data'!H5:H7) -> 8.1226667 | I5: =AVERAGE('Raw Data'!I5:I7) -> 10.883667 | J5: =AVERAGE('Raw Data'!J5:J7) -> 2.5306667 | K5: =AVERAGE('Raw Data'!K5:K7) -> 4.9856667 | ... U5: =AVERAGE('Raw Data'!U5:U7) -> 48.546 | W5: =AVERAGE('Raw Data'!W5:W7) -> 2.707
A6: Ekkhuliya | B6: Up-stream | C6: 8–10 | D6: =AVERAGE('Raw Data'!D8:D10) -> 0.5 | E6: =AVERAGE('Raw Data'!E8:E10) -> 4.676 | F6: =AVERAGE('Raw Data'!F8:F10) -> 0.5 | G6: =AVERAGE('Raw Data'!G8:G10) -> 0.5 | H6: =AVERAGE('Raw Data'!H8:H10) -> 7.2613333 | I6: =AVERAGE('Raw Data'!I8:I10) -> 8.3356667 | J6: =AVERAGE('Raw Data'!J8:J10) -> 0.5 | K6: =AVERAGE('Raw Data'!K8:K10) -> 0.985 | ... U6: =AVERAGE('Raw Data'!U8:U10) -> 26.258 | W6: =AVERAGE('Raw Data'!W8:W10) -> 1
A7: Nazirhat | B7: Up-stream | C7: 11–13 | D7: =AVERAGE('Raw Data'!D11:D13) -> 7.5616667 | E7: =AVERAGE('Raw Data'!E11:E13) -> 11.585333 | F7: =AVERAGE('Raw Data'!F11:F13) -> 7.0156667 | G7: =AVERAGE('Raw Data'!G11:G13) -> 8.6126667 | H7: =AVERAGE('Raw Data'!H11:H13) -> 9.2243333 | I7: =AVERAGE('Raw Data'!I11:I13) -> 18.710333 | J7: =AVERAGE('Raw Data'!J11:J13) -> 7.412 | K7: =AVERAGE('Raw Data'!K11:K13) -> 14.602 | ... U7: =AVERAGE('Raw Data'!U11:U13) -> 120.47733 | W7: =AVERAGE('Raw Data'!W11:W13) -> 16.287
A8: Sekandar Para | B8: Mid-stream | C8: 14–16 | D8: =AVERAGE('Raw Data'!D14:D16) -> 4.298 | E8: =AVERAGE('Raw Data'!E14:E16) -> 6.123 | F8: =AVERAGE('Raw Data'!F14:F16) -> 0.5 | G8: =AVERAGE('Raw Data'!G14:G16) -> 5.4633333 | H8: =AVERAGE('Raw Data'!H14:H16) -> 6.548 | I8: =AVERAGE('Raw Data'!I14:I16) -> 13 | J8: =AVERAGE('Raw Data'!J14:J16) -> 3.0996667 | K8: =AVERAGE('Raw Data'!K14:K16) -> 6.1056667 | ... U8: =AVERAGE('Raw Data'!U14:U16) -> 51.676 | W8: =AVERAGE('Raw Data'!W14:W16) -> 1
A9: Nichintapur | B9: Mid-stream | C9: 17–19 | D9: =AVERAGE('Raw Data'!D17:D19) -> 6.0546667 | E9: =AVERAGE('Raw Data'!E17:E19) -> 8.6763333 | F9: =AVERAGE('Raw Data'!F17:F19) -> 5.019 | G9: =AVERAGE('Raw Data'!G17:G19) -> 3.3926667 | H9: =AVERAGE('Raw Data'!H17:H19) -> 7.388 | I9: =AVERAGE('Raw Data'!I17:I19) -> 18.89 | J9: =AVERAGE('Raw Data'!J17:J19) -> 4.0103333 | K9: =AVERAGE('Raw Data'!K17:K19) -> 7.9003333 | ... U9: =AVERAGE('Raw Data'!U17:U19) -> 72.805 | W9: =AVERAGE('Raw Data'!W17:W19) -> 4.982
A10: Nadimpur | B10: Mid-stream | C10: 20–22 | D10: =AVERAGE('Raw Data'!D20:D22) -> 6.5976667 | E10: =AVERAGE('Raw Data'!E20:E22) -> 9.0756667 | F10: =AVERAGE('Raw Data'!F20:F22) -> 5.859 | G10: =AVERAGE('Raw Data'!G20:G22) -> 4.752 | H10: =AVERAGE('Raw Data'!H20:H22) -> 7.642 | I10: =AVERAGE('Raw Data'!I20:I22) -> 20.352 | J10: =AVERAGE('Raw Data'!J20:J22) -> 5.3076667 | K10: =AVERAGE('Raw Data'!K20:K22) -> 10.522667 | ... U10: =AVERAGE('Raw Data'!U20:U22) -> 80.833333 | W10: =AVERAGE('Raw Data'!W20:W22) -> 4.8703333
A11: West Binajuri | B11: Down-stream | C11: 23–25 | D11: =AVERAGE('Raw Data'!D23:D25) -> 8.3486667 | E11: =AVERAGE('Raw Data'!E23:E25) -> 8.9196667 | F11: =AVERAGE('Raw Data'!F23:F25) -> 0.5 | G11: =AVERAGE('Raw Data'!G23:G25) -> 5.0226667 | H11: =AVERAGE('Raw Data'!H23:H25) -> 7.599 | I11: =AVERAGE('Raw Data'!I23:I25) -> 19.880667 | J11: =AVERAGE('Raw Data'!J23:J25) -> 6.789 | K11: =AVERAGE('Raw Data'!K23:K25) -> 13.374333 | ... U11: =AVERAGE('Raw Data'!U23:U25) -> 85.460333 | W11: =AVERAGE('Raw Data'!W23:W25) -> 3.6716667
A12: Napiter Ghona | B12: Down-stream | C12: 26–28 | D12: =AVERAGE('Raw Data'!D26:D28) -> 9.2173333 | E12: =AVERAGE('Raw Data'!E26:E28) -> 8.7166667 | F12: =AVERAGE('Raw Data'!F26:F28) -> 8.5176667 | G12: =AVERAGE('Raw Data'!G26:G28) -> 5.1293333 | H12: =AVERAGE('Raw Data'!H26:H28) -> 8.131 | I12: =AVERAGE('Raw Data'!I26:I28) -> 20.945667 | J12: =AVERAGE('Raw Data'!J26:J28) -> 5.8396667 | K12: =AVERAGE('Raw Data'!K26:K28) -> 11.503667 | ... U12: =AVERAGE('Raw Data'!U26:U28) -> 100.73633 | W12: =AVERAGE('Raw Data'!W26:W28) -> 9.0593333
A13: Horekrishno Mohajoner Tek | B13: Down-stream | C13: 29–31 | D13: =AVERAGE('Raw Data'!D29:D31) -> 9.456 | E13: =AVERAGE('Raw Data'!E29:E31) -> 10.034667 | F13: =AVERAGE('Raw Data'!F29:F31) -> 6.386 | G13: =AVERAGE('Raw Data'!G29:G31) -> 8.6613333 | H13: =AVERAGE('Raw Data'!H29:H31) -> 9.2606667 | I13: =AVERAGE('Raw Data'!I29:I31) -> 21.23 | J13: =AVERAGE('Raw Data'!J29:J31) -> 7.4593333 | K13: =AVERAGE('Raw Data'!K29:K31) -> 14.695667 | ... U13: =AVERAGE('Raw Data'!U29:U31) -> 111.74067 | W13: =AVERAGE('Raw Data'!W29:W31) -> 8.2726667
A14: Chayar Char | B14: Down-stream | C14: 32–34 | D14: =AVERAGE('Raw Data'!D32:D34) -> 9.984 | E14: =AVERAGE('Raw Data'!E32:E34) -> 13.183667 | F14: =AVERAGE('Raw Data'!F32:F34) -> 9.1683333 | G14: =AVERAGE('Raw Data'!G32:G34) -> 6.525 | H14: =AVERAGE('Raw Data'!H32:H34) -> 9.1703333 | I14: =AVERAGE('Raw Data'!I32:I34) -> 23.928667 | J14: =AVERAGE('Raw Data'!J32:J34) -> 6.7353333 | K14: =AVERAGE('Raw Data'!K32:K34) -> 13.335667 | ... U14: =AVERAGE('Raw Data'!U32:U34) -> 128.581 | W14: =AVERAGE('Raw Data'!W32:W34) -> 13.197333
A15: Kalurghat | B15: Down-stream | C15: 35–37 | D15: =AVERAGE('Raw Data'!D35:D37) -> 12.125667 | E15: =AVERAGE('Raw Data'!E35:E37) -> 13.853 | F15: =AVERAGE('Raw Data'!F35:F37) -> 11.514 | G15: =AVERAGE('Raw Data'!G35:G37) -> 9.3116667 | H15: =AVERAGE('Raw Data'!H35:H37) -> 11.402667 | I15: =AVERAGE('Raw Data'!I35:I37) -> 29.953333 | J15: =AVERAGE('Raw Data'!J35:J37) -> 8.4113333 | K15: =AVERAGE('Raw Data'!K35:K37) -> 16.603667 | ... U15: =AVERAGE('Raw Data'!U35:U37) -> 174.23033 | W15: =AVERAGE('Raw Data'!W35:W37) -> 22.719333
A18: Site (SD) | B18: Zone | C18: Rows | D18: o,p'-DDT | E18: p,p'-DDT | F18: o,p'-DDD | G18: p,p'-DDD | H18: o,p'-DDE | I18: p,p'-DDE | J18: α-HCH | K18: β-HCH | L18: γ-HCH (Lindane) | M18: δ-HCH | N18: Aldrin | O18: Dieldrin | P18: Heptachlor | Q18: Heptachlor epoxide | R18: ΣDDT | S18: ΣHCH | T18: ΣDRN | U18: ΣOCP | W18: ΣHPT
A19: Bhujpur Dam | B19: Up-stream | C19: 5–7 | D19: =STDEV('Raw Data'!D5:D7) -> 1.2689292 | E19: =STDEV('Raw Data'!E5:E7) -> 0.50496171 | F19: =STDEV('Raw Data'!F5:F7) -> 1.5234482 | G19: =STDEV('Raw Data'!G5:G7) -> 1.3511733 | H19: =STDEV('Raw Data'!H5:H7) -> 0.42959322 | I19: =STDEV('Raw Data'!I5:I7) -> 1.5407029 | J19: =STDEV('Raw Data'!J5:J7) -> 0.65953494 | K19: =STDEV('Raw Data'!K5:K7) -> 1.2996747 | ... U19: =STDEV('Raw Data'!U5:U7) -> 3.6458411 | W19: =STDEV('Raw Data'!W5:W7) -> 0.34245146
A20: Ekkhuliya | B20: Up-stream | C20: 8–10 | D20: =STDEV('Raw Data'!D8:D10) -> 0 | E20: =STDEV('Raw Data'!E8:E10) -> 0.37471589 | F20: =STDEV('Raw Data'!F8:F10) -> 0 | G20: =STDEV('Raw Data'!G8:G10) -> 0 | H20: =STDEV('Raw Data'!H8:H10) -> 0.16159311 | I20: =STDEV('Raw Data'!I8:I10) -> 0.41056343 | J20: =STDEV('Raw Data'!J8:J10) -> 0 | K20: =STDEV('Raw Data'!K8:K10) -> 0 | ... U20: =STDEV('Raw Data'!U8:U10) -> 0.62275838 | W20: =STDEV('Raw Data'!W8:W10) -> 0
A21: Nazirhat | B21: Up-stream | C21: 11–13 | D21: =STDEV('Raw Data'!D11:D13) -> 0.31642745 | E21: =STDEV('Raw Data'!E11:E13) -> 2.298061 | F21: =STDEV('Raw Data'!F11:F13) -> 1.2339426 | G21: =STDEV('Raw Data'!G11:G13) -> 0.31858646 | H21: =STDEV('Raw Data'!H11:H13) -> 0.062171805 | I21: =STDEV('Raw Data'!I11:I13) -> 0.73228023 | J21: =STDEV('Raw Data'!J11:J13) -> 0.49180789 | K21: =STDEV('Raw Data'!K11:K13) -> 0.96950967 | ... U21: =STDEV('Raw Data'!U11:U13) -> 6.4892343 | W21: =STDEV('Raw Data'!W11:W13) -> 1.4470933
A22: Sekandar Para | B22: Mid-stream | C22: 14–16 | D22: =STDEV('Raw Data'!D14:D16) -> 1.189391 | E22: =STDEV('Raw Data'!E14:E16) -> 1.2247698 | F22: =STDEV('Raw Data'!F14:F16) -> 0 | G22: =STDEV('Raw Data'!G14:G16) -> 1.9497285 | H22: =STDEV('Raw Data'!H14:H16) -> 0.32565012 | I22: =STDEV('Raw Data'!I14:I16) -> 3.4306077 | J22: =STDEV('Raw Data'!J14:J16) -> 0.88321251 | K22: =STDEV('Raw Data'!K14:K16) -> 1.7409714 | ... U22: =STDEV('Raw Data'!U14:U16) -> 5.1195792 | W22: =STDEV('Raw Data'!W14:W16) -> 0
A23: Nichintapur | B23: Mid-stream | C23: 17–19 | D23: =STDEV('Raw Data'!D17:D19) -> 0.97643911 | E23: =STDEV('Raw Data'!E17:E19) -> 0.63162832 | F23: =STDEV('Raw Data'!F17:F19) -> 1.771895 | G23: =STDEV('Raw Data'!G17:G19) -> 2.5720671 | H23: =STDEV('Raw Data'!H17:H19) -> 0.45816045 | I23: =STDEV('Raw Data'!I17:I19) -> 1.3925778 | J23: =STDEV('Raw Data'!J17:J19) -> 0.88220991 | K23: =STDEV('Raw Data'!K17:K19) -> 1.7378436 | ... U23: =STDEV('Raw Data'!U17:U19) -> 6.1899367 | W23: =STDEV('Raw Data'!W17:W19) -> 0.52294264
A24: Nadimpur | B24: Mid-stream | C24: 20–22 | D24: =STDEV('Raw Data'!D20:D22) -> 1.5728243 | E24: =STDEV('Raw Data'!E20:E22) -> 1.4607838 | F24: =STDEV('Raw Data'!F20:F22) -> 2.4435163 | G24: =STDEV('Raw Data'!G20:G22) -> 0.7052262 | H24: =STDEV('Raw Data'!H20:H22) -> 2.0275298 | I24: =STDEV('Raw Data'!I20:I22) -> 0.76907152 | J24: =STDEV('Raw Data'!J20:J22) -> 1.3347308 | K24: =STDEV('Raw Data'!K20:K22) -> 2.7341288 | ... U24: =STDEV('Raw Data'!U20:U22) -> 3.0524958 | W24: =STDEV('Raw Data'!W20:W22) -> 1.0468258
A25: West Binajuri | B25: Down-stream | C25: 23–25 | D25: =STDEV('Raw Data'!D23:D25) -> 1.2350742 | E25: =STDEV('Raw Data'!E23:E25) -> 1.075593 | F25: =STDEV('Raw Data'!F23:F25) -> 0 | G25: =STDEV('Raw Data'!G23:G25) -> 2.0443878 | H25: =STDEV('Raw Data'!H23:H25) -> 0.56473711 | I25: =STDEV('Raw Data'!I23:I25) -> 0.72597544 | J25: =STDEV('Raw Data'!J23:J25) -> 0.64458359 | K25: =STDEV('Raw Data'!K23:K25) -> 1.2696694 | ... U25: =STDEV('Raw Data'!U23:U25) -> 2.3238077 | W25: =STDEV('Raw Data'!W23:W25) -> 0.97036144
A26: Napiter Ghona | B26: Down-stream | C26: 26–28 | D26: =STDEV('Raw Data'!D26:D28) -> 0.60929167 | E26: =STDEV('Raw Data'!E26:E28) -> 1.7657017 | F26: =STDEV('Raw Data'!F26:F28) -> 1.9037653 | G26: =STDEV('Raw Data'!G26:G28) -> 1.37452 | H26: =STDEV('Raw Data'!H26:H28) -> 0.17393102 | I26: =STDEV('Raw Data'!I26:I28) -> 2.9084966 | J26: =STDEV('Raw Data'!J26:J28) -> 1.777889 | K26: =STDEV('Raw Data'!K26:K28) -> 3.5027797 | ... U26: =STDEV('Raw Data'!U26:U28) -> 6.1337067 | W26: =STDEV('Raw Data'!W26:W28) -> 0.50652674
A27: Horekrishno Mohajoner Tek | B27: Down-stream | C27: 29–31 | D27: =STDEV('Raw Data'!D29:D31) -> 2.232347 | E27: =STDEV('Raw Data'!E29:E31) -> 0.84021981 | F27: =STDEV('Raw Data'!F29:F31) -> 0.4883554 | G27: =STDEV('Raw Data'!G29:G31) -> 1.7619141 | H27: =STDEV('Raw Data'!H29:H31) -> 0.2016168 | I27: =STDEV('Raw Data'!I29:I31) -> 1.5636816 | J27: =STDEV('Raw Data'!J29:J31) -> 0.6182025 | K27: =STDEV('Raw Data'!K29:K31) -> 1.2503817 | ... U27: =STDEV('Raw Data'!U29:U31) -> 1.879517 | W27: =STDEV('Raw Data'!W29:W31) -> 1.7176147
A28: Chayar Char | B28: Down-stream | C28: 32–34 | D28: =STDEV('Raw Data'!D32:D34) -> 2.629815 | E28: =STDEV('Raw Data'!E32:E34) -> 0.32581334 | F28: =STDEV('Raw Data'!F32:F34) -> 0.94951268 | G28: =STDEV('Raw Data'!G32:G34) -> 0.82275391 | H28: =STDEV('Raw Data'!H32:H34) -> 1.6458607 | I28: =STDEV('Raw Data'!I32:I34) -> 1.5111778 | J28: =STDEV('Raw Data'!J32:J34) -> 1.1626377 | K28: =STDEV('Raw Data'!K32:K34) -> 2.2697789 | ... U28: =STDEV('Raw Data'!U32:U34) -> 9.6853442 | W28: =STDEV('Raw Data'!W32:W34) -> 1.4151104
A29: Kalurghat | B29: Down-stream | C29: 35–37 | D29: =STDEV('Raw Data'!D35:D37) -> 1.5932 | E29: =STDEV('Raw Data'!E35:E37) -> 0.68733034 | F29: =STDEV('Raw Data'!F35:F37) -> 0.28597378 | G29: =STDEV('Raw Data'!G35:G37) -> 0.31581218 | H29: =STDEV('Raw Data'!H35:H37) -> 1.7518317 | I29: =STDEV('Raw Data'!I35:I37) -> 2.9167846 | J29: =STDEV('Raw Data'!J35:J37) -> 0.94100708 | K29: =STDEV('Raw Data'!K35:K37) -> 1.7962968 | ... U29: =STDEV('Raw Data'!U35:U37) -> 8.8370262 | W29: =STDEV('Raw Data'!W35:W37) -> 2.5702654

Sheet Zone Means
A1: Zone-wise mean, SD and n (µg/kg)
A2: Up-stream = rows of Bhujpur Dam, Ekkhuliya, Nazirhat; Mid-stream = Sekandar Para, Nichintapur, Nadimpur; Down-stream = the five remaining sites.
A4: Zone | B4: n | C4: Rows | D4: o,p'-DDT | E4: p,p'-DDT | F4: o,p'-DDD | G4: p,p'-DDD | H4: o,p'-DDE | I4: p,p'-DDE | J4: α-HCH | K4: β-HCH | L4: γ-HCH (Lindane) | M4: δ-HCH | N4: Aldrin | O4: Dieldrin | P4: Heptachlor | Q4: Heptachlor epoxide | R4: ΣDDT | S4: ΣHCH | T4: ΣDRN | U4: ΣOCP | W4: ΣHPT
A5: Up-stream | B5: =COUNTA('Raw Data'!C5:C13) -> 9 | C5: 5–13 | D5: =AVERAGE('Raw Data'!D5:D13) -> 3.6187778 | E5: =AVERAGE('Raw Data'!E5:E13) -> 7.5575556 | F5: =AVERAGE('Raw Data'!F5:F13) -> 3.7661111 | G5: =AVERAGE('Raw Data'!G5:G13) -> 4.2984444 | H5: =AVERAGE('Raw Data'!H5:H13) -> 8.2027778 | I5: =AVERAGE('Raw Data'!I5:I13) -> 12.643222 | J5: =AVERAGE('Raw Data'!J5:J13) -> 3.4808889 | K5: =AVERAGE('Raw Data'!K5:K13) -> 6.8575556 | ... U5: =AVERAGE('Raw Data'!U5:U13) -> 65.093778 | W5: =AVERAGE('Raw Data'!W5:W13) -> 6.6646667
A6: Mid-stream | B6: =COUNTA('Raw Data'!C14:C22) -> 9 | C6: 14–22 | D6: =AVERAGE('Raw Data'!D14:D22) -> 5.6501111 | E6: =AVERAGE('Raw Data'!E14:E22) -> 7.9583333 | F6: =AVERAGE('Raw Data'!F14:F22) -> 3.7926667 | G6: =AVERAGE('Raw Data'!G14:G22) -> 4.536 | H6: =AVERAGE('Raw Data'!H14:H22) -> 7.1926667 | I6: =AVERAGE('Raw Data'!I14:I22) -> 17.414 | J6: =AVERAGE('Raw Data'!J14:J22) -> 4.1392222 | K6: =AVERAGE('Raw Data'!K14:K22) -> 8.1762222 | ... U6: =AVERAGE('Raw Data'!U14:U22) -> 68.438111 | W6: =AVERAGE('Raw Data'!W14:W22) -> 3.6174444
A7: Down-stream | B7: =COUNTA('Raw Data'!C23:C37) -> 15 | C7: 23–37 | D7: =AVERAGE('Raw Data'!D23:D37) -> 9.8263333 | E7: =AVERAGE('Raw Data'!E23:E37) -> 10.941533 | F7: =AVERAGE('Raw Data'!F23:F37) -> 7.2172 | G7: =AVERAGE('Raw Data'!G23:G37) -> 6.93 | H7: =AVERAGE('Raw Data'!H23:H37) -> 9.1127333 | I7: =AVERAGE('Raw Data'!I23:I37) -> 23.187667 | J7: =AVERAGE('Raw Data'!J23:J37) -> 7.0469333 | K7: =AVERAGE('Raw Data'!K23:K37) -> 13.9026 | ... U7: =AVERAGE('Raw Data'!U23:U37) -> 120.14973 | W7: =AVERAGE('Raw Data'!W23:W37) -> 11.384067
A10: Zone (SD) | B10: n | C10: Rows | D10: o,p'-DDT | E10: p,p'-DDT | F10: o,p'-DDD | G10: p,p'-DDD | H10: o,p'-DDE | I10: p,p'-DDE | J10: α-HCH | K10: β-HCH | L10: γ-HCH (Lindane) | M10: δ-HCH | N10: Aldrin | O10: Dieldrin | P10: Heptachlor | Q10: Heptachlor epoxide | R10: ΣDDT | S10: ΣHCH | T10: ΣDRN | U10: ΣOCP | W10: ΣHPT
A11: Up-stream | B11: =B5 -> 9 | C11: 5–13 | D11: =STDEV('Raw Data'!D5:D13) -> 3.1874272 | E11: =STDEV('Raw Data'!E5:E13) -> 3.333045 | F11: =STDEV('Raw Data'!F5:F13) -> 2.9868277 | G11: =STDEV('Raw Data'!G5:G13) -> 3.6016402 | H11: =STDEV('Raw Data'!H5:H13) -> 0.8830338 | I11: =STDEV('Raw Data'!I5:I13) -> 4.7636626 | J11: =STDEV('Raw Data'!J5:J13) -> 3.1040395 | K11: =STDEV('Raw Data'!K5:K13) -> 6.1151461 | ... U11: =STDEV('Raw Data'!U5:U13) -> 42.807322 | W11: =STDEV('Raw Data'!W5:W13) -> 7.2925075
A12: Mid-stream | B12: =B6 -> 9 | C12: 14–22 | D12: =STDEV('Raw Data'!D14:D22) -> 1.5146334 | E12: =STDEV('Raw Data'!E14:E22) -> 1.7125649 | F12: =STDEV('Raw Data'!F14:F22) -> 2.9169035 | G12: =STDEV('Raw Data'!G14:G22) -> 1.8864673 | H12: =STDEV('Raw Data'!H14:H22) -> 1.1630039 | I12: =STDEV('Raw Data'!I14:I22) -> 3.8646001 | J12: =STDEV('Raw Data'!J14:J22) -> 1.3260553 | K12: =STDEV('Raw Data'!K14:K22) -> 2.6613069 | ... U12: =STDEV('Raw Data'!U14:U22) -> 13.732831 | W12: =STDEV('Raw Data'!W14:W22) -> 2.0489906
A13: Down-stream | B13: =B7 -> 15 | C13: 23–37 | D13: =STDEV('Raw Data'!D23:D37) -> 2.0120782 | E13: =STDEV('Raw Data'!E23:E37) -> 2.4084798 | F13: =STDEV('Raw Data'!F23:F37) -> 3.9551885 | G13: =STDEV('Raw Data'!G23:G37) -> 2.1883172 | H13: =STDEV('Raw Data'!H23:H37) -> 1.6455081 | I13: =STDEV('Raw Data'!I23:I37) -> 4.1644873 | J13: =STDEV('Raw Data'!J23:J37) -> 1.2914521 | K13: =STDEV('Raw Data'!K23:K37) -> 2.5423182 | ... U13: =STDEV('Raw Data'!U23:U37) -> 32.045884 | W13: =STDEV('Raw Data'!W23:W37) -> 6.7851829
A16: Zone | B16: ΣDDT (%) | C16: ΣHCH (%) | D16: ΣDRN (%) | E16: ΣHPT (%)
A17: Up-stream | B17: =R5/U5*100 -> 61.583288 | C17: =S5/U5*100 -> 20.987498 | D17: =T5/U5*100 -> 7.1906514 | E17: =W5/U5*100 -> 10.238562
A18: Mid-stream | B18: =R6/U6*100 -> 68.008566 | C18: =S6/U6*100 -> 22.04993 | D18: =T6/U6*100 -> 4.655788 | E18: =W6/U6*100 -> 5.2857164
A19: Down-stream | B19: =R7/U7*100 -> 55.943084 | C19: =S7/U7*100 -> 26.370817 | D19: =T7/U7*100 -> 8.2111987 | E19: =W7/U7*100 -> 9.4748997
A20: Overall | B20: ='Descriptive Stats'!B19/'Descriptive Stats'!B22*100 -> 59.516923 | C20: ='Descriptive Stats'!B20/'Descriptive Stats'!B22*100 -> 24.435018 | D20: ='Descriptive Stats'!B21/'Descriptive Stats'!B22*100 -> 7.2831757 | E20: ='Descriptive Stats'!B23/'Descriptive Stats'!B22*100 -> 8.7648837

Sheet Group Means
A1: Mean concentrations (µg/kg) for every site, zone and overall — lookup table for the risk sheets
A2: Green = links to Site Means / Zone Means / Descriptive Stats.
A4: Group | B4: Type | C4: o,p'-DDT | D4: p,p'-DDT | E4: o,p'-DDD | F4: p,p'-DDD | G4: o,p'-DDE | H4: p,p'-DDE | I4: α-HCH | J4: β-HCH | K4: γ-HCH (Lindane) | L4: δ-HCH | M4: Aldrin | N4: Dieldrin | O4: Heptachlor | P4: Heptachlor epoxide | Q4: ΣDDT | R4: ΣHCH | S4: ΣCyclodiene | T4: ΣOCP
A5: Bhujpur Dam | B5: Site | C5: ='Site Means'!D5 -> 2.7946667 | D5: ='Site Means'!E5 -> 6.4113333 | E5: ='Site Means'!F5 -> 3.7826667 | F5: ='Site Means'!G5 -> 3.7826667 | G5: ='Site Means'!H5 -> 8.1226667 | H5: ='Site Means'!I5 -> 10.883667 | I5: ='Site Means'!J5 -> 2.5306667 | J5: ='Site Means'!K5 -> 4.9856667 | ... T5: ='Site Means'!U5 -> 48.546
A6: Ekkhuliya | B6: Site | C6: ='Site Means'!D6 -> 0.5 | D6: ='Site Means'!E6 -> 4.676 | E6: ='Site Means'!F6 -> 0.5 | F6: ='Site Means'!G6 -> 0.5 | G6: ='Site Means'!H6 -> 7.2613333 | H6: ='Site Means'!I6 -> 8.3356667 | I6: ='Site Means'!J6 -> 0.5 | J6: ='Site Means'!K6 -> 0.985 | ... T6: ='Site Means'!U6 -> 26.258
A7: Nazirhat | B7: Site | C7: ='Site Means'!D7 -> 7.5616667 | D7: ='Site Means'!E7 -> 11.585333 | E7: ='Site Means'!F7 -> 7.0156667 | F7: ='Site Means'!G7 -> 8.6126667 | G7: ='Site Means'!H7 -> 9.2243333 | H7: ='Site Means'!I7 -> 18.710333 | I7: ='Site Means'!J7 -> 7.412 | J7: ='Site Means'!K7 -> 14.602 | ... T7: ='Site Means'!U7 -> 120.47733
A8: Sekandar Para | B8: Site | C8: ='Site Means'!D8 -> 4.298 | D8: ='Site Means'!E8 -> 6.123 | E8: ='Site Means'!F8 -> 0.5 | F8: ='Site Means'!G8 -> 5.4633333 | G8: ='Site Means'!H8 -> 6.548 | H8: ='Site Means'!I8 -> 13 | I8: ='Site Means'!J8 -> 3.0996667 | J8: ='Site Means'!K8 -> 6.1056667 | ... T8: ='Site Means'!U8 -> 51.676
A9: Nichintapur | B9: Site | C9: ='Site Means'!D9 -> 6.0546667 | D9: ='Site Means'!E9 -> 8.6763333 | E9: ='Site Means'!F9 -> 5.019 | F9: ='Site Means'!G9 -> 3.3926667 | G9: ='Site Means'!H9 -> 7.388 | H9: ='Site Means'!I9 -> 18.89 | I9: ='Site Means'!J9 -> 4.0103333 | J9: ='Site Means'!K9 -> 7.9003333 | ... T9: ='Site Means'!U9 -> 72.805
A10: Nadimpur | B10: Site | C10: ='Site Means'!D10 -> 6.5976667 | D10: ='Site Means'!E10 -> 9.0756667 | E10: ='Site Means'!F10 -> 5.859 | F10: ='Site Means'!G10 -> 4.752 | G10: ='Site Means'!H10 -> 7.642 | H10: ='Site Means'!I10 -> 20.352 | I10: ='Site Means'!J10 -> 5.3076667 | J10: ='Site Means'!K10 -> 10.522667 | ... T10: ='Site Means'!U10 -> 80.833333
A11: West Binajuri | B11: Site | C11: ='Site Means'!D11 -> 8.3486667 | D11: ='Site Means'!E11 -> 8.9196667 | E11: ='Site Means'!F11 -> 0.5 | F11: ='Site Means'!G11 -> 5.0226667 | G11: ='Site Means'!H11 -> 7.599 | H11: ='Site Means'!I11 -> 19.880667 | I11: ='Site Means'!J11 -> 6.789 | J11: ='Site Means'!K11 -> 13.374333 | ... T11: ='Site Means'!U11 -> 85.460333
A12: Napiter Ghona | B12: Site | C12: ='Site Means'!D12 -> 9.2173333 | D12: ='Site Means'!E12 -> 8.7166667 | E12: ='Site Means'!F12 -> 8.5176667 | F12: ='Site Means'!G12 -> 5.1293333 | G12: ='Site Means'!H12 -> 8.131 | H12: ='Site Means'!I12 -> 20.945667 | I12: ='Site Means'!J12 -> 5.8396667 | J12: ='Site Means'!K12 -> 11.503667 | ... T12: ='Site Means'!U12 -> 100.73633
A13: Horekrishno Mohajoner Tek | B13: Site | C13: ='Site Means'!D13 -> 9.456 | D13: ='Site Means'!E13 -> 10.034667 | E13: ='Site Means'!F13 -> 6.386 | F13: ='Site Means'!G13 -> 8.6613333 | G13: ='Site Means'!H13 -> 9.2606667 | H13: ='Site Means'!I13 -> 21.23 | I13: ='Site Means'!J13 -> 7.4593333 | J13: ='Site Means'!K13 -> 14.695667 | ... T13: ='Site Means'!U13 -> 111.74067
A14: Chayar Char | B14: Site | C14: ='Site Means'!D14 -> 9.984 | D14: ='Site Means'!E14 -> 13.183667 | E14: ='Site Means'!F14 -> 9.1683333 | F14: ='Site Means'!G14 -> 6.525 | G14: ='Site Means'!H14 -> 9.1703333 | H14: ='Site Means'!I14 -> 23.928667 | I14: ='Site Means'!J14 -> 6.7353333 | J14: ='Site Means'!K14 -> 13.335667 | ... T14: ='Site Means'!U14 -> 128.581
A15: Kalurghat | B15: Site | C15: ='Site Means'!D15 -> 12.125667 | D15: ='Site Means'!E15 -> 13.853 | E15: ='Site Means'!F15 -> 11.514 | F15: ='Site Means'!G15 -> 9.3116667 | G15: ='Site Means'!H15 -> 11.402667 | H15: ='Site Means'!I15 -> 29.953333 | I15: ='Site Means'!J15 -> 8.4113333 | J15: ='Site Means'!K15 -> 16.603667 | ... T15: ='Site Means'!U15 -> 174.23033
A16: Up-stream | B16: Zone | C16: ='Zone Means'!D5 -> 3.6187778 | D16: ='Zone Means'!E5 -> 7.5575556 | E16: ='Zone Means'!F5 -> 3.7661111 | F16: ='Zone Means'!G5 -> 4.2984444 | G16: ='Zone Means'!H5 -> 8.2027778 | H16: ='Zone Means'!I5 -> 12.643222 | I16: ='Zone Means'!J5 -> 3.4808889 | J16: ='Zone Means'!K5 -> 6.8575556 | ... T16: ='Zone Means'!U5 -> 65.093778
A17: Mid-stream | B17: Zone | C17: ='Zone Means'!D6 -> 5.6501111 | D17: ='Zone Means'!E6 -> 7.9583333 | E17: ='Zone Means'!F6 -> 3.7926667 | F17: ='Zone Means'!G6 -> 4.536 | G17: ='Zone Means'!H6 -> 7.1926667 | H17: ='Zone Means'!I6 -> 17.414 | I17: ='Zone Means'!J6 -> 4.1392222 | J17: ='Zone Means'!K6 -> 8.1762222 | ... T17: ='Zone Means'!U6 -> 68.438111
A18: Down-stream | B18: Zone | C18: ='Zone Means'!D7 -> 9.8263333 | D18: ='Zone Means'!E7 -> 10.941533 | E18: ='Zone Means'!F7 -> 7.2172 | F18: ='Zone Means'!G7 -> 6.93 | G18: ='Zone Means'!H7 -> 9.1127333 | H18: ='Zone Means'!I7 -> 23.187667 | I18: ='Zone Means'!J7 -> 7.0469333 | J18: ='Zone Means'!K7 -> 13.9026 | ... T18: ='Zone Means'!U7 -> 120.14973
A19: Overall | B19: All samples | C19: ='Descriptive Stats'!B5 -> 6.9943939 | D19: ='Descriptive Stats'!B6 -> 9.2050303 | E19: ='Descriptive Stats'!B7 -> 5.3420303 | F19: ='Descriptive Stats'!B8 -> 5.5593939 | G19: ='Descriptive Stats'!B9 -> 8.3409091 | H19: ='Descriptive Stats'!B10 -> 18.737273 | I19: ='Descriptive Stats'!B11 -> 5.2813636 | J19: ='Descriptive Stats'!B12 -> 10.419485 | K19: ='Descriptive Stats'!B13 -> 1.9577273 | L19: ='Descriptive Stats'!B14 -> 4.5849394 | M19: ='Descriptive Stats'!B15 -> 2.528697 | N19: ='Descriptive Stats'!B16 -> 4.1012727 | O19: ='Descriptive Stats'!B17 -> 2.8690909 | P19: ='Descriptive Stats'!B18 -> 5.109697 | Q19: ='Descriptive Stats'!B19 -> 54.17903 | R19: ='Descriptive Stats'!B20 -> 22.243515 | S19: ='Descriptive Stats'!B21 -> 6.6299697 | T19: ='Descriptive Stats'!B22 -> 91.031303

Sheet Statistics
A1: Non-parametric statistics on ΣOCP
A2: Kruskal–Wallis by worksheet formulas (ranks via RANK.AVG, tie-corrected); SciPy values shown for cross-check. Pairwise Mann–Whitney from SciPy (values).
A4: Sample | B4: Zone | C4: Site order (1 = most up-stream) | D4: ΣOCP | E4: Rank of ΣOCP | F4: Rank of site order
A5: ='Raw Data'!C5 -> BSR1 | B5: ='Raw Data'!A5 -> Up-stream | C5: 1 | D5: ='Raw Data'!U5 -> 47.078 | E5: =_xlfn.RANK.AVG(D5,$D$5:$D$37,1) -> 5 | F5: =_xlfn.RANK.AVG(C5,$C$5:$C$37,1) -> 2
A6: ='Raw Data'!C6 -> BSR2 | B6: ='Raw Data'!A6 -> Up-stream | C6: 1 | D6: ='Raw Data'!U6 -> 45.863 | E6: =_xlfn.RANK.AVG(D6,$D$5:$D$37,1) -> 4 | F6: =_xlfn.RANK.AVG(C6,$C$5:$C$37,1) -> 2
A7: ='Raw Data'!C7 -> BSR3 | B7: ='Raw Data'!A7 -> Up-stream | C7: 1 | D7: ='Raw Data'!U7 -> 52.697 | E7: =_xlfn.RANK.AVG(D7,$D$5:$D$37,1) -> 8 | F7: =_xlfn.RANK.AVG(C7,$C$5:$C$37,1) -> 2
A8: ='Raw Data'!C8 -> ESR1 | B8: ='Raw Data'!A8 -> Up-stream | C8: 2 | D8: ='Raw Data'!U8 -> 26.312 | E8: =_xlfn.RANK.AVG(D8,$D$5:$D$37,1) -> 2 | F8: =_xlfn.RANK.AVG(C8,$C$5:$C$37,1) -> 5
A9: ='Raw Data'!C9 -> ESR2 | B9: ='Raw Data'!A9 -> Up-stream | C9: 2 | D9: ='Raw Data'!U9 -> 25.61 | E9: =_xlfn.RANK.AVG(D9,$D$5:$D$37,1) -> 1 | F9: =_xlfn.RANK.AVG(C9,$C$5:$C$37,1) -> 5
A10: ='Raw Data'!C10 -> ESR3 | B10: ='Raw Data'!A10 -> Up-stream | C10: 2 | D10: ='Raw Data'!U10 -> 26.852 | E10: =_xlfn.RANK.AVG(D10,$D$5:$D$37,1) -> 3 | F10: =_xlfn.RANK.AVG(C10,$C$5:$C$37,1) -> 5
A11: ='Raw Data'!C11 -> NZSR1 | B11: ='Raw Data'!A11 -> Up-stream | C11: 3 | D11: ='Raw Data'!U11 -> 119.916 | E11: =_xlfn.RANK.AVG(D11,$D$5:$D$37,1) -> 26 | F11: =_xlfn.RANK.AVG(C11,$C$5:$C$37,1) -> 8
A12: ='Raw Data'!C12 -> NZSR2 | B12: ='Raw Data'!A12 -> Up-stream | C12: 3 | D12: ='Raw Data'!U12 -> 127.229 | E12: =_xlfn.RANK.AVG(D12,$D$5:$D$37,1) -> 29 | F12: =_xlfn.RANK.AVG(C12,$C$5:$C$37,1) -> 8
A13: ='Raw Data'!C13 -> NZSR3 | B13: ='Raw Data'!A13 -> Up-stream | C13: 3 | D13: ='Raw Data'!U13 -> 114.287 | E13: =_xlfn.RANK.AVG(D13,$D$5:$D$37,1) -> 25 | F13: =_xlfn.RANK.AVG(C13,$C$5:$C$37,1) -> 8
A14: ='Raw Data'!C14 -> SSR1 | B14: ='Raw Data'!A14 -> Mid-stream | C14: 4 | D14: ='Raw Data'!U14 -> 47.291 | E14: =_xlfn.RANK.AVG(D14,$D$5:$D$37,1) -> 6 | F14: =_xlfn.RANK.AVG(C14,$C$5:$C$37,1) -> 11
A15: ='Raw Data'!C15 -> SSR2 | B15: ='Raw Data'!A15 -> Mid-stream | C15: 4 | D15: ='Raw Data'!U15 -> 57.302 | E15: =_xlfn.RANK.AVG(D15,$D$5:$D$37,1) -> 9 | F15: =_xlfn.RANK.AVG(C15,$C$5:$C$37,1) -> 11
A16: ='Raw Data'!C16 -> SSR3 | B16: ='Raw Data'!A16 -> Mid-stream | C16: 4 | D16: ='Raw Data'!U16 -> 50.435 | E16: =_xlfn.RANK.AVG(D16,$D$5:$D$37,1) -> 7 | F16: =_xlfn.RANK.AVG(C16,$C$5:$C$37,1) -> 11
... A37: ='Raw Data'!C37 -> KSR3 | B37: ='Raw Data'!A37 -> Down-stream | C37: 11 | D37: ='Raw Data'!U37 -> 183.622 | E37: =_xlfn.RANK.AVG(D37,$D$5:$D$37,1) -> 33 | F37: =_xlfn.RANK.AVG(C37,$C$5:$C$37,1) -> 32
A39: Kruskal–Wallis test of ΣOCP across zones
A40: Zone | B40: n_i | C40: Sum of ranks R_i | D40: R_i² / n_i
A41: Up-stream | B41: =COUNTIF($B$5:$B$37,A41) -> 9 | C41: =SUMIF($B$5:$B$37,A41,$E$5:$E$37) -> 103 | D41: =C41^2/B41 -> 1178.7778
A42: Mid-stream | B42: =COUNTIF($B$5:$B$37,A42) -> 9 | C42: =SUMIF($B$5:$B$37,A42,$E$5:$E$37) -> 97 | D42: =C42^2/B42 -> 1045.4444
A43: Down-stream | B43: =COUNTIF($B$5:$B$37,A43) -> 15 | C43: =SUMIF($B$5:$B$37,A43,$E$5:$E$37) -> 361 | D43: =C43^2/B43 -> 8688.0667
A44: N | B44: =SUM(B41:B43) -> 33
A45: H (uncorrected) = 12/(N(N+1)) × Σ(R_i²/n_i) − 3(N+1) | B45: =12/(B44*(B44+1))*SUM(D41:D43)-3*(B44+1) -> 14.708972
A46: Tie correction C = 1 − Σ(t³−t)/(N³−N) | B46: =1-SUMPRODUCT((COUNTIF($D$5:$D$37,$D$5:$D$37)^2-1))/(B44^3-B44) -> 1
A47: H (tie-corrected) | B47: =B45/B46 -> 14.708972
A48: degrees of freedom (k − 1) | B48: 2
A49: p-value = CHISQ.DIST.RT(H, df) | B49: =_xlfn.CHISQ.DIST.RT(B47,B48) -> 0.00063971612
A50: SciPy cross-check: H | B50: 13.64896 | C50: scipy.stats.kruskal
A51: SciPy cross-check: p | B51: 0.0010868408
A53: Spearman rank correlation, ΣOCP vs site order (1–11)
A54: ρ = CORREL(rank ΣOCP, rank site order) | B54: =CORREL(E5:E37,F5:F37) -> 0.77591941
A55: t = ρ√((n−2)/(1−ρ²)) | B55: =B54*SQRT((COUNT(D5:D37)-2)/(1-B54^2)) -> 6.8483147
A56: p (two-sided, t-approximation) | B56: =_xlfn.T.DIST.2T(ABS(B55),COUNT(D5:D37)-2) -> 1.1270477e-07
A57: SciPy cross-check: ρ, p | B57: 0.82422567 | C57: 3.7516452e-09
A59: Pairwise Mann–Whitney U tests (SciPy, two-sided; Bonferroni ×3) — values
A60: Comparison | B60: U | C60: p (raw) | D60: p (Bonferroni) | E60: Significant (α = 0.05)?
A61: Up-stream vs Mid-stream | B61: 27 | C61: 0.25099827 | D61: =MIN(1,C61*3) -> 0.75299481 | E61: =IF(D61<0.05,"Yes","No") -> No
A62: Up-stream vs Down-stream | B62: 19 | C62: 0.0042075513 | D62: =MIN(1,C62*3) -> 0.012622654 | E62: =IF(D62<0.05,"Yes","No") -> Yes
A63: Mid-stream vs Down-stream | B63: 15 | C63: 0.0019307622 | D63: =MIN(1,C63*3) -> 0.0057922865 | E63: =IF(D63<0.05,"Yes","No") -> Yes
A65: Kruskal–Wallis by zone for individual compounds and by site for ΣOCP (SciPy values)
...

Sheet Diagnostic Ratios
A1: Source-diagnostic ratios (from group mean concentrations)
A2: DDT/(DDD+DDE) > 1 = recent input; (DDD+DDE)/ΣDDT > 0.5 = aged; DDD/(DDD+DDE) > 0.5 = anaerobic degradation; α/γ-HCH 4–7 = technical HCH, < 1 = lindane. "n.a." = denominator not detected.
A4: Group | B4: DDT (o,p'+p,p') | C4: DDD (o,p'+p,p') | D4: DDE (o,p'+p,p') | E4: DDT/(DDD+DDE) | F4: (DDD+DDE)/ΣDDT | G4: DDD/(DDD+DDE) | H4: o,p'-DDT/p,p'-DDT | I4: α/γ-HCH | J4: α/β-HCH | K4: β-HCH/ΣHCH (%) | L4: (α+γ)/ΣHCH (%)
A5: Bhujpur Dam | B5: ='Group Means'!C5+'Group Means'!D5 -> 9.206 | C5: ='Group Means'!E5+'Group Means'!F5 -> 7.5653333 | D5: ='Group Means'!G5+'Group Means'!H5 -> 19.006333 | E5: =IF((C5+D5)>0,B5/(C5+D5),"n.a.") -> 0.34645926 | F5: =IF('Group Means'!Q5>0,(C5+D5)/'Group Means'!Q5,"n.a.") -> 0.74268864 | G5: =IF((C5+D5)>0,C5/(C5+D5),"n.a.") -> 0.28471429 | H5: =IF('Group Means'!D5>0,'Group Means'!C5/'Group Means'!D5,"n.a.") -> 0.43589477 | I5: =IF('Group Means'!K5>0,'Group Means'!I5/'Group Means'!K5,"n.a.") -> 5.0613333 | J5: =IF('Group Means'!J5>0,'Group Means'!I5/'Group Means'!J5,"n.a.") -> 0.50758842 | K5: =IF('Group Means'!R5>0,'Group Means'!J5/'Group Means'!R5*100,"n.a.") -> 58.542409 | L5: =IF('Group Means'!R5>0,('Group Means'!I5+'Group Means'!K5)/'Group Means'!R5*100,"n.a.") -> 35.58652
A6: Ekkhuliya | B6: ='Group Means'!C6+'Group Means'!D6 -> 5.176 | C6: ='Group Means'!E6+'Group Means'!F6 -> 1 | D6: ='Group Means'!G6+'Group Means'!H6 -> 15.597 | E6: =IF((C6+D6)>0,B6/(C6+D6),"n.a.") -> 0.31186359 | F6: =IF('Group Means'!Q6>0,(C6+D6)/'Group Means'!Q6,"n.a.") -> 0.76227438 | G6: =IF((C6+D6)>0,C6/(C6+D6),"n.a.") -> 0.060251853 | H6: =IF('Group Means'!D6>0,'Group Means'!C6/'Group Means'!D6,"n.a.") -> 0.106929 | I6: =IF('Group Means'!K6>0,'Group Means'!I6/'Group Means'!K6,"n.a.") -> 1 | J6: =IF('Group Means'!J6>0,'Group Means'!I6/'Group Means'!J6,"n.a.") -> 0.50761421 | K6: =IF('Group Means'!R6>0,'Group Means'!J6/'Group Means'!R6*100,"n.a.") -> 39.637827 | L6: =IF('Group Means'!R6>0,('Group Means'!I6+'Group Means'!K6)/'Group Means'!R6*100,"n.a.") -> 40.241449
A7: Nazirhat | B7: ='Group Means'!C7+'Group Means'!D7 -> 19.147 | C7: ='Group Means'!E7+'Group Means'!F7 -> 15.628333 | D7: ='Group Means'!G7+'Group Means'!H7 -> 27.934667 | E7: =IF((C7+D7)>0,B7/(C7+D7),"n.a.") -> 0.43952437 | F7: =IF('Group Means'!Q7>0,(C7+D7)/'Group Means'!Q7,"n.a.") -> 0.6946739 | G7: =IF((C7+D7)>0,C7/(C7+D7),"n.a.") -> 0.35875246 | H7: =IF('Group Means'!D7>0,'Group Means'!C7/'Group Means'!D7,"n.a.") -> 0.65269306 | I7: =IF('Group Means'!K7>0,'Group Means'!I7/'Group Means'!K7,"n.a.") -> 2.0084907 | J7: =IF('Group Means'!J7>0,'Group Means'!I7/'Group Means'!J7,"n.a.") -> 0.5076017 | K7: =IF('Group Means'!R7>0,'Group Means'!J7/'Group Means'!R7*100,"n.a.") -> 48.700389 | L7: =IF('Group Means'!R7>0,('Group Means'!I7+'Group Means'!K7)/'Group Means'!R7*100,"n.a.") -> 37.028349
A8: Sekandar Para | B8: ='Group Means'!C8+'Group Means'!D8 -> 10.421 | C8: ='Group Means'!E8+'Group Means'!F8 -> 5.9633333 | D8: ='Group Means'!G8+'Group Means'!H8 -> 19.548 | E8: =IF((C8+D8)>0,B8/(C8+D8),"n.a.") -> 0.40848512 | F8: =IF('Group Means'!Q8>0,(C8+D8)/'Group Means'!Q8,"n.a.") -> 0.70998265 | G8: =IF((C8+D8)>0,C8/(C8+D8),"n.a.") -> 0.23375232 | H8: =IF('Group Means'!D8>0,'Group Means'!C8/'Group Means'!D8,"n.a.") -> 0.70194349 | I8: =IF('Group Means'!K8>0,'Group Means'!I8/'Group Means'!K8,"n.a.") -> 6.1993333 | J8: =IF('Group Means'!J8>0,'Group Means'!I8/'Group Means'!J8,"n.a.") -> 0.50767047 | K8: =IF('Group Means'!R8>0,'Group Means'!J8/'Group Means'!R8*100,"n.a.") -> 59.828194 | L8: =IF('Group Means'!R8>0,('Group Means'!I8+'Group Means'!K8)/'Group Means'!R8*100,"n.a.") -> 35.272407
A9: Nichintapur | B9: ='Group Means'!C9+'Group Means'!D9 -> 14.731 | C9: ='Group Means'!E9+'Group Means'!F9 -> 8.4116667 | D9: ='Group Means'!G9+'Group Means'!H9 -> 26.278 | E9: =IF((C9+D9)>0,B9/(C9+D9),"n.a.") -> 0.42465095 | F9: =IF('Group Means'!Q9>0,(C9+D9)/'Group Means'!Q9,"n.a.") -> 0.70192632 | G9: =IF((C9+D9)>0,C9/(C9+D9),"n.a.") -> 0.24248335 | H9: =IF('Group Means'!D9>0,'Group Means'!C9/'Group Means'!D9,"n.a.") -> 0.69783703 | I9: =IF('Group Means'!K9>0,'Group Means'!I9/'Group Means'!K9,"n.a.") -> 8.0206667 | J9: =IF('Group Means'!J9>0,'Group Means'!I9/'Group Means'!J9,"n.a.") -> 0.50761571 | K9: =IF('Group Means'!R9>0,'Group Means'!J9/'Group Means'!R9*100,"n.a.") -> 51.353108 | L9: =IF('Group Means'!R9>0,('Group Means'!I9+'Group Means'!K9)/'Group Means'!R9*100,"n.a.") -> 29.317704
A10: Nadimpur | B10: ='Group Means'!C10+'Group Means'!D10 -> 15.673333 | C10: ='Group Means'!E10+'Group Means'!F10 -> 10.611 | D10: ='Group Means'!G10+'Group Means'!H10 -> 27.994 | E10: =IF((C10+D10)>0,B10/(C10+D10),"n.a.") -> 0.40599232 | F10: =IF('Group Means'!Q10>0,(C10+D10)/'Group Means'!Q10,"n.a.") -> 0.71124144 | G10: =IF((C10+D10)>0,C10/(C10+D10),"n.a.") -> 0.27486077 | H10: =IF('Group Means'!D10>0,'Group Means'!C10/'Group Means'!D10,"n.a.") -> 0.72696221 | I10: =IF('Group Means'!K10>0,'Group Means'!I10/'Group Means'!K10,"n.a.") -> 10.615333 | J10: =IF('Group Means'!J10>0,'Group Means'!I10/'Group Means'!J10,"n.a.") -> 0.50440319 | K10: =IF('Group Means'!R10>0,'Group Means'!J10/'Group Means'!R10*100,"n.a.") -> 53.463401 | L10: =IF('Group Means'!R10>0,('Group Means'!I10+'Group Means'!K10)/'Group Means'!R10*100,"n.a.") -> 29.507503
A11: West Binajuri | B11: ='Group Means'!C11+'Group Means'!D11 -> 17.268333 | C11: ='Group Means'!E11+'Group Means'!F11 -> 5.5226667 | D11: ='Group Means'!G11+'Group Means'!H11 -> 27.479667 | E11: =IF((C11+D11)>0,B11/(C11+D11),"n.a.") -> 0.52324583 | F11: =IF('Group Means'!Q11>0,(C11+D11)/'Group Means'!Q11,"n.a.") -> 0.65649285 | G11: =IF((C11+D11)>0,C11/(C11+D11),"n.a.") -> 0.1673417 | H11: =IF('Group Means'!D11>0,'Group Means'!C11/'Group Means'!D11,"n.a.") -> 0.93598415 | I11: =IF('Group Means'!K11>0,'Group Means'!I11/'Group Means'!K11,"n.a.") -> 2.4783402 | J11: =IF('Group Means'!J11>0,'Group Means'!I11/'Group Means'!J11,"n.a.") -> 0.50761409 | K11: =IF('Group Means'!R11>0,'Group Means'!J11/'Group Means'!R11*100,"n.a.") -> 51.250511 | L11: =IF('Group Means'!R11>0,('Group Means'!I11+'Group Means'!K11)/'Group Means'!R11*100,"n.a.") -> 36.51262
A12: Napiter Ghona | B12: ='Group Means'!C12+'Group Means'!D12 -> 17.934 | C12: ='Group Means'!E12+'Group Means'!F12 -> 13.647 | D12: ='Group Means'!G12+'Group Means'!H12 -> 29.076667 | E12: =IF((C12+D12)>0,B12/(C12+D12),"n.a.") -> 0.41976734 | F12: =IF('Group Means'!Q12>0,(C12+D12)/'Group Means'!Q12,"n.a.") -> 0.70434075 | G12: =IF((C12+D12)>0,C12/(C12+D12),"n.a.") -> 0.31942483 | H12: =IF('Group Means'!D12>0,'Group Means'!C12/'Group Means'!D12,"n.a.") -> 1.0574379 | I12: =IF('Group Means'!K12>0,'Group Means'!I12/'Group Means'!K12,"n.a.") -> 2.5062947 | J12: =IF('Group Means'!J12>0,'Group Means'!I12/'Group Means'!J12,"n.a.") -> 0.50763525 | K12: =IF('Group Means'!R12>0,'Group Means'!J12/'Group Means'!R12*100,"n.a.") -> 45.723863 | L12: =IF('Group Means'!R12>0,('Group Means'!I12+'Group Means'!K12)/'Group Means'!R12*100,"n.a.") -> 32.472144
A13: Horekrishno Mohajoner Tek | B13: ='Group Means'!C13+'Group Means'!D13 -> 19.490667 | C13: ='Group Means'!E13+'Group Means'!F13 -> 15.047333 | D13: ='Group Means'!G13+'Group Means'!H13 -> 30.490667 | E13: =IF((C13+D13)>0,B13/(C13+D13),"n.a.") -> 0.42800884 | F13: =IF('Group Means'!Q13>0,(C13+D13)/'Group Means'!Q13,"n.a.") -> 0.70027578 | G13: =IF((C13+D13)>0,C13/(C13+D13),"n.a.") -> 0.33043466 | H13: =IF('Group Means'!D13>0,'Group Means'!C13/'Group Means'!D13,"n.a.") -> 0.94233324 | I13: =IF('Group Means'!K13>0,'Group Means'!I13/'Group Means'!K13,"n.a.") -> 3.2986439 | J13: =IF('Group Means'!J13>0,'Group Means'!I13/'Group Means'!J13,"n.a.") -> 0.50758727 | K13: =IF('Group Means'!R13>0,'Group Means'!J13/'Group Means'!R13*100,"n.a.") -> 48.242091 | L13: =IF('Group Means'!R13>0,('Group Means'!I13+'Group Means'!K13)/'Group Means'!R13*100,"n.a.") -> 31.910447
A14: Chayar Char | B14: ='Group Means'!C14+'Group Means'!D14 -> 23.167667 | C14: ='Group Means'!E14+'Group Means'!F14 -> 15.693333 | D14: ='Group Means'!G14+'Group Means'!H14 -> 33.099 | E14: =IF((C14+D14)>0,B14/(C14+D14),"n.a.") -> 0.47482186 | F14: =IF('Group Means'!Q14>0,(C14+D14)/'Group Means'!Q14,"n.a.") -> 0.67804799 | G14: =IF((C14+D14)>0,C14/(C14+D14),"n.a.") -> 0.32163523 | H14: =IF('Group Means'!D14>0,'Group Means'!C14/'Group Means'!D14,"n.a.") -> 0.7573007 | I14: =IF('Group Means'!K14>0,'Group Means'!I14/'Group Means'!K14,"n.a.") -> 1.8981682 | J14: =IF('Group Means'!J14>0,'Group Means'!I14/'Group Means'!J14,"n.a.") -> 0.50506161 | K14: =IF('Group Means'!R14>0,'Group Means'!J14/'Group Means'!R14*100,"n.a.") -> 41.844387 | L14: =IF('Group Means'!R14>0,('Group Means'!I14+'Group Means'!K14)/'Group Means'!R14*100,"n.a.") -> 32.267883
A15: Kalurghat | B15: ='Group Means'!C15+'Group Means'!D15 -> 25.978667 | C15: ='Group Means'!E15+'Group Means'!F15 -> 20.825667 | D15: ='Group Means'!G15+'Group Means'!H15 -> 41.356 | E15: =IF((C15+D15)>0,B15/(C15+D15),"n.a.") -> 0.41778659 | F15: =IF('Group Means'!Q15>0,(C15+D15)/'Group Means'!Q15,"n.a.") -> 0.70532477 | G15: =IF((C15+D15)>0,C15/(C15+D15),"n.a.") -> 0.33491651 | H15: =IF('Group Means'!D15>0,'Group Means'!C15/'Group Means'!D15,"n.a.") -> 0.8753098 | I15: =IF('Group Means'!K15>0,'Group Means'!I15/'Group Means'!K15,"n.a.") -> 1.883556 | J15: =IF('Group Means'!J15>0,'Group Means'!I15/'Group Means'!J15,"n.a.") -> 0.50659493 | K15: =IF('Group Means'!R15>0,'Group Means'!J15/'Group Means'!R15*100,"n.a.") -> 37.032549 | L15: =IF('Group Means'!R15>0,('Group Means'!I15+'Group Means'!K15)/'Group Means'!R15*100,"n.a.") -> 28.720652
A16: Up-stream | B16: ='Group Means'!C16+'Group Means'!D16 -> 11.176333 | C16: ='Group Means'!E16+'Group Means'!F16 -> 8.0645556 | D16: ='Group Means'!G16+'Group Means'!H16 -> 20.846 | E16: =IF((C16+D16)>0,B16/(C16+D16),"n.a.") -> 0.38658314 | F16: =IF('Group Means'!Q16>0,(C16+D16)/'Group Means'!Q16,"n.a.") -> 0.72119729 | G16: =IF((C16+D16)>0,C16/(C16+D16),"n.a.") -> 0.27894848 | H16: =IF('Group Means'!D16>0,'Group Means'!C16/'Group Means'!D16,"n.a.") -> 0.47882913 | I16: =IF('Group Means'!K16>0,'Group Means'!I16/'Group Means'!K16,"n.a.") -> 2.2264231 | J16: =IF('Group Means'!J16>0,'Group Means'!I16/'Group Means'!J16,"n.a.") -> 0.50759908 | K16: =IF('Group Means'!R16>0,'Group Means'!J16/'Group Means'!R16*100,"n.a.") -> 50.196008 | L16: =IF('Group Means'!R16>0,('Group Means'!I16+'Group Means'!K16)/'Group Means'!R16*100,"n.a.") -> 36.923565
... A19: Overall | B19: ='Group Means'!C19+'Group Means'!D19 -> 16.199424 | C19: ='Group Means'!E19+'Group Means'!F19 -> 10.901424 | D19: ='Group Means'!G19+'Group Means'!H19 -> 27.078182 | E19: =IF((C19+D19)>0,B19/(C19+D19),"n.a.") -> 0.42652955 | F19: =IF('Group Means'!Q19>0,(C19+D19)/'Group Means'!Q19,"n.a.") -> 0.70100195 | G19: =IF((C19+D19)>0,C19/(C19+D19),"n.a.") -> 0.28703363 | H19: =IF('Group Means'!D19>0,'Group Means'!C19/'Group Means'!D19,"n.a.") -> 0.75984475 | I19: =IF('Group Means'!K19>0,'Group Means'!I19/'Group Means'!K19,"n.a.") -> 2.6977014 | J19: =IF('Group Means'!J19>0,'Group Means'!I19/'Group Means'!J19,"n.a.") -> 0.50687378 | K19: =IF('Group Means'!R19>0,'Group Means'!J19/'Group Means'!R19*100,"n.a.") -> 46.842798 | L19: =IF('Group Means'!R19>0,('Group Means'!I19+'Group Means'!K19)/'Group Means'!R19*100,"n.a.") -> 32.544725

Sheet SQG
A1: Sediment quality guidelines (µg/kg dry weight) — editable inputs
A2: Threshold-effect value = TEL/ISQG (CCME 2001), LEL (Persaud et al. 1993) or TEC (MacDonald et al. 2000); probable-effect value = PEL, SEL or PEC. Surrogate = 1 where no compound-specific guideline exists.
A4: Compound | B4: Threshold-effect value (TEL) | C4: Surrogate? (1 = yes) | D4: Probable-effect value (PEL) | E4: Source
A5: o,p'-DDT | B5: 1.19 | C5: 1 | D5: 4.77 | E5: Surrogate: CCME DDT
A6: p,p'-DDT | B6: 1.19 | C6: 0 | D6: 4.77 | E6: CCME (2001) freshwater ISQG/PEL (DDT)
A7: o,p'-DDD | B7: 3.54 | C7: 1 | D7: 8.51 | E7: Surrogate: CCME DDD
A8: p,p'-DDD | B8: 3.54 | C8: 0 | D8: 8.51 | E8: CCME (2001) freshwater ISQG/PEL (DDD)
A9: o,p'-DDE | B9: 1.42 | C9: 1 | D9: 6.75 | E9: Surrogate: CCME DDE
A10: p,p'-DDE | B10: 1.42 | C10: 0 | D10: 6.75 | E10: CCME (2001) freshwater ISQG/PEL (DDE)
A11: α-HCH | B11: 6 | C11: 0 | D11: 100 | E11: Ontario MOE LEL/SEL (Persaud et al., 1993)
A12: β-HCH | B12: 5 | C12: 0 | D12: 210 | E12: Ontario MOE LEL/SEL (Persaud et al., 1993)
A13: γ-HCH (Lindane) | B13: 0.94 | C13: 0 | D13: 1.38 | E13: CCME (2001) freshwater ISQG/PEL (lindane)
A14: δ-HCH | B14: 3 | C14: 1 | D14: 120 | E14: Surrogate: Ontario MOE LEL/SEL for total HCH
A15: Aldrin | B15: 2 | C15: 0 | D15: 80 | E15: Ontario MOE LEL/SEL (Persaud et al., 1993)
A16: Dieldrin | B16: 2.85 | C16: 0 | D16: 6.67 | E16: CCME (2001) freshwater ISQG/PEL
... A18: Heptachlor epoxide | B18: 0.6 | C18: 0 | D18: 2.74 | E18: CCME (2001) freshwater ISQG/PEL
A20: Class sum | B20: Threshold-effect value | D20: Probable-effect value | E20: Source
A21: ΣDDT | B21: 5.28 | D21: 572 | E21: MacDonald et al. (2000) consensus TEC/PEC (total DDT)
A22: ΣHCH | B22: 3 | D22: 120 | E22: Ontario MOE LEL/SEL (total HCH; Persaud et al., 1993)
A25: Risk-class thresholds (Hernando et al., 2006): RQ < 0.1 Low; 0.1 ≤ RQ < 1 Medium; RQ ≥ 1 High.
A26: RQ low/medium boundary | B26: 0.1
A27: RQ medium/high boundary | B27: 1
A29: mPEL-Q bands (Long et al., 1998): ≤ 0.1 → ~8 % probability of toxicity; 0.11–1.5 → ~21 %; 1.51–2.3 → ~49 %; > 2.3 → ~73 %.

Sheet Ecological Risk
A1: Ecological risk screening: RQ = C/TEL, RQ-PEL = C/PEL, mean PEL-quotient
A2: C = group mean concentration (Group Means sheet). Non-detects give RQ = 0. Blank guideline cells would give errors — keep all 14 guideline values filled on the SQG sheet.
A4: A. Mean concentration (µg/kg)
A5: Group | B5: o,p'-DDT | C5: p,p'-DDT | D5: o,p'-DDD | E5: p,p'-DDD | F5: o,p'-DDE | G5: p,p'-DDE | H5: α-HCH | I5: β-HCH | J5: γ-HCH (Lindane) | K5: δ-HCH | L5: Aldrin | M5: Dieldrin | N5: Heptachlor | O5: Heptachlor epoxide
A6: Bhujpur Dam | B6: ='Group Means'!C5 -> 2.7946667 | C6: ='Group Means'!D5 -> 6.4113333 | D6: ='Group Means'!E5 -> 3.7826667 | E6: ='Group Means'!F5 -> 3.7826667 | F6: ='Group Means'!G5 -> 8.1226667 | G6: ='Group Means'!H5 -> 10.883667 | H6: ='Group Means'!I5 -> 2.5306667 | I6: ='Group Means'!J5 -> 4.9856667 | ... O6: ='Group Means'!P5 -> 2.207
