Workbook

Sheet Factor
A1: Actual | B1: Factored | C1: Factor
A2: 7337 | B2: 1000 | C2: =A2/B2 -> 7.337
A3: 963 | B3: 963 | C3: =A3/B3 -> 1

Sheet Phase1
A1: variable | B1: bin | C1: count | D1: count_distr | E1: neg | F1: pos | G1: posprob | H1: woe | I1: bin_iv | J1: total_iv | K1: breaks | L1: is_special_values | M1: Correlation | N1: Bad Rate | O1: Bad Rate (Factored) | P1: Remarks for Binning Adjustment | Q1: Breaks
A2: Bor_No_Rep_Institutes | B2: [-Inf,3) | C2: 886 | D2: 0.45134997 | E2: 467 | F2: 419 | G2: 0.47291196 | H2: -0.070756471 | I2: 0.0022572269 | J2: 0.015827167 | K2: 3 | L2: FALSE | M2: =IFERROR(IF(NOT(ISNUMBER(J2)), "", IF(J2<0.01,"No Correlation",IF(J2<0.03,"Marginal contribution",IF(J2<0.1,"Adequate predictability",IF(J2<0.3,"Strong Predictor",IF(J2<0.5,"Very Strong predictor",IF(J2>=0.5,"Extremely high correlation", ))))))), "") -> Marginal contribution | N2: =IFERROR(F2/C2, 0) -> 0.47291196 | O2: =IFERROR(F2/((E2*Factor!$C$2)+Phase1!F2), 0) -> 0.10896195 | P2: =(F2+F3)/((F2+F3)+(E2+E3)*Factor!$C$2) -> 0.11262863 | Q2: 1, 6
A3: Bor_No_Rep_Institutes | B3: [3,4) | C3: 406 | D3: 0.20682629 | E3: 202 | F3: 204 | G3: 0.50246305 | H3: 0.047554164 | I3: 0.00046783816 | J3: 0.015827167 | K3: 4 | L3: FALSE | M3: =IFERROR(IF(NOT(ISNUMBER(J3)), "", IF(J3<0.01,"No Correlation",IF(J3<0.03,"Marginal contribution",IF(J3<0.1,"Adequate predictability",IF(J3<0.3,"Strong Predictor",IF(J3<0.5,"Very Strong predictor",IF(J3>=0.5,"Extremely high correlation", ))))))), "") -> Marginal contribution | N3: =IFERROR(F3/C3, 0) -> 0.50246305 | O3: =IFERROR(F3/((E3*Factor!$C$2)+Phase1!F3), 0) -> 0.12099113
A4: Bor_No_Rep_Institutes | B4: [4,5) | C4: 270 | D4: 0.13754457 | E4: 127 | F4: 143 | G4: 0.52962963 | H4: 0.15635941 | I4: 0.0033608343 | J4: 0.015827167 | K4: 5 | L4: FALSE | M4: =IFERROR(IF(NOT(ISNUMBER(J4)), "", IF(J4<0.01,"No Correlation",IF(J4<0.03,"Marginal contribution",IF(J4<0.1,"Adequate predictability",IF(J4<0.3,"Strong Predictor",IF(J4<0.5,"Very Strong predictor",IF(J4>=0.5,"Extremely high correlation", ))))))), "") -> Marginal contribution | N4: =IFERROR(F4/C4, 0) -> 0.52962963 | O4: =IFERROR(F4/((E4*Factor!$C$2)+Phase1!F4), 0) -> 0.13304813 | P4: =(F4+F5)/((F4+F5)+(E4+E5)*Factor!$C$2) -> 0.11603833
A5: Bor_No_Rep_Institutes | B5: [5,6) | C5: 156 | D5: 0.079470199 | E5: 90 | F5: 66 | G5: 0.42307692 | H5: -0.27245306 | I5: 0.00584798 | J5: 0.015827167 | K5: 6 | L5: FALSE | M5: =IFERROR(IF(NOT(ISNUMBER(J5)), "", IF(J5<0.01,"No Correlation",IF(J5<0.03,"Marginal contribution",IF(J5<0.1,"Adequate predictability",IF(J5<0.3,"Strong Predictor",IF(J5<0.5,"Very Strong predictor",IF(J5>=0.5,"Extremely high correlation", ))))))), "") -> Marginal contribution | N5: =IFERROR(F5/C5, 0) -> 0.42307692 | O5: =IFERROR(F5/((E5*Factor!$C$2)+Phase1!F5), 0) -> 0.090867787
A6: Bor_No_Rep_Institutes | B6: [6, Inf) | C6: 245 | D6: 0.12480897 | E6: 114 | F6: 131 | G6: 0.53469388 | H6: 0.17670074 | I6: 0.003893288 | J6: 0.015827167 | K6: Inf | L6: FALSE | M6: =IFERROR(IF(NOT(ISNUMBER(J6)), "", IF(J6<0.01,"No Correlation",IF(J6<0.03,"Marginal contribution",IF(J6<0.1,"Adequate predictability",IF(J6<0.3,"Strong Predictor",IF(J6<0.5,"Very Strong predictor",IF(J6>=0.5,"Extremely high correlation", ))))))), "") -> Marginal contribution | N6: =IFERROR(F6/C6, 0) -> 0.53469388 | O6: =IFERROR(F6/((E6*Factor!$C$2)+Phase1!F6), 0) -> 0.13541199 | P6: =O6 -> 0.13541199
M7: =IFERROR(IF(NOT(ISNUMBER(J7)), "", IF(J7<0.01,"No Correlation",IF(J7<0.03,"Marginal contribution",IF(J7<0.1,"Adequate predictability",IF(J7<0.3,"Strong Predictor",IF(J7<0.5,"Very Strong predictor",IF(J7>=0.5,"Extremely high correlation", ))))))), "")
A8: variable | B8: bin | C8: count | D8: count_distr | E8: neg | F8: pos | G8: posprob | H8: woe | I8: bin_iv | J8: total_iv | K8: breaks | L8: is_special_values | M8: =IFERROR(IF(NOT(ISNUMBER(J8)), "", IF(J8<0.01,"No Correlation",IF(J8<0.03,"Marginal contribution",IF(J8<0.1,"Adequate predictability",IF(J8<0.3,"Strong Predictor",IF(J8<0.5,"Very Strong predictor",IF(J8>=0.5,"Extremely high correlation", ))))))), "")
A9: Bor_No_Living_Contracts | B9: [-Inf,1) | C9: 453 | D9: 0.23076923 | E9: 255 | F9: 198 | G9: 0.43708609 | H9: -0.21529465 | I9: 0.010633946 | J9: 0.019195497 | K9: 1 | L9: FALSE | M9: =IFERROR(IF(NOT(ISNUMBER(J9)), "", IF(J9<0.01,"No Correlation",IF(J9<0.03,"Marginal contribution",IF(J9<0.1,"Adequate predictability",IF(J9<0.3,"Strong Predictor",IF(J9<0.5,"Very Strong predictor",IF(J9>=0.5,"Extremely high correlation", ))))))), "") -> Marginal contribution | N9: =IFERROR(F9/C9, 0) -> 0.43708609 | O9: =IFERROR(F9/((E9*Factor!$C$2)+Phase1!F9), 0) -> 0.095701412 | P9: =O9 -> 0.095701412 | Q9: 1, 5
A10: Bor_No_Living_Contracts | B10: [1,2) | C10: 696 | D10: 0.35455935 | E10: 329 | F10: 367 | G10: 0.52729885 | H10: 0.14700596 | I10: 0.0076591176 | J10: 0.019195497 | K10: 2 | L10: FALSE | M10: =IFERROR(IF(NOT(ISNUMBER(J10)), "", IF(J10<0.01,"No Correlation",IF(J10<0.03,"Marginal contribution",IF(J10<0.1,"Adequate predictability",IF(J10<0.3,"Strong Predictor",IF(J10<0.5,"Very Strong predictor",IF(J10>=0.5,"Extremely high correlation", ))))))), "") -> Marginal contribution | N10: =IFERROR(F10/C10, 0) -> 0.52729885 | O10: =IFERROR(F10/((E10*Factor!$C$2)+Phase1!F10), 0) -> 0.13197295 | P10: =(F10+F11)/((F10+F11)+(E10+E11)*Factor!$C$2) -> 0.12243128
A11: Bor_No_Living_Contracts | B11: [2,5) | C11: 676 | D11: 0.34437086 | E11: 349 | F11: 327 | G11: 0.48372781 | H11: -0.027409884 | I11: 0.00025864342 | J11: 0.019195497 | K11: 5 | L11: FALSE | M11: =IFERROR(IF(NOT(ISNUMBER(J11)), "", IF(J11<0.01,"No Correlation",IF(J11<0.03,"Marginal contribution",IF(J11<0.1,"Adequate predictability",IF(J11<0.3,"Strong Predictor",IF(J11<0.5,"Very Strong predictor",IF(J11>=0.5,"Extremely high correlation", ))))))), "") -> Marginal contribution | N11: =IFERROR(F11/C11, 0) -> 0.48372781 | O11: =IFERROR(F11/((E11*Factor!$C$2)+Phase1!F11), 0) -> 0.11324232
A12: Bor_No_Living_Contracts | B12: [5, Inf) | C12: 138 | D12: 0.07030056 | E12: 67 | F12: 71 | G12: 0.51449275 | H12: 0.095689125 | I12: 0.00064379007 | J12: 0.019195497 | K12: Inf | L12: FALSE | M12: =IFERROR(IF(NOT(ISNUMBER(J12)), "", IF(J12<0.01,"No Correlation",IF(J12<0.03,"Marginal contribution",IF(J12<0.1,"Adequate predictability",IF(J12<0.3,"Strong Predictor",IF(J12<0.5,"Very Strong predictor",IF(J12>=0.5,"Extremely high correlation", ))))))), "") -> Marginal contribution | N12: =IFERROR(F12/C12, 0) -> 0.51449275 | O12: =IFERROR(F12/((E12*Factor!$C$2)+Phase1!F12), 0) -> 0.1262045 | P12: =O12 -> 0.1262045
M13: =IFERROR(IF(NOT(ISNUMBER(J13)), "", IF(J13<0.01,"No Correlation",IF(J13<0.03,"Marginal contribution",IF(J13<0.1,"Adequate predictability",IF(J13<0.3,"Strong Predictor",IF(J13<0.5,"Very Strong predictor",IF(J13>=0.5,"Extremely high correlation", ))))))), "")
A14: variable | B14: bin | C14: count | D14: count_distr | E14: neg | F14: pos | G14: posprob | H14: woe | I14: bin_iv | J14: total_iv | K14: breaks | L14: is_special_values | M14: =IFERROR(IF(NOT(ISNUMBER(J14)), "", IF(J14<0.01,"No Correlation",IF(J14<0.03,"Marginal contribution",IF(J14<0.1,"Adequate predictability",IF(J14<0.3,"Strong Predictor",IF(J14<0.5,"Very Strong predictor",IF(J14>=0.5,"Extremely high correlation", ))))))), "")
A15: Bor_Boral_OS_Amt | B15: [-Inf,300000) | C15: 638 | D15: 0.32501274 | E15: 364 | F15: 274 | G15: 0.42946708 | H15: -0.24632389 | I15: 0.019575971 | J15: 0.053361281 | K15: 300000 | L15: FALSE | M15: =IFERROR(IF(NOT(ISNUMBER(J15)), "", IF(J15<0.01,"No Correlation",IF(J15<0.03,"Marginal contribution",IF(J15<0.1,"Adequate predictability",IF(J15<0.3,"Strong Predictor",IF(J15<0.5,"Very Strong predictor",IF(J15>=0.5,"Extremely high correlation", ))))))), "") -> Adequate predictability | N15: =IFERROR(F15/C15, 0) -> 0.42946708 | O15: =IFERROR(F15/((E15*Factor!$C$2)+Phase1!F15), 0) -> 0.093049539 | P15: =(F15+F16)/((F15+F16)+(E15+E16)*Factor!$C$2) -> 0.11551908 | Q15: =K16 -> 900000
A16: Bor_Boral_OS_Amt | B16: [300000,900000) | C16: 488 | D16: 0.24859908 | E16: 211 | F16: 277 | G16: 0.56762295 | H16: 0.30986124 | I16: 0.023748628 | J16: 0.053361281 | K16: 900000 | L16: FALSE | M16: =IFERROR(IF(NOT(ISNUMBER(J16)), "", IF(J16<0.01,"No Correlation",IF(J16<0.03,"Marginal contribution",IF(J16<0.1,"Adequate predictability",IF(J16<0.3,"Strong Predictor",IF(J16<0.5,"Very Strong predictor",IF(J16>=0.5,"Extremely high correlation", ))))))), "") -> Adequate predictability | N16: =IFERROR(F16/C16, 0) -> 0.56762295 | O16: =IFERROR(F16/((E16*Factor!$C$2)+Phase1!F16), 0) -> 0.15177192
A17: Bor_Boral_OS_Amt | B17: [900000,2500000) | C17: 488 | D17: 0.24859908 | E17: 232 | F17: 256 | G17: 0.52459016 | H17: 0.13614194 | I17: 0.0046064891 | J17: 0.053361281 | K17: 2500000 | L17: FALSE | M17: =IFERROR(IF(NOT(ISNUMBER(J17)), "", IF(J17<0.01,"No Correlation",IF(J17<0.03,"Marginal contribution",IF(J17<0.1,"Adequate predictability",IF(J17<0.3,"Strong Predictor",IF(J17<0.5,"Very Strong predictor",IF(J17>=0.5,"Extremely high correlation", ))))))), "") -> Adequate predictability | N17: =IFERROR(F17/C17, 0) -> 0.52459016 | O17: =IFERROR(F17/((E17*Factor!$C$2)+Phase1!F17), 0) -> 0.13073337 | P17: =(F17+F18)/((F17+F18)+(E17+E18)*Factor!$C$2) -> 0.11670644
A18: Bor_Boral_OS_Amt | B18: [2500000, Inf) | C18: 349 | D18: 0.1777891 | E18: 193 | F18: 156 | G18: 0.4469914 | H18: -0.17513231 | I18: 0.0054301929 | J18: 0.053361281 | K18: Inf | L18: FALSE | M18: =IFERROR(IF(NOT(ISNUMBER(J18)), "", IF(J18<0.01,"No Correlation",IF(J18<0.03,"Marginal contribution",IF(J18<0.1,"Adequate predictability",IF(J18<0.3,"Strong Predictor",IF(J18<0.5,"Very Strong predictor",IF(J18>=0.5,"Extremely high correlation", ))))))), "") -> Adequate predictability | N18: =IFERROR(F18/C18, 0) -> 0.4469914 | O18: =IFERROR(F18/((E18*Factor!$C$2)+Phase1!F18), 0) -> 0.099234053
M19: =IFERROR(IF(NOT(ISNUMBER(J19)), "", IF(J19<0.01,"No Correlation",IF(J19<0.03,"Marginal contribution",IF(J19<0.1,"Adequate predictability",IF(J19<0.3,"Strong Predictor",IF(J19<0.5,"Very Strong predictor",IF(J19>=0.5,"Extremely high correlation", ))))))), "")
A20: variable | B20: bin | C20: count | D20: count_distr | E20: neg | F20: pos | G20: posprob | H20: woe | I20: bin_iv | J20: total_iv | K20: breaks | L20: is_special_values | M20: =IFERROR(IF(NOT(ISNUMBER(J20)), "", IF(J20<0.01,"No Correlation",IF(J20<0.03,"Marginal contribution",IF(J20<0.1,"Adequate predictability",IF(J20<0.3,"Strong Predictor",IF(J20<0.5,"Very Strong predictor",IF(J20>=0.5,"Extremely high correlation", ))))))), "")
A21: Bor_Boral_Overdue_Amt | B21: [-Inf,10000) | C21: 1860 | D21: 0.94752929 | E21: 958 | F21: 902 | G21: 0.48494624 | H21: -0.022531391 | I21: 0.00048090364 | J21: 0.0092511677 | K21: 10000 | L21: FALSE | M21: =IFERROR(IF(NOT(ISNUMBER(J21)), "", IF(J21<0.01,"No Correlation",IF(J21<0.03,"Marginal contribution",IF(J21<0.1,"Adequate predictability",IF(J21<0.3,"Strong Predictor",IF(J21<0.5,"Very Strong predictor",IF(J21>=0.5,"Extremely high correlation", ))))))), "") -> No Correlation | N21: =IFERROR(F21/C21, 0) -> 0.48494624 | O21: =IFERROR(F21/((E21*Factor!$C$2)+Phase1!F21), 0) -> 0.11373314
A22: Bor_Boral_Overdue_Amt | B22: [10000, Inf) | C22: 103 | D22: 0.052470708 | E22: 42 | F22: 61 | G22: 0.59223301 | H22: 0.41090611 | I22: 0.008770264 | J22: 0.0092511677 | K22: Inf | L22: FALSE | M22: =IFERROR(IF(NOT(ISNUMBER(J22)), "", IF(J22<0.01,"No Correlation",IF(J22<0.03,"Marginal contribution",IF(J22<0.1,"Adequate predictability",IF(J22<0.3,"Strong Predictor",IF(J22<0.5,"Very Strong predictor",IF(J22>=0.5,"Extremely high correlation", ))))))), "") -> No Correlation | N22: =IFERROR(F22/C22, 0) -> 0.59223301 | O22: =IFERROR(F22/((E22*Factor!$C$2)+Phase1!F22), 0) -> 0.16524269
M23: =IFERROR(IF(NOT(ISNUMBER(J23)), "", IF(J23<0.01,"No Correlation",IF(J23<0.03,"Marginal contribution",IF(J23<0.1,"Adequate predictability",IF(J23<0.3,"Strong Predictor",IF(J23<0.5,"Very Strong predictor",IF(J23>=0.5,"Extremely high correlation", ))))))), "")
A24: variable | B24: bin | C24: count | D24: count_distr | E24: neg | F24: pos | G24: posprob | H24: woe | I24: bin_iv | J24: total_iv | K24: breaks | L24: is_special_values | M24: =IFERROR(IF(NOT(ISNUMBER(J24)), "", IF(J24<0.01,"No Correlation",IF(J24<0.03,"Marginal contribution",IF(J24<0.1,"Adequate predictability",IF(J24<0.3,"Strong Predictor",IF(J24<0.5,"Very Strong predictor",IF(J24>=0.5,"Extremely high correlation", ))))))), "")
A25: Bor_Current_Highest_NPI | B25: [-Inf, Inf) | C25: 1963 | D25: 1 | E25: 1000 | F25: 963 | G25: 0.49057565 | H25: 0 | I25: 0 | J25: 0 | K25: Inf | L25: FALSE | M25: =IFERROR(IF(NOT(ISNUMBER(J25)), "", IF(J25<0.01,"No Correlation",IF(J25<0.03,"Marginal contribution",IF(J25<0.1,"Adequate predictability",IF(J25<0.3,"Strong Predictor",IF(J25<0.5,"Very Strong predictor",IF(J25>=0.5,"Extremely high correlation", ))))))), "") -> No Correlation | N25: =IFERROR(F25/C25, 0) -> 0.49057565 | O25: =IFERROR(F25/((E25*Factor!$C$2)+Phase1!F25), 0) -> 0.1160241
M26: =IFERROR(IF(NOT(ISNUMBER(J26)), "", IF(J26<0.01,"No Correlation",IF(J26<0.03,"Marginal contribution",IF(J26<0.1,"Adequate predictability",IF(J26<0.3,"Strong Predictor",IF(J26<0.5,"Very Strong predictor",IF(J26>=0.5,"Extremely high correlation", ))))))), "")
A27: variable | B27: bin | C27: count | D27: count_distr | E27: neg | F27: pos | G27: posprob | H27: woe | I27: bin_iv | J27: total_iv | K27: breaks | L27: is_special_values | M27: =IFERROR(IF(NOT(ISNUMBER(J27)), "", IF(J27<0.01,"No Correlation",IF(J27<0.03,"Marginal contribution",IF(J27<0.1,"Adequate predictability",IF(J27<0.3,"Strong Predictor",IF(J27<0.5,"Very Strong predictor",IF(J27>=0.5,"Extremely high correlation", ))))))), "")
A28: Bor_Historic_High_NPI_L12 | B28: [-Inf,1) | C28: 1748 | D28: 0.89047376 | E28: 903 | F28: 845 | G28: 0.48340961 | H28: -0.028684059 | I28: 0.00073241155 | J28: 0.0066990234 | K28: 1 | L28: FALSE | M28: =IFERROR(IF(NOT(ISNUMBER(J28)), "", IF(J28<0.01,"No Correlation",IF(J28<0.03,"Marginal contribution",IF(J28<0.1,"Adequate predictability",IF(J28<0.3,"Strong Predictor",IF(J28<0.5,"Very Strong predictor",IF(J28>=0.5,"Extremely high correlation", ))))))), "") -> No Correlation | N28: =IFERROR(F28/C28, 0) -> 0.48340961 | O28: =IFERROR(F28/((E28*Factor!$C$2)+Phase1!F28), 0) -> 0.11311443
A29: Bor_Historic_High_NPI_L12 | B29: [1, Inf) | C29: 215 | D29: 0.10952624 | E29: 97 | F29: 118 | G29: 0.54883721 | H29: 0.23367551 | I29: 0.0059666118 | J29: 0.0066990234 | K29: Inf | L29: FALSE | M29: =IFERROR(IF(NOT(ISNUMBER(J29)), "", IF(J29<0.01,"No Correlation",IF(J29<0.03,"Marginal contribution",IF(J29<0.1,"Adequate predictability",IF(J29<0.3,"Strong Predictor",IF(J29<0.5,"Very Strong predictor",IF(J29>=0.5,"Extremely high correlation", ))))))), "") -> No Correlation | N29: =IFERROR(F29/C29, 0) -> 0.54883721 | O29: =IFERROR(F29/((E29*Factor!$C$2)+Phase1!F29), 0) -> 0.14222197
M30: =IFERROR(IF(NOT(ISNUMBER(J30)), "", IF(J30<0.01,"No Correlation",IF(J30<0.03,"Marginal contribution",IF(J30<0.1,"Adequate predictability",IF(J30<0.3,"Strong Predictor",IF(J30<0.5,"Very Strong predictor",IF(J30>=0.5,"Extremely high correlation", ))))))), "")
A31: variable | B31: bin | C31: count | D31: count_distr | E31: neg | F31: pos | G31: posprob | H31: woe | I31: bin_iv | J31: total_iv | K31: breaks | L31: is_special_values | M31: =IFERROR(IF(NOT(ISNUMBER(J31)), "", IF(J31<0.01,"No Correlation",IF(J31<0.03,"Marginal contribution",IF(J31<0.1,"Adequate predictability",IF(J31<0.3,"Strong Predictor",IF(J31<0.5,"Very Strong predictor",IF(J31>=0.5,"Extremely high correlation", ))))))), "")
A32: Bor_Historic_High_NPI_L24 | B32: [-Inf,1) | C32: 1679 | D32: 0.85532348 | E32: 873 | F32: 806 | G32: 0.48004765 | H32: -0.042149946 | I32: 0.0015187549 | J32: 0.010518176 | K32: 1 | L32: FALSE | M32: =IFERROR(IF(NOT(ISNUMBER(J32)), "", IF(J32<0.01,"No Correlation",IF(J32<0.03,"Marginal contribution",IF(J32<0.1,"Adequate predictability",IF(J32<0.3,"Strong Predictor",IF(J32<0.5,"Very Strong predictor",IF(J32>=0.5,"Extremely high correlation", ))))))), "") -> Marginal contribution | N32: =IFERROR(F32/C32, 0) -> 0.48004765 | O32: =IFERROR(F32/((E32*Factor!$C$2)+Phase1!F32), 0) -> 0.11177056 | P32: All Okay
A33: Bor_Historic_High_NPI_L24 | B33: [1, Inf) | C33: 284 | D33: 0.14467652 | E33: 127 | F33: 157 | G33: 0.5528169 | H33: 0.24976059 | I33: 0.0089994212 | J33: 0.010518176 | K33: Inf | L33: FALSE | M33: =IFERROR(IF(NOT(ISNUMBER(J33)), "", IF(J33<0.01,"No Correlation",IF(J33<0.03,"Marginal contribution",IF(J33<0.1,"Adequate predictability",IF(J33<0.3,"Strong Predictor",IF(J33<0.5,"Very Strong predictor",IF(J33>=0.5,"Extremely high correlation", ))))))), "") -> Marginal contribution | N33: =IFERROR(F33/C33, 0) -> 0.5528169 | O33: =IFERROR(F33/((E33*Factor!$C$2)+Phase1!F33), 0) -> 0.14419558 | P33: All Okay
M34: =IFERROR(IF(NOT(ISNUMBER(J34)), "", IF(J34<0.01,"No Correlation",IF(J34<0.03,"Marginal contribution",IF(J34<0.1,"Adequate predictability",IF(J34<0.3,"Strong Predictor",IF(J34<0.5,"Very Strong predictor",IF(J34>=0.5,"Extremely high correlation", ))))))), "")
A35: variable | B35: bin | C35: count | D35: count_distr | E35: neg | F35: pos | G35: posprob | H35: woe | I35: bin_iv | J35: total_iv | K35: breaks | L35: is_special_values | M35: =IFERROR(IF(NOT(ISNUMBER(J35)), "", IF(J35<0.01,"No Correlation",IF(J35<0.03,"Marginal contribution",IF(J35<0.1,"Adequate predictability",IF(J35<0.3,"Strong Predictor",IF(J35<0.5,"Very Strong predictor",IF(J35>=0.5,"Extremely high correlation", ))))))), "")
A36: Bor_Terminated_Loans_L24 | B36: [-Inf,1) | C36: 919 | D36: 0.46816098 | E36: 470 | F36: 449 | G36: 0.48857454 | H36: -0.0080079398 | I36: 3.001938e-05 | J36: 0.0021424597 | K36: 1 | L36: FALSE | M36: =IFERROR(IF(NOT(ISNUMBER(J36)), "", IF(J36<0.01,"No Correlation",IF(J36<0.03,"Marginal contribution",IF(J36<0.1,"Adequate predictability",IF(J36<0.3,"Strong Predictor",IF(J36<0.5,"Very Strong predictor",IF(J36>=0.5,"Extremely high correlation", ))))))), "") -> No Correlation | N36: =IFERROR(F36/C36, 0) -> 0.48857454 | O36: =IFERROR(F36/((E36*Factor!$C$2)+Phase1!F36), 0) -> 0.1152053
A37: Bor_Terminated_Loans_L24 | B37: [1,2) | C37: 475 | D37: 0.24197657 | E37: 237 | F37: 238 | G37: 0.50105263 | H37: 0.0419124 | I37: 0.00042517366 | J37: 0.0021424597 | K37: 2 | L37: FALSE | M37: =IFERROR(IF(NOT(ISNUMBER(J37)), "", IF(J37<0.01,"No Correlation",IF(J37<0.03,"Marginal contribution",IF(J37<0.1,"Adequate predictability",IF(J37<0.3,"Strong Predictor",IF(J37<0.5,"Very Strong predictor",IF(J37>=0.5,"Extremely high correlation", ))))))), "") -> No Correlation | N37: =IFERROR(F37/C37, 0) -> 0.50105263 | O37: =IFERROR(F37/((E37*Factor!$C$2)+Phase1!F37), 0) -> 0.1203924
A38: Bor_Terminated_Loans_L24 | B38: [2,3) | C38: 269 | D38: 0.13703515 | E38: 139 | F38: 130 | G38: 0.48327138 | H38: -0.029237615 | I38: 0.00011710227 | J38: 0.0021424597 | K38: 3 | L38: FALSE | M38: =IFERROR(IF(NOT(ISNUMBER(J38)), "", IF(J38<0.01,"No Correlation",IF(J38<0.03,"Marginal contribution",IF(J38<0.1,"Adequate predictability",IF(J38<0.3,"Strong Predictor",IF(J38<0.5,"Very Strong predictor",IF(J38>=0.5,"Extremely high correlation", ))))))), "") -> No Correlation | N38: =IFERROR(F38/C38, 0) -> 0.48327138 | O38: =IFERROR(F38/((E38*Factor!$C$2)+Phase1!F38), 0) -> 0.11305891
A39: Bor_Terminated_Loans_L24 | B39: [3,5) | C39: 167 | D39: 0.085073867 | E39: 82 | F39: 85 | G39: 0.50898204 | H39: 0.073633876 | I39: 0.00046137779 | J39: 0.0021424597 | K39: 5 | L39: FALSE | M39: =IFERROR(IF(NOT(ISNUMBER(J39)), "", IF(J39<0.01,"No Correlation",IF(J39<0.03,"Marginal contribution",IF(J39<0.1,"Adequate predictability",IF(J39<0.3,"Strong Predictor",IF(J39<0.5,"Very Strong predictor",IF(J39>=0.5,"Extremely high correlation", ))))))), "") -> No Correlation | N39: =IFERROR(F39/C39, 0) -> 0.50898204 | O39: =IFERROR(F39/((E39*Factor!$C$2)+Phase1!F39), 0) -> 0.1237923
A40: Bor_Terminated_Loans_L24 | B40: [5, Inf) | C40: 133 | D40: 0.067753439 | E40: 72 | F40: 61 | G40: 0.45864662 | H40: -0.12809039 | I40: 0.0011087866 | J40: 0.0021424597 | K40: Inf | L40: FALSE | M40: =IFERROR(IF(NOT(ISNUMBER(J40)), "", IF(J40<0.01,"No Correlation",IF(J40<0.03,"Marginal contribution",IF(J40<0.1,"Adequate predictability",IF(J40<0.3,"Strong Predictor",IF(J40<0.5,"Very Strong predictor",IF(J40>=0.5,"Extremely high correlation", ))))))), "") -> No Correlation | N40: =IFERROR(F40/C40, 0) -> 0.45864662 | O40: =IFERROR(F40/((E40*Factor!$C$2)+Phase1!F40), 0) -> 0.10351897
...

Sheet Phase2
A1: variable | B1: bin | C1: count | D1: count_distr | E1: neg | F1: pos | G1: posprob | H1: woe | I1: bin_iv | J1: total_iv | K1: breaks | L1: is_special_values | M1: Correlation | N1: Bad Rate | O1: Bad Rate (Factored) | P1: Variables under consideration
A2: Bor_No_Rep_Institutes | B2: [-Inf,1) | C2: 256 | D2: 0.13041263 | E2: 136 | F2: 120 | G2: 0.46875 | H2: -0.087461276 | I2: 0.00099613216 | J2: 0.0050415569 | K2: 1 | L2: FALSE | M2: =IFERROR(IF(NOT(ISNUMBER(J2)), "", IF(J2<0.01,"No Correlation",IF(J2<0.03,"Marginal contribution",IF(J2<0.1,"Adequate predictability",IF(J2<0.3,"Strong Predictor",IF(J2<0.5,"Very Strong predictor",IF(J2>=0.5,"Extremely high correlation", ))))))), "") -> No Correlation | N2: =IFERROR(F2/C2, 0) -> 0.46875 | O2: =IFERROR(F2/((E2*Factor!$C$2)+F2), 0) -> 0.10735066 | P2: =VLOOKUP(A2, Synopsis!$G$2:$G$15,1,FALSE) -> Bor_No_Rep_Institutes
A3: Bor_No_Rep_Institutes | B3: [1,6) | C3: 1462 | D3: 0.7447784 | E3: 750 | F3: 712 | G3: 0.4870041 | H3: -0.014293428 | I3: 0.00015213669 | J3: 0.0050415569 | K3: 6 | L3: FALSE | M3: =IFERROR(IF(NOT(ISNUMBER(J3)), "", IF(J3<0.01,"No Correlation",IF(J3<0.03,"Marginal contribution",IF(J3<0.1,"Adequate predictability",IF(J3<0.3,"Strong Predictor",IF(J3<0.5,"Very Strong predictor",IF(J3>=0.5,"Extremely high correlation", ))))))), "") -> No Correlation | N3: =IFERROR(F3/C3, 0) -> 0.4870041 | O3: =IFERROR(F3/((E3*Factor!$C$2)+F3), 0) -> 0.11456615 | P3: =VLOOKUP(A3, Synopsis!$G$2:$G$15,1,FALSE) -> Bor_No_Rep_Institutes
A4: Bor_No_Rep_Institutes | B4: [6, Inf) | C4: 245 | D4: 0.12480897 | E4: 114 | F4: 131 | G4: 0.53469388 | H4: 0.17670074 | I4: 0.003893288 | J4: 0.0050415569 | K4: Inf | L4: FALSE | M4: =IFERROR(IF(NOT(ISNUMBER(J4)), "", IF(J4<0.01,"No Correlation",IF(J4<0.03,"Marginal contribution",IF(J4<0.1,"Adequate predictability",IF(J4<0.3,"Strong Predictor",IF(J4<0.5,"Very Strong predictor",IF(J4>=0.5,"Extremely high correlation", ))))))), "") -> No Correlation | N4: =IFERROR(F4/C4, 0) -> 0.53469388 | O4: =IFERROR(F4/((E4*Factor!$C$2)+F4), 0) -> 0.13541199 | P4: =VLOOKUP(A4, Synopsis!$G$2:$G$15,1,FALSE) -> Bor_No_Rep_Institutes
M5: =IFERROR(IF(NOT(ISNUMBER(J5)), "", IF(J5<0.01,"No Correlation",IF(J5<0.03,"Marginal contribution",IF(J5<0.1,"Adequate predictability",IF(J5<0.3,"Strong Predictor",IF(J5<0.5,"Very Strong predictor",IF(J5>=0.5,"Extremely high correlation", ))))))), "")
A6: variable | B6: bin | C6: count | D6: count_distr | E6: neg | F6: pos | G6: posprob | H6: woe | I6: bin_iv | J6: total_iv | K6: breaks | L6: is_special_values | M6: =IFERROR(IF(NOT(ISNUMBER(J6)), "", IF(J6<0.01,"No Correlation",IF(J6<0.03,"Marginal contribution",IF(J6<0.1,"Adequate predictability",IF(J6<0.3,"Strong Predictor",IF(J6<0.5,"Very Strong predictor",IF(J6>=0.5,"Extremely high correlation", ))))))), "")
A7: Bor_No_Living_Contracts | B7: [-Inf,1) | C7: 453 | D7: 0.23076923 | E7: 255 | F7: 198 | G7: 0.43708609 | H7: -0.21529465 | I7: 0.010633946 | J7: 0.013881408 | K7: 1 | L7: FALSE | M7: =IFERROR(IF(NOT(ISNUMBER(J7)), "", IF(J7<0.01,"No Correlation",IF(J7<0.03,"Marginal contribution",IF(J7<0.1,"Adequate predictability",IF(J7<0.3,"Strong Predictor",IF(J7<0.5,"Very Strong predictor",IF(J7>=0.5,"Extremely high correlation", ))))))), "") -> Marginal contribution | N7: =IFERROR(F7/C7, 0) -> 0.43708609 | O7: =IFERROR(F7/((E7*Factor!$C$2)+F7), 0) -> 0.095701412 | P7: =VLOOKUP(A7, Synopsis!$G$2:$G$15,1,FALSE) -> Bor_No_Living_Contracts
A8: Bor_No_Living_Contracts | B8: [1,5) | C8: 1372 | D8: 0.69893021 | E8: 678 | F8: 694 | G8: 0.5058309 | H8: 0.06102654 | I8: 0.0026036723 | J8: 0.013881408 | K8: 5 | L8: FALSE | M8: =IFERROR(IF(NOT(ISNUMBER(J8)), "", IF(J8<0.01,"No Correlation",IF(J8<0.03,"Marginal contribution",IF(J8<0.1,"Adequate predictability",IF(J8<0.3,"Strong Predictor",IF(J8<0.5,"Very Strong predictor",IF(J8>=0.5,"Extremely high correlation", ))))))), "") -> Marginal contribution | N8: =IFERROR(F8/C8, 0) -> 0.5058309 | O8: =IFERROR(F8/((E8*Factor!$C$2)+F8), 0) -> 0.12243128 | P8: =VLOOKUP(A8, Synopsis!$G$2:$G$15,1,FALSE) -> Bor_No_Living_Contracts
A9: Bor_No_Living_Contracts | B9: [5, Inf) | C9: 138 | D9: 0.07030056 | E9: 67 | F9: 71 | G9: 0.51449275 | H9: 0.095689125 | I9: 0.00064379007 | J9: 0.013881408 | K9: Inf | L9: FALSE | M9: =IFERROR(IF(NOT(ISNUMBER(J9)), "", IF(J9<0.01,"No Correlation",IF(J9<0.03,"Marginal contribution",IF(J9<0.1,"Adequate predictability",IF(J9<0.3,"Strong Predictor",IF(J9<0.5,"Very Strong predictor",IF(J9>=0.5,"Extremely high correlation", ))))))), "") -> Marginal contribution | N9: =IFERROR(F9/C9, 0) -> 0.51449275 | O9: =IFERROR(F9/((E9*Factor!$C$2)+F9), 0) -> 0.1262045 | P9: =VLOOKUP(A9, Synopsis!$G$2:$G$15,1,FALSE) -> Bor_No_Living_Contracts
M10: =IFERROR(IF(NOT(ISNUMBER(J10)), "", IF(J10<0.01,"No Correlation",IF(J10<0.03,"Marginal contribution",IF(J10<0.1,"Adequate predictability",IF(J10<0.3,"Strong Predictor",IF(J10<0.5,"Very Strong predictor",IF(J10>=0.5,"Extremely high correlation", ))))))), "")
A11: variable | B11: bin | C11: count | D11: count_distr | E11: neg | F11: pos | G11: posprob | H11: woe | I11: bin_iv | J11: total_iv | K11: breaks | L11: is_special_values | M11: =IFERROR(IF(NOT(ISNUMBER(J11)), "", IF(J11<0.01,"No Correlation",IF(J11<0.03,"Marginal contribution",IF(J11<0.1,"Adequate predictability",IF(J11<0.3,"Strong Predictor",IF(J11<0.5,"Very Strong predictor",IF(J11>=0.5,"Extremely high correlation", ))))))), "")
A12: Bor_Boral_OS_Amt | B12: [-Inf,900000) | C12: 1126 | D12: 0.57361182 | E12: 575 | F12: 551 | G12: 0.48934281 | H12: -0.0049333645 | I12: 1.3959936e-05 | J12: 3.2737952e-05 | K12: 900000 | L12: FALSE | M12: =IFERROR(IF(NOT(ISNUMBER(J12)), "", IF(J12<0.01,"No Correlation",IF(J12<0.03,"Marginal contribution",IF(J12<0.1,"Adequate predictability",IF(J12<0.3,"Strong Predictor",IF(J12<0.5,"Very Strong predictor",IF(J12>=0.5,"Extremely high correlation", ))))))), "") -> No Correlation | N12: =IFERROR(F12/C12, 0) -> 0.48934281 | O12: =IFERROR(F12/((E12*Factor!$C$2)+F12), 0) -> 0.11551908 | P12: =VLOOKUP(A12, Synopsis!$G$2:$G$15,1,FALSE) -> Bor_Boral_OS_Amt
A13: Bor_Boral_OS_Amt | B13: [900000, Inf) | C13: 837 | D13: 0.42638818 | E13: 425 | F13: 412 | G13: 0.49223417 | H13: 0.0066360476 | I13: 1.8778016e-05 | J13: 3.2737952e-05 | K13: Inf | L13: FALSE | M13: =IFERROR(IF(NOT(ISNUMBER(J13)), "", IF(J13<0.01,"No Correlation",IF(J13<0.03,"Marginal contribution",IF(J13<0.1,"Adequate predictability",IF(J13<0.3,"Strong Predictor",IF(J13<0.5,"Very Strong predictor",IF(J13>=0.5,"Extremely high correlation", ))))))), "") -> No Correlation | N13: =IFERROR(F13/C13, 0) -> 0.49223417 | O13: =IFERROR(F13/((E13*Factor!$C$2)+F13), 0) -> 0.11670644 | P13: =VLOOKUP(A13, Synopsis!$G$2:$G$15,1,FALSE) -> Bor_Boral_OS_Amt
M14: =IFERROR(IF(NOT(ISNUMBER(J14)), "", IF(J14<0.01,"No Correlation",IF(J14<0.03,"Marginal contribution",IF(J14<0.1,"Adequate predictability",IF(J14<0.3,"Strong Predictor",IF(J14<0.5,"Very Strong predictor",IF(J14>=0.5,"Extremely high correlation", ))))))), "")
A15: variable | B15: bin | C15: count | D15: count_distr | E15: neg | F15: pos | G15: posprob | H15: woe | I15: bin_iv | J15: total_iv | K15: breaks | L15: is_special_values | M15: =IFERROR(IF(NOT(ISNUMBER(J15)), "", IF(J15<0.01,"No Correlation",IF(J15<0.03,"Marginal contribution",IF(J15<0.1,"Adequate predictability",IF(J15<0.3,"Strong Predictor",IF(J15<0.5,"Very Strong predictor",IF(J15>=0.5,"Extremely high correlation", ))))))), "")
A16: Bor_Boral_Overdue_Amt | B16: [-Inf,10000) | C16: 1860 | D16: 0.94752929 | E16: 958 | F16: 902 | G16: 0.48494624 | H16: -0.022531391 | I16: 0.00048090364 | J16: 0.0092511677 | K16: 10000 | L16: FALSE | M16: =IFERROR(IF(NOT(ISNUMBER(J16)), "", IF(J16<0.01,"No Correlation",IF(J16<0.03,"Marginal contribution",IF(J16<0.1,"Adequate predictability",IF(J16<0.3,"Strong Predictor",IF(J16<0.5,"Very Strong predictor",IF(J16>=0.5,"Extremely high correlation", ))))))), "") -> No Correlation | N16: =IFERROR(F16/C16, 0) -> 0.48494624 | O16: =IFERROR(F16/((E16*Factor!$C$2)+F16), 0) -> 0.11373314 | P16: =VLOOKUP(A16, Synopsis!$G$2:$G$15,1,FALSE) -> #N/A
A17: Bor_Boral_Overdue_Amt | B17: [10000, Inf) | C17: 103 | D17: 0.052470708 | E17: 42 | F17: 61 | G17: 0.59223301 | H17: 0.41090611 | I17: 0.008770264 | J17: 0.0092511677 | K17: Inf | L17: FALSE | M17: =IFERROR(IF(NOT(ISNUMBER(J17)), "", IF(J17<0.01,"No Correlation",IF(J17<0.03,"Marginal contribution",IF(J17<0.1,"Adequate predictability",IF(J17<0.3,"Strong Predictor",IF(J17<0.5,"Very Strong predictor",IF(J17>=0.5,"Extremely high correlation", ))))))), "") -> No Correlation | N17: =IFERROR(F17/C17, 0) -> 0.59223301 | O17: =IFERROR(F17/((E17*Factor!$C$2)+F17), 0) -> 0.16524269 | P17: =VLOOKUP(A17, Synopsis!$G$2:$G$15,1,FALSE) -> #N/A
M18: =IFERROR(IF(NOT(ISNUMBER(J18)), "", IF(J18<0.01,"No Correlation",IF(J18<0.03,"Marginal contribution",IF(J18<0.1,"Adequate predictability",IF(J18<0.3,"Strong Predictor",IF(J18<0.5,"Very Strong predictor",IF(J18>=0.5,"Extremely high correlation", ))))))), "")
A19: variable | B19: bin | C19: count | D19: count_distr | E19: neg | F19: pos | G19: posprob | H19: woe | I19: bin_iv | J19: total_iv | K19: breaks | L19: is_special_values | M19: =IFERROR(IF(NOT(ISNUMBER(J19)), "", IF(J19<0.01,"No Correlation",IF(J19<0.03,"Marginal contribution",IF(J19<0.1,"Adequate predictability",IF(J19<0.3,"Strong Predictor",IF(J19<0.5,"Very Strong predictor",IF(J19>=0.5,"Extremely high correlation", ))))))), "")
A20: Bor_Current_Highest_NPI | B20: [-Inf, Inf) | C20: 1963 | D20: 1 | E20: 1000 | F20: 963 | G20: 0.49057565 | H20: 0 | I20: 0 | J20: 0 | K20: Inf | L20: FALSE | M20: =IFERROR(IF(NOT(ISNUMBER(J20)), "", IF(J20<0.01,"No Correlation",IF(J20<0.03,"Marginal contribution",IF(J20<0.1,"Adequate predictability",IF(J20<0.3,"Strong Predictor",IF(J20<0.5,"Very Strong predictor",IF(J20>=0.5,"Extremely high correlation", ))))))), "") -> No Correlation | N20: =IFERROR(F20/C20, 0) -> 0.49057565 | O20: =IFERROR(F20/((E20*Factor!$C$2)+F20), 0) -> 0.1160241 | P20: =VLOOKUP(A20, Synopsis!$G$2:$G$15,1,FALSE) -> #N/A
M21: =IFERROR(IF(NOT(ISNUMBER(J21)), "", IF(J21<0.01,"No Correlation",IF(J21<0.03,"Marginal contribution",IF(J21<0.1,"Adequate predictability",IF(J21<0.3,"Strong Predictor",IF(J21<0.5,"Very Strong predictor",IF(J21>=0.5,"Extremely high correlation", ))))))), "")
A22: variable | B22: bin | C22: count | D22: count_distr | E22: neg | F22: pos | G22: posprob | H22: woe | I22: bin_iv | J22: total_iv | K22: breaks | L22: is_special_values | M22: =IFERROR(IF(NOT(ISNUMBER(J22)), "", IF(J22<0.01,"No Correlation",IF(J22<0.03,"Marginal contribution",IF(J22<0.1,"Adequate predictability",IF(J22<0.3,"Strong Predictor",IF(J22<0.5,"Very Strong predictor",IF(J22>=0.5,"Extremely high correlation", ))))))), "")
A23: Bor_Historic_High_NPI_L12 | B23: [-Inf,1) | C23: 1748 | D23: 0.89047376 | E23: 903 | F23: 845 | G23: 0.48340961 | H23: -0.028684059 | I23: 0.00073241155 | J23: 0.0066990234 | K23: 1 | L23: FALSE | M23: =IFERROR(IF(NOT(ISNUMBER(J23)), "", IF(J23<0.01,"No Correlation",IF(J23<0.03,"Marginal contribution",IF(J23<0.1,"Adequate predictability",IF(J23<0.3,"Strong Predictor",IF(J23<0.5,"Very Strong predictor",IF(J23>=0.5,"Extremely high correlation", ))))))), "") -> No Correlation | N23: =IFERROR(F23/C23, 0) -> 0.48340961 | O23: =IFERROR(F23/((E23*Factor!$C$2)+F23), 0) -> 0.11311443 | P23: =VLOOKUP(A23, Synopsis!$G$2:$G$15,1,FALSE) -> #N/A
A24: Bor_Historic_High_NPI_L12 | B24: [1, Inf) | C24: 215 | D24: 0.10952624 | E24: 97 | F24: 118 | G24: 0.54883721 | H24: 0.23367551 | I24: 0.0059666118 | J24: 0.0066990234 | K24: Inf | L24: FALSE | M24: =IFERROR(IF(NOT(ISNUMBER(J24)), "", IF(J24<0.01,"No Correlation",IF(J24<0.03,"Marginal contribution",IF(J24<0.1,"Adequate predictability",IF(J24<0.3,"Strong Predictor",IF(J24<0.5,"Very Strong predictor",IF(J24>=0.5,"Extremely high correlation", ))))))), "") -> No Correlation | N24: =IFERROR(F24/C24, 0) -> 0.54883721 | O24: =IFERROR(F24/((E24*Factor!$C$2)+F24), 0) -> 0.14222197 | P24: =VLOOKUP(A24, Synopsis!$G$2:$G$15,1,FALSE) -> #N/A
M25: =IFERROR(IF(NOT(ISNUMBER(J25)), "", IF(J25<0.01,"No Correlation",IF(J25<0.03,"Marginal contribution",IF(J25<0.1,"Adequate predictability",IF(J25<0.3,"Strong Predictor",IF(J25<0.5,"Very Strong predictor",IF(J25>=0.5,"Extremely high correlation", ))))))), "")
A26: variable | B26: bin | C26: count | D26: count_distr | E26: neg | F26: pos | G26: posprob | H26: woe | I26: bin_iv | J26: total_iv | K26: breaks | L26: is_special_values | M26: =IFERROR(IF(NOT(ISNUMBER(J26)), "", IF(J26<0.01,"No Correlation",IF(J26<0.03,"Marginal contribution",IF(J26<0.1,"Adequate predictability",IF(J26<0.3,"Strong Predictor",IF(J26<0.5,"Very Strong predictor",IF(J26>=0.5,"Extremely high correlation", ))))))), "")
A27: Bor_Historic_High_NPI_L24 | B27: [-Inf,1) | C27: 1679 | D27: 0.85532348 | E27: 873 | F27: 806 | G27: 0.48004765 | H27: -0.042149946 | I27: 0.0015187549 | J27: 0.010518176 | K27: 1 | L27: FALSE | M27: =IFERROR(IF(NOT(ISNUMBER(J27)), "", IF(J27<0.01,"No Correlation",IF(J27<0.03,"Marginal contribution",IF(J27<0.1,"Adequate predictability",IF(J27<0.3,"Strong Predictor",IF(J27<0.5,"Very Strong predictor",IF(J27>=0.5,"Extremely high correlation", ))))))), "") -> Marginal contribution | N27: =IFERROR(F27/C27, 0) -> 0.48004765 | O27: =IFERROR(F27/((E27*Factor!$C$2)+F27), 0) -> 0.11177056 | P27: =VLOOKUP(A27, Synopsis!$G$2:$G$15,1,FALSE) -> Bor_Historic_High_NPI_L24
A28: Bor_Historic_High_NPI_L24 | B28: [1, Inf) | C28: 284 | D28: 0.14467652 | E28: 127 | F28: 157 | G28: 0.5528169 | H28: 0.24976059 | I28: 0.0089994212 | J28: 0.010518176 | K28: Inf | L28: FALSE | M28: =IFERROR(IF(NOT(ISNUMBER(J28)), "", IF(J28<0.01,"No Correlation",IF(J28<0.03,"Marginal contribution",IF(J28<0.1,"Adequate predictability",IF(J28<0.3,"Strong Predictor",IF(J28<0.5,"Very Strong predictor",IF(J28>=0.5,"Extremely high correlation", ))))))), "") -> Marginal contribution | N28: =IFERROR(F28/C28, 0) -> 0.5528169 | O28: =IFERROR(F28/((E28*Factor!$C$2)+F28), 0) -> 0.14419558 | P28: =VLOOKUP(A28, Synopsis!$G$2:$G$15,1,FALSE) -> Bor_Historic_High_NPI_L24
M29: =IFERROR(IF(NOT(ISNUMBER(J29)), "", IF(J29<0.01,"No Correlation",IF(J29<0.03,"Marginal contribution",IF(J29<0.1,"Adequate predictability",IF(J29<0.3,"Strong Predictor",IF(J29<0.5,"Very Strong predictor",IF(J29>=0.5,"Extremely high correlation", ))))))), "")
A30: variable | B30: bin | C30: count | D30: count_distr | E30: neg | F30: pos | G30: posprob | H30: woe | I30: bin_iv | J30: total_iv | K30: breaks | L30: is_special_values | M30: =IFERROR(IF(NOT(ISNUMBER(J30)), "", IF(J30<0.01,"No Correlation",IF(J30<0.03,"Marginal contribution",IF(J30<0.1,"Adequate predictability",IF(J30<0.3,"Strong Predictor",IF(J30<0.5,"Very Strong predictor",IF(J30>=0.5,"Extremely high correlation", ))))))), "")
A31: Bor_Terminated_Loans_L24 | B31: [-Inf,1) | C31: 919 | D31: 0.46816098 | E31: 470 | F31: 449 | G31: 0.48857454 | H31: -0.0080079398 | I31: 3.001938e-05 | J31: 0.0021424597 | K31: 1 | L31: FALSE | M31: =IFERROR(IF(NOT(ISNUMBER(J31)), "", IF(J31<0.01,"No Correlation",IF(J31<0.03,"Marginal contribution",IF(J31<0.1,"Adequate predictability",IF(J31<0.3,"Strong Predictor",IF(J31<0.5,"Very Strong predictor",IF(J31>=0.5,"Extremely high correlation", ))))))), "") -> No Correlation | N31: =IFERROR(F31/C31, 0) -> 0.48857454 | O31: =IFERROR(F31/((E31*Factor!$C$2)+F31), 0) -> 0.1152053 | P31: =VLOOKUP(A31, Synopsis!$G$2:$G$15,1,FALSE) -> #N/A
A32: Bor_Terminated_Loans_L24 | B32: [1,2) | C32: 475 | D32: 0.24197657 | E32: 237 | F32: 238 | G32: 0.50105263 | H32: 0.0419124 | I32: 0.00042517366 | J32: 0.0021424597 | K32: 2 | L32: FALSE | M32: =IFERROR(IF(NOT(ISNUMBER(J32)), "", IF(J32<0.01,"No Correlation",IF(J32<0.03,"Marginal contribution",IF(J32<0.1,"Adequate predictability",IF(J32<0.3,"Strong Predictor",IF(J32<0.5,"Very Strong predictor",IF(J32>=0.5,"Extremely high correlation", ))))))), "") -> No Correlation | N32: =IFERROR(F32/C32, 0) -> 0.50105263 | O32: =IFERROR(F32/((E32*Factor!$C$2)+F32), 0) -> 0.1203924 | P32: =VLOOKUP(A32, Synopsis!$G$2:$G$15,1,FALSE) -> #N/A
A33: Bor_Terminated_Loans_L24 | B33: [2,3) | C33: 269 | D33: 0.13703515 | E33: 139 | F33: 130 | G33: 0.48327138 | H33: -0.029237615 | I33: 0.00011710227 | J33: 0.0021424597 | K33: 3 | L33: FALSE | M33: =IFERROR(IF(NOT(ISNUMBER(J33)), "", IF(J33<0.01,"No Correlation",IF(J33<0.03,"Marginal contribution",IF(J33<0.1,"Adequate predictability",IF(J33<0.3,"Strong Predictor",IF(J33<0.5,"Very Strong predictor",IF(J33>=0.5,"Extremely high correlation", ))))))), "") -> No Correlation | N33: =IFERROR(F33/C33, 0) -> 0.48327138 | O33: =IFERROR(F33/((E33*Factor!$C$2)+F33), 0) -> 0.11305891 | P33: =VLOOKUP(A33, Synopsis!$G$2:$G$15,1,FALSE) -> #N/A
A34: Bor_Terminated_Loans_L24 | B34: [3,5) | C34: 167 | D34: 0.085073867 | E34: 82 | F34: 85 | G34: 0.50898204 | H34: 0.073633876 | I34: 0.00046137779 | J34: 0.0021424597 | K34: 5 | L34: FALSE | M34: =IFERROR(IF(NOT(ISNUMBER(J34)), "", IF(J34<0.01,"No Correlation",IF(J34<0.03,"Marginal contribution",IF(J34<0.1,"Adequate predictability",IF(J34<0.3,"Strong Predictor",IF(J34<0.5,"Very Strong predictor",IF(J34>=0.5,"Extremely high correlation", ))))))), "") -> No Correlation | N34: =IFERROR(F34/C34, 0) -> 0.50898204 | O34: =IFERROR(F34/((E34*Factor!$C$2)+F34), 0) -> 0.1237923 | P34: =VLOOKUP(A34, Synopsis!$G$2:$G$15,1,FALSE) -> #N/A
A35: Bor_Terminated_Loans_L24 | B35: [5, Inf) | C35: 133 | D35: 0.067753439 | E35: 72 | F35: 61 | G35: 0.45864662 | H35: -0.12809039 | I35: 0.0011087866 | J35: 0.0021424597 | K35: Inf | L35: FALSE | M35: =IFERROR(IF(NOT(ISNUMBER(J35)), "", IF(J35<0.01,"No Correlation",IF(J35<0.03,"Marginal contribution",IF(J35<0.1,"Adequate predictability",IF(J35<0.3,"Strong Predictor",IF(J35<0.5,"Very Strong predictor",IF(J35>=0.5,"Extremely high correlation", ))))))), "") -> No Correlation | N35: =IFERROR(F35/C35, 0) -> 0.45864662 | O35: =IFERROR(F35/((E35*Factor!$C$2)+F35), 0) -> 0.10351897 | P35: =VLOOKUP(A35, Synopsis!$G$2:$G$15,1,FALSE) -> #N/A
M36: =IFERROR(IF(NOT(ISNUMBER(J36)), "", IF(J36<0.01,"No Correlation",IF(J36<0.03,"Marginal contribution",IF(J36<0.1,"Adequate predictability",IF(J36<0.3,"Strong Predictor",IF(J36<0.5,"Very Strong predictor",IF(J36>=0.5,"Extremely high correlation", ))))))), "")
A37: variable | B37: bin | C37: count | D37: count_distr | E37: neg | F37: pos | G37: posprob | H37: woe | I37: bin_iv | J37: total_iv | K37: breaks | L37: is_special_values | M37: =IFERROR(IF(NOT(ISNUMBER(J37)), "", IF(J37<0.01,"No Correlation",IF(J37<0.03,"Marginal contribution",IF(J37<0.1,"Adequate predictability",IF(J37<0.3,"Strong Predictor",IF(J37<0.5,"Very Strong predictor",IF(J37>=0.5,"Extremely high correlation", ))))))), "")
A38: Bor_No_Term_Loans_L12 | B38: [-Inf,1) | C38: 1274 | D38: 0.64900662 | E38: 670 | F38: 604 | G38: 0.47409733 | H38: -0.066001647 | I38: 0.0028244319 | J38: 0.0087606655 | K38: 1 | L38: FALSE | M38: =IFERROR(IF(NOT(ISNUMBER(J38)), "", IF(J38<0.01,"No Correlation",IF(J38<0.03,"Marginal contribution",IF(J38<0.1,"Adequate predictability",IF(J38<0.3,"Strong Predictor",IF(J38<0.5,"Very Strong predictor",IF(J38>=0.5,"Extremely high correlation", ))))))), "") -> No Correlation | N38: =IFERROR(F38/C38, 0) -> 0.47409733 | O38: =IFERROR(F38/((E38*Factor!$C$2)+F38), 0) -> 0.10942445 | P38: =VLOOKUP(A38, Synopsis!$G$2:$G$15,1,FALSE) -> #N/A
A39: Bor_No_Term_Loans_L12 | B39: [1,2) | C39: 568 | D39: 0.28935303 | E39: 275 | F39: 293 | G39: 0.51584507 | H39: 0.10110338 | I39: 0.002958035 | J39: 0.0087606655 | K39: 2 | L39: FALSE | M39: =IFERROR(IF(NOT(ISNUMBER(J39)), "", IF(J39<0.01,"No Correlation",IF(J39<0.03,"Marginal contribution",IF(J39<0.1,"Adequate predictability",IF(J39<0.3,"Strong Predictor",IF(J39<0.5,"Very Strong predictor",IF(J39>=0.5,"Extremely high correlation", ))))))), "") -> No Correlation | N39: =IFERROR(F39/C39, 0) -> 0.51584507 | O39: =IFERROR(F39/((E39*Factor!$C$2)+F39), 0) -> 0.12680277 | P39: =VLOOKUP(A39, Synopsis!$G$2:$G$15,1,FALSE) -> #N/A
A40: Bor_No_Term_Loans_L12 | B40: [2, Inf) | C40: 121 | D40: 0.061640346 | E40: 55 | F40: 66 | G40: 0.54545455 | H40: 0.22002342 | I40: 0.0029781987 | J40: 0.0087606655 | K40: Inf | L40: FALSE | M40: =IFERROR(IF(NOT(ISNUMBER(J40)), "", IF(J40<0.01,"No Correlation",IF(J40<0.03,"Marginal contribution",IF(J40<0.1,"Adequate predictability",IF(J40<0.3,"Strong Predictor",IF(J40<0.5,"Very Strong predictor",IF(J40>=0.5,"Extremely high correlation", ))))))), "") -> No Correlation | N40: =IFERROR(F40/C40, 0) -> 0.54545455 | O40: =IFERROR(F40/((E40*Factor!$C$2)+F40), 0) -> 0.1405646 | P40: =VLOOKUP(A40, Synopsis!$G$2:$G$15,1,FALSE) -> #N/A
...

Sheet Synopsis
A1: Phase 1: | G1: Phase 2
A2: Variables | B2: IV | C2: Correlation | D2: IFC | E2: Remarks | G2: Variables | H2: Correlation | I2: IV | J2: Breaks IDLC | K2: Breaks IFC
A3: Bor_No_Rep_Institutes | B3: 0.015827167 | C3: Marginal contribution | D3: Marginal contribution | G3: Bor_No_Rep_Institutes | H3: =VLOOKUP(G3, Phase2!A:M,13,FALSE) -> No Correlation | I3: =VLOOKUP(G3, Phase2!A:M,10,FALSE) -> 0.0050415569 | J3: =VLOOKUP(G3, Phase1!A:Q,17,FALSE) -> 1, 6 | K3: 1,6
A4: Bor_No_Living_Contracts | B4: 0.019195497 | C4: Marginal contribution | D4: Marginal contribution | G4: Bor_No_Living_Contracts | H4: =VLOOKUP(G4, Phase2!A:M,13,FALSE) -> Marginal contribution | I4: =VLOOKUP(G4, Phase2!A:M,10,FALSE) -> 0.013881408 | J4: =VLOOKUP(G4, Phase1!A:Q,17,FALSE) -> 1, 5 | K4: =J4 -> 1, 5
A5: Bor_Boral_OS_Amt | B5: 0.053361281 | C5: Adequate predictability | D5: Adequate predictability | G5: Bor_Boral_OS_Amt | H5: =VLOOKUP(G5, Phase2!A:M,13,FALSE) -> No Correlation | I5: =VLOOKUP(G5, Phase2!A:M,10,FALSE) -> 3.2737952e-05 | J5: =VLOOKUP(G5, Phase1!A:Q,17,FALSE) -> 900000 | K5: Did not Adjust
A6: Bor_Boral_Overdue_Amt | B6: 0.0092511677 | C6: No Correlation | D6: Marginal contribution | E6: Will be excluded | G6: Bor_Historic_High_NPI_L24 | H6: =VLOOKUP(G6, Phase2!A:M,13,FALSE) -> Marginal contribution | I6: =VLOOKUP(G6, Phase2!A:M,10,FALSE) -> 0.010518176 | J6: =VLOOKUP(G6, Phase1!A:Q,17,FALSE) -> 0 | K6: NA
A7: Bor_Current_Highest_NPI | B7: 0 | C7: No Correlation | D7: No Correlation | E7: Will be excluded | G7: Bor_No_Term_Loans_L24 | H7: =VLOOKUP(G7, Phase2!A:M,13,FALSE) -> Marginal contribution | I7: =VLOOKUP(G7, Phase2!A:M,10,FALSE) -> 0.027215194 | J7: =VLOOKUP(G7, Phase1!A:Q,17,FALSE) -> 1, 2 | K7: Additional Variable
A8: Bor_Historic_High_NPI_L12 | B8: 0.0066990234 | C8: No Correlation | D8: No Correlation | E8: Will be excluded | G8: Guar_Guaral_OS_Amt | H8: =VLOOKUP(G8, Phase2!A:M,13,FALSE) -> No Correlation | I8: =VLOOKUP(G8, Phase2!A:M,10,FALSE) -> 4.0879126e-05 | J8: =VLOOKUP(G8, Phase1!A:Q,17,FALSE) -> 1300000 | K8: Did not Adjust
A9: Bor_Historic_High_NPI_L24 | B9: 0.010518176 | C9: Marginal contribution | D9: No Correlation | G9: Guar_Terminated_Loans_L24 | H9: =VLOOKUP(G9, Phase2!A:M,13,FALSE) -> Marginal contribution | I9: =VLOOKUP(G9, Phase2!A:M,10,FALSE) -> 0.01007778 | J9: =VLOOKUP(G9, Phase1!A:Q,17,FALSE) -> 1, 2 | K9: Did not Adjust
A10: Bor_Terminated_Loans_L24 | B10: 0.0021424597 | C10: No Correlation | D10: No Correlation | E10: Will be excluded | G10: Guar_No_Term_Loans_L12 | H10: =VLOOKUP(G10, Phase2!A:M,13,FALSE) -> Marginal contribution | I10: =VLOOKUP(G10, Phase2!A:M,10,FALSE) -> 0.010120381 | J10: =VLOOKUP(G10, Phase1!A:Q,17,FALSE) -> 0 | K10: Additional Variable
A11: Bor_No_Term_Loans_L12 | B11: 0.0087606655 | C11: No Correlation | D11: NA | E11: Will be excluded | G11: Tot_No_Rep_Institutes | H11: =VLOOKUP(G11, Phase2!A:M,13,FALSE) -> No Correlation | I11: =VLOOKUP(G11, Phase2!A:M,10,FALSE) -> 0.0062780403 | J11: =VLOOKUP(G11, Phase1!A:Q,17,FALSE) -> 4, 11 | K11: Did not Adjust
A12: Bor_No_Term_Loans_L24 | B12: 0.035337855 | C12: Adequate predictability | D12: NA | G12: Tot_Total_OS_Amt | H12: =VLOOKUP(G12, Phase2!A:M,13,FALSE) -> No Correlation | I12: =VLOOKUP(G12, Phase2!A:M,10,FALSE) -> 0.00066619204 | J12: =VLOOKUP(G12, Phase1!A:Q,17,FALSE) -> 3200000 | K12: Did not Adjust
A13: Guar_No_Rep_Institutes | B13: 0.0096784009 | C13: No Correlation | D13: No Correlation | E13: Will be excluded | G13: Tot_Total_Overdue_Amt | H13: =VLOOKUP(G13, Phase2!A:M,13,FALSE) -> Marginal contribution | I13: =VLOOKUP(G13, Phase2!A:M,10,FALSE) -> 0.016602309 | J13: 10000 | K13: 10000
A14: Guar_No_Living_Contracts | B14: 0.0077875404 | C14: No Correlation | D14: No Correlation | E14: Will be excluded | G14: Tot_No_Term_Loans_L12 | H14: =VLOOKUP(G14, Phase2!A:M,13,FALSE) -> Marginal contribution | I14: =VLOOKUP(G14, Phase2!A:M,10,FALSE) -> 0.019642828 | J14: =VLOOKUP(G14, Phase1!A:Q,17,FALSE) -> 2 | K14: Additional Variable
A15: Guar_Guaral_OS_Amt | B15: 0.017582087 | C15: Marginal contribution | D15: Marginal contribution | G15: Tot_No_Term_Loans_L24 | H15: =VLOOKUP(G15, Phase2!A:M,13,FALSE) -> Marginal contribution | I15: =VLOOKUP(G15, Phase2!A:M,10,FALSE) -> 0.02015076 | J15: =VLOOKUP(G15, Phase1!A:Q,17,FALSE) -> 1, 2, 4, 7 | K15: Additional Variable
A16: Guar_Guaral_Overdue_Amt | B16: 0.0060309111 | C16: No Correlation | D16: No Correlation | E16: Will be excluded
A17: Guar_Current_Highest_NPI | B17: 0.0030042608 | C17: No Correlation | D17: No Correlation | E17: Will be excluded
A18: Guar_Historic_High_NPI_L12 | B18: 0.0023717335 | C18: No Correlation | D18: No Correlation | E18: Will be excluded
A19: Guar_Historic_High_NPI_L24 | B19: 0.003713359 | C19: No Correlation | D19: No Correlation | E19: Will be excluded
A20: Guar_Terminated_Loans_L24 | B20: 0.011011278 | C20: Marginal contribution | D20: Marginal contribution
A21: Guar_No_Term_Loans_L12 | B21: 0.010120381 | C21: Marginal contribution | D21: NA
A22: Guar_No_Term_Loans_L24 | B22: 0.0059416695 | C22: No Correlation | D22: NA | E22: Will be excluded
A23: Tot_No_Rep_Institutes | B23: 0.019992215 | C23: Marginal contribution | D23: Marginal contribution
A24: Tot_No_Living_Contracts | B24: 0.0079937917 | C24: No Correlation | D24: Marginal contribution | E24: Will be excluded
A25: Tot_Total_OS_Amt | B25: 0.026935464 | C25: Marginal contribution | D25: Marginal contribution
A26: Tot_Total_Overdue_Amt | B26: 0.016602309 | C26: Marginal contribution | D26: Marginal contribution
A27: Tot_Current_Highest_NPI | B27: 0.0047870201 | C27: No Correlation | D27: No Correlation | E27: Will be excluded
A28: Tot_Historic_High_NPI_L12 | B28: 0.0063921172 | C28: No Correlation | D28: No Correlation | E28: Will be excluded
A29: Tot_Historic_High_NPI_L24 | B29: 0.0084965889 | C29: No Correlation | D29: No Correlation | E29: Will be excluded
A30: Tot_Terminated_Loans_L24 | B30: 0.0077692916 | C30: No Correlation | D30: Marginal contribution | E30: Will be excluded
A31: Tot_No_Term_Loans_L12 | B31: 0.019832626 | C31: Marginal contribution | D31: NA
A32: Tot_No_Term_Loans_L24 | B32: 0.032913081 | C32: Adequate predictability | D32: NA
